Workbook
Name Райони: '0000'!$AA$2:$AA$28

Sheet 0000
B1: Форма № 10 (річна) | E1: Звіт щодо надання психіатричної допомоги населенню за | K1: 2024 рік
AA2: Vinnytska
B3: Термін подання: | E3: Затверджено | J3: Зареєстровано | M3: Погоджено: | AA3: Volynska
B4: відповідно до Наказу МОЗ України | E4: Наказ МОЗ України | J4: у Міністерстві юстиції України | M4: Державна служба статистики України | AA4: Dnipropetrovska
B5: від 9 грудня 2024 року № 2056 | E5: від 30 листопада 2017 року № 1504 | J5: 10 квітня 2018 року за № 426/31878 | M5: Державна регуляторна служба України | AA5: Donetska
M6: Державна служба спеціального зв’язку | AA6: Zhytomyrska
M7: та захисту інформації України | AA7: Zakarpatska
B8: Подають: | AA8: Zaporizka
B9: заклади охорони здоров’я незалежно від їх організаційно-правової форми | AA9: Ivano_Frankivska
B10: та фізичні особи — підприємці, які провадять медичну практику на підставі ліцензії | AA10: Kyivska
B11: й у звітному році брали участь у наданні психіатричної допомоги населенню, в тому числі й особам з розладами психіки та поведінки внаслідок уживання психоактивних речовин | AA11: Kyiv
AA12: Kirovohradska
B13: в електронному вигляді — державній установі «Інститут судової психіатрії Міністерства охорони здоров’я України» | AA13: Luhanska
AA14: Lvivska
B15: 1. Зазначте адресну інформацію, керуючись наведеними у примітках прикладами: | J15: 2. Зазначте наявну інформацію в листах 1000 — 4100, що відповідають таблицям форми № 10 | AA15: Mykolaivska
B16: Респондент: | J16: У звіті ЗОЗ має бути обов'язково заповнено таблицю 4000. У звіті ФОП — таблицю 4100. | AA16: Odeska
A17: edrpou | B17: код за ЄДРПОУ: | J17: Зверніть увагу, що інформацію на цьому та інших листах необхідно вносити | AA17: Poltavska
A18: rnokpp | B18: РНОКПП (зазначати у разі звіту ФОП): | J18: тільки у комірки світло-зеленого кольору | AA18: Rivnenska
A19: name | B19: Найменування ЗОЗ (або П. І. Б. ФОП): | J19: Просимо уникати внесення змін у комірки без кольору чи іншого кольору, | AA19: Sumska
A20: postindex | B20: Місцезнаходження: | E20: поштовий індекс | J20: не видаляти / додавати / редагувати текст та формули, не змінювати форматування тощо | AA20: Ternopilska
A21: oblast | B21: регіон | AA21: Kharkivska
A22: rayon | B22: район | J22: 3. Перевірте правильність внесення даних, користуючись вказівками, розміщеними | AA22: Khersonska
A23: punkt | B23: населений пункт | J23: справа та внизу від таблиць у листах 1000 — 3000. У разі наявності помилок, виправте внесені | AA23: Khmelnytska
A24: street | B24: вулиця / провулок, площа тощо | J24: дані відповідно до перевірочних формул у комірках червоного кольору з позначкою "Помилка" | AA24: Cherkaska
A25: house | B25: № будинку / корпусу | J25: (кількість помилок у кожній таблиці відображається в лівій нижній частині цього листа) | AA25: Chernivetska
A26: room | B26: № квартири / офісу | AA26: Chernihivska
A27: filename | G27: =J28 -> 2024-_ | J27: 4. Після завершення внесення даних перейменуйте файл, як зазначено у комірці нижче: | AA27: AR_Krym
A28: dir | B28: П. І. Б. керівника: | J28: =TRIM(CONCATENATE("2024-",G21,"_",G17)) -> 2024-_ | K28: (наприклад: "2024-Cherkaska_02005484") | AA28: Sevastopol
A29: dir_tel | B29: номер телефону:
A30: dir_email | B30: електронна адреса: | J30: 5. Кожному із закладів з надання психіатричної допомоги області (включно із спеціалізованими
A31: resp | B31: П. І. Б. відповідального за звіт: | J31: та неспеціалізованими) — необхідно надіслати звіт у форматі .xlsx до ДОЗ, для формування
A32: resp_pos | B32: посада: | J32: пакету звітів по області
A33: resp_tel | B33: номер телефону:
A34: resp_email | B34: електронна адреса: | J34: 6. Просимо ДОЗ надіслати пакет звітів усіх закладів з надання психіатричної допомоги
J35: (включно із спеціалізованими та неспеціалізованими) по області (в архівному файлі .zip)
A36: mis_1000 | B36: Кількість помилок | E36: табл. 1000 | G36: =COUNTIF('1000'!E10:AQ239, "Помилка") -> 0 | J36: на електронну адресу: | K36: ndips@ukr.net | M36: відповідно до графіку, зазначеному в додатку 2
A37: mis_1100 | B37: у таблицях: | E37: табл. 1100 | G37: =COUNTIF('1100'!E10:AV157, "Помилка") -> 0 | J37: до Наказу МОЗ України від 9 грудня 2024 року № 2056
A38: mis_1200 | E38: табл. 1200 | G38: =COUNTIF('1200'!E10:AV49, "Помилка") -> 0
A39: mis_1300 | E39: табл. 1300 | G39: =COUNTIF('1300'!E10:Q77, "Помилка") -> 0
A40: mis_1400 | E40: табл. 1400 | G40: =COUNTIF('1400'!E10:AD43, "Помилка") -> 0
...

Sheet 1000
A1: cd | B1: dsrdr | C1: clmn | D1: icd10 | E1: op | F1: op_inc | G1: op_inc_m | H1: op_inc_r | I1: op_inc_u14 | J1: op_inc_u18 | K1: op_inc_y | L1: op_inc_e | M1: op_stp | N1: op_stp_c | O1: op_stp_d | P1: op_prv | Q1: op_prv_m | R1: op_prv_r | S1: op_prv_u14 | T1: op_prv_u18 | U1: op_prv_y | V1: op_prv_e
B2: Таблиця 1000 | C2: Амбулаторна психіатрична допомога
B3: Найменування розладів | C3: Номер | D3: Код за МКХ-10 | E3: Кількість осіб, яким було розпочато надання амбулаторної психіатричної допомоги | M3: Кількість осіб, які припинили отримувати амбулаторну психіатричну допомогу | P3: Кількість осіб, яким надавалась амбулаторна психіатрична допомога на кінець року
C4: рядка | E4: усього | F4: з них з уперше встановленим розладом психіки та поведінки | M4: усього | N4: з них у зв’язку | P4: усього | Q4: у тому числі
F5: усього | G5: у тому числі | N5: з одужанням, | O5: зі смертю | Q5: чоловіки | R5: сільське | S5: за віковими групами
G6: чоловіки | H6: сільське | I6: за віковими групами | N6: стійкою | O6: з різних | R6: населення | S6: малолітні | T6: діти | U6: молодь | V6: особи
H7: населення | I7: малолітні | J7: діти | K7: молодь | L7: особи похилого віку | N7: ремісією | O7: причин | V7: похилого віку
B9: А | C9: Б | D9: В | E9: 1 | F9: 2 | G9: 3 | H9: 4 | I9: 5 | J9: 6 | K9: 7 | L9: 8 | M9: 9 | N9: 10 | O9: 11 | P9: 12 | Q9: 13 | R9: 14 | S9: 15 | T9: 16 | U9: 17 | V9: 18
A10: f_[00:99] | B10: Усього | C10: 1.0 | D10: F00-F99 | E10: 1133 | F10: 615 | G10: 476 | H10: 335 | I10: 110 | J10: 126 | K10: 117 | L10: 59 | M10: 589 | N10: 397 | O10: 25 | P10: 3201 | Q10: 1860 | R10: 1672 | S10: 620 | T10: 739 | U10: 560 | V10: 449 | X10: =IF(E10>=F10,"Вірно","Помилка") -> Вірно | Y10: =IF(F10>=G10,"Вірно","Помилка") -> Вірно | Z10: =IF(F10>=H10,"Вірно","Помилка") -> Вірно | AA10: =IF(F10>=J10,"Вірно","Помилка") -> Вірно | AB10: =IF(J10>=I10,"Вірно","Помилка") -> Вірно | AC10: =IF(F10>=K10,"Вірно","Помилка") -> Вірно | AD10: =IF(F10>=L10,"Вірно","Помилка") -> Вірно | AE10: =IF(M10>=N10,"Вірно","Помилка") -> Вірно | AF10: =IF(M10>=O10,"Вірно","Помилка") -> Вірно | AG10: =IF(P10>=Q10,"Вірно","Помилка") -> Вірно | AH10: =IF(P10>=R10,"Вірно","Помилка") -> Вірно | AI10: =IF(P10>=T10,"Вірно","Помилка") -> Вірно | AJ10: =IF(T10>=S10,"Вірно","Помилка") -> Вірно | AK10: =IF(P10>=U10,"Вірно","Помилка") -> Вірно | AL10: =IF(P10>=V10,"Вірно","Помилка") -> Вірно | AM10: =IF((I10+K10+L10)<=F10,"Вірно","Помилка") -> Вірно | AN10: =IF((J10+L10)<=F10,"Вірно","Помилка") -> Вірно | AO10: =IF((N10+O10)<=M10,"Вірно","Помилка") -> Вірно | AP10: =IF((S10+U10+V10)<=P10,"Вірно","Помилка") -> Вірно | AQ10: =IF((T10+V10)<=P10,"Вірно","Помилка") -> Вірно
B11: у тому числі:
A12: f_0[0:9] | B12: органічні, включно із симптоматичними | C12: 2.0 | D12: F00-F09 | E12: 131 | F12: 36 | G12: 22 | H12: 17 | I12: 11 | J12: 13 | K12: 4 | L12: 15 | M12: 38 | N12: 3 | P12: 240 | Q12: 164 | R12: 186 | S12: 105 | T12: 116 | U12: 11 | V12: 30 | X12: =IF(E12>=F12,"Вірно","Помилка") -> Вірно | Y12: =IF(F12>=G12,"Вірно","Помилка") -> Вірно | Z12: =IF(F12>=H12,"Вірно","Помилка") -> Вірно | AA12: =IF(F12>=J12,"Вірно","Помилка") -> Вірно | AB12: =IF(J12>=I12,"Вірно","Помилка") -> Вірно | AC12: =IF(F12>=K12,"Вірно","Помилка") -> Вірно | AD12: =IF(F12>=L12,"Вірно","Помилка") -> Вірно | AE12: =IF(M12>=N12,"Вірно","Помилка") -> Вірно | AF12: =IF(M12>=O12,"Вірно","Помилка") -> Вірно | AG12: =IF(P12>=Q12,"Вірно","Помилка") -> Вірно | AH12: =IF(P12>=R12,"Вірно","Помилка") -> Вірно | AI12: =IF(P12>=T12,"Вірно","Помилка") -> Вірно | AJ12: =IF(T12>=S12,"Вірно","Помилка") -> Вірно | AK12: =IF(P12>=U12,"Вірно","Помилка") -> Вірно | AL12: =IF(P12>=V12,"Вірно","Помилка") -> Вірно | AM12: =IF((I12+K12+L12)<=F12,"Вірно","Помилка") -> Вірно | AN12: =IF((J12+L12)<=F12,"Вірно","Помилка") -> Вірно | AO12: =IF((N12+O12)<=M12,"Вірно","Помилка") -> Вірно | AP12: =IF((S12+U12+V12)<=P12,"Вірно","Помилка") -> Вірно | AQ12: =IF((T12+V12)<=P12,"Вірно","Помилка") -> Вірно
A13: f_0[0:3] | B13: з них деменція, усі форми | C13: 2.1 | D13: F00-F03 | E13: 1 | F13: 1 | G13: 1 | H13: 1 | L13: 1 | M13: 3 | P13: 1 | Q13: 1 | R13: 1 | V13: 1 | X13: =IF(E13>=F13,"Вірно","Помилка") -> Вірно | Y13: =IF(F13>=G13,"Вірно","Помилка") -> Вірно | Z13: =IF(F13>=H13,"Вірно","Помилка") -> Вірно | AA13: =IF(F13>=J13,"Вірно","Помилка") -> Вірно | AB13: =IF(J13>=I13,"Вірно","Помилка") -> Вірно | AC13: =IF(F13>=K13,"Вірно","Помилка") -> Вірно | AD13: =IF(F13>=L13,"Вірно","Помилка") -> Вірно | AE13: =IF(M13>=N13,"Вірно","Помилка") -> Вірно | AF13: =IF(M13>=O13,"Вірно","Помилка") -> Вірно | AG13: =IF(P13>=Q13,"Вірно","Помилка") -> Вірно | AH13: =IF(P13>=R13,"Вірно","Помилка") -> Вірно | AI13: =IF(P13>=T13,"Вірно","Помилка") -> Вірно | AJ13: =IF(T13>=S13,"Вірно","Помилка") -> Вірно | AK13: =IF(P13>=U13,"Вірно","Помилка") -> Вірно | AL13: =IF(P13>=V13,"Вірно","Помилка") -> Вірно | AM13: =IF((I13+K13+L13)<=F13,"Вірно","Помилка") -> Вірно | AN13: =IF((J13+L13)<=F13,"Вірно","Помилка") -> Вірно | AO13: =IF((N13+O13)<=M13,"Вірно","Помилка") -> Вірно | AP13: =IF((S13+U13+V13)<=P13,"Вірно","Помилка") -> Вірно | AQ13: =IF((T13+V13)<=P13,"Вірно","Помилка") -> Вірно
B14: у тому числі:
A15: f_00 | B15: деменція при хворобі Альцгеймера | C15: 2.1.1 | D15: F00 | X15: =IF(E15>=F15,"Вірно","Помилка") -> Вірно | Y15: =IF(F15>=G15,"Вірно","Помилка") -> Вірно | Z15: =IF(F15>=H15,"Вірно","Помилка") -> Вірно | AA15: =IF(F15>=J15,"Вірно","Помилка") -> Вірно | AB15: =IF(J15>=I15,"Вірно","Помилка") -> Вірно | AC15: =IF(F15>=K15,"Вірно","Помилка") -> Вірно | AD15: =IF(F15>=L15,"Вірно","Помилка") -> Вірно | AE15: =IF(M15>=N15,"Вірно","Помилка") -> Вірно | AF15: =IF(M15>=O15,"Вірно","Помилка") -> Вірно | AG15: =IF(P15>=Q15,"Вірно","Помилка") -> Вірно | AH15: =IF(P15>=R15,"Вірно","Помилка") -> Вірно | AI15: =IF(P15>=T15,"Вірно","Помилка") -> Вірно | AJ15: =IF(T15>=S15,"Вірно","Помилка") -> Вірно | AK15: =IF(P15>=U15,"Вірно","Помилка") -> Вірно | AL15: =IF(P15>=V15,"Вірно","Помилка") -> Вірно | AM15: =IF((I15+K15+L15)<=F15,"Вірно","Помилка") -> Вірно | AN15: =IF((J15+L15)<=F15,"Вірно","Помилка") -> Вірно | AO15: =IF((N15+O15)<=M15,"Вірно","Помилка") -> Вірно | AP15: =IF((S15+U15+V15)<=P15,"Вірно","Помилка") -> Вірно | AQ15: =IF((T15+V15)<=P15,"Вірно","Помилка") -> Вірно
A16: f_01 | B16: судинна деменція | C16: 2.1.2 | D16: F01 | E16: 1 | F16: 1 | G16: 1 | H16: 1 | L16: 1 | M16: 3 | P16: 1 | Q16: 1 | R16: 1 | V16: 1 | X16: =IF(E16>=F16,"Вірно","Помилка") -> Вірно | Y16: =IF(F16>=G16,"Вірно","Помилка") -> Вірно | Z16: =IF(F16>=H16,"Вірно","Помилка") -> Вірно | AA16: =IF(F16>=J16,"Вірно","Помилка") -> Вірно | AB16: =IF(J16>=I16,"Вірно","Помилка") -> Вірно | AC16: =IF(F16>=K16,"Вірно","Помилка") -> Вірно | AD16: =IF(F16>=L16,"Вірно","Помилка") -> Вірно | AE16: =IF(M16>=N16,"Вірно","Помилка") -> Вірно | AF16: =IF(M16>=O16,"Вірно","Помилка") -> Вірно | AG16: =IF(P16>=Q16,"Вірно","Помилка") -> Вірно | AH16: =IF(P16>=R16,"Вірно","Помилка") -> Вірно | AI16: =IF(P16>=T16,"Вірно","Помилка") -> Вірно | AJ16: =IF(T16>=S16,"Вірно","Помилка") -> Вірно | AK16: =IF(P16>=U16,"Вірно","Помилка") -> Вірно | AL16: =IF(P16>=V16,"Вірно","Помилка") -> Вірно | AM16: =IF((I16+K16+L16)<=F16,"Вірно","Помилка") -> Вірно | AN16: =IF((J16+L16)<=F16,"Вірно","Помилка") -> Вірно | AO16: =IF((N16+O16)<=M16,"Вірно","Помилка") -> Вірно | AP16: =IF((S16+U16+V16)<=P16,"Вірно","Помилка") -> Вірно | AQ16: =IF((T16+V16)<=P16,"Вірно","Помилка") -> Вірно
A17: f_06 | B17: інші психічні розлади органічної етіології | C17: 2.2 | D17: F06 | E17: 75 | F17: 11 | G17: 6 | H17: 5 | I17: 4 | J17: 5 | K17: 2 | L17: 3 | M17: 13 | N17: 2 | P17: 143 | Q17: 92 | R17: 124 | S17: 61 | T17: 71 | U17: 6 | V17: 6 | X17: =IF(E17>=F17,"Вірно","Помилка") -> Вірно | Y17: =IF(F17>=G17,"Вірно","Помилка") -> Вірно | Z17: =IF(F17>=H17,"Вірно","Помилка") -> Вірно | AA17: =IF(F17>=J17,"Вірно","Помилка") -> Вірно | AB17: =IF(J17>=I17,"Вірно","Помилка") -> Вірно | AC17: =IF(F17>=K17,"Вірно","Помилка") -> Вірно | AD17: =IF(F17>=L17,"Вірно","Помилка") -> Вірно | AE17: =IF(M17>=N17,"Вірно","Помилка") -> Вірно | AF17: =IF(M17>=O17,"Вірно","Помилка") -> Вірно | AG17: =IF(P17>=Q17,"Вірно","Помилка") -> Вірно | AH17: =IF(P17>=R17,"Вірно","Помилка") -> Вірно | AI17: =IF(P17>=T17,"Вірно","Помилка") -> Вірно | AJ17: =IF(T17>=S17,"Вірно","Помилка") -> Вірно | AK17: =IF(P17>=U17,"Вірно","Помилка") -> Вірно | AL17: =IF(P17>=V17,"Вірно","Помилка") -> Вірно | AM17: =IF((I17+K17+L17)<=F17,"Вірно","Помилка") -> Вірно | AN17: =IF((J17+L17)<=F17,"Вірно","Помилка") -> Вірно | AO17: =IF((N17+O17)<=M17,"Вірно","Помилка") -> Вірно | AP17: =IF((S17+U17+V17)<=P17,"Вірно","Помилка") -> Вірно | AQ17: =IF((T17+V17)<=P17,"Вірно","Помилка") -> Вірно
A18: f_07 | B18: розлади особистості та поведінки органічної етіології | C18: 2.3 | D18: F07 | E18: 55 | F18: 24 | G18: 14 | H18: 11 | I18: 7 | J18: 8 | K18: 2 | L18: 11 | M18: 5 | N18: 1 | P18: 96 | Q18: 71 | R18: 61 | S18: 44 | T18: 45 | U18: 5 | V18: 23 | X18: =IF(E18>=F18,"Вірно","Помилка") -> Вірно | Y18: =IF(F18>=G18,"Вірно","Помилка") -> Вірно | Z18: =IF(F18>=H18,"Вірно","Помилка") -> Вірно | AA18: =IF(F18>=J18,"Вірно","Помилка") -> Вірно | AB18: =IF(J18>=I18,"Вірно","Помилка") -> Вірно | AC18: =IF(F18>=K18,"Вірно","Помилка") -> Вірно | AD18: =IF(F18>=L18,"Вірно","Помилка") -> Вірно | AE18: =IF(M18>=N18,"Вірно","Помилка") -> Вірно | AF18: =IF(M18>=O18,"Вірно","Помилка") -> Вірно | AG18: =IF(P18>=Q18,"Вірно","Помилка") -> Вірно | AH18: =IF(P18>=R18,"Вірно","Помилка") -> Вірно | AI18: =IF(P18>=T18,"Вірно","Помилка") -> Вірно | AJ18: =IF(T18>=S18,"Вірно","Помилка") -> Вірно | AK18: =IF(P18>=U18,"Вірно","Помилка") -> Вірно | AL18: =IF(P18>=V18,"Вірно","Помилка") -> Вірно | AM18: =IF((I18+K18+L18)<=F18,"Вірно","Помилка") -> Вірно | AN18: =IF((J18+L18)<=F18,"Вірно","Помилка") -> Вірно | AO18: =IF((N18+O18)<=M18,"Вірно","Помилка") -> Вірно | AP18: =IF((S18+U18+V18)<=P18,"Вірно","Помилка") -> Вірно | AQ18: =IF((T18+V18)<=P18,"Вірно","Помилка") -> Вірно
A19: f_0_epi | B19: внаслідок епілепсії | C19: 2.4 | D19: F02.8x3, F06.x3, F07.83 | M19: 17 | X19: =IF(E19>=F19,"Вірно","Помилка") -> Вірно | Y19: =IF(F19>=G19,"Вірно","Помилка") -> Вірно | Z19: =IF(F19>=H19,"Вірно","Помилка") -> Вірно | AA19: =IF(F19>=J19,"Вірно","Помилка") -> Вірно | AB19: =IF(J19>=I19,"Вірно","Помилка") -> Вірно | AC19: =IF(F19>=K19,"Вірно","Помилка") -> Вірно | AD19: =IF(F19>=L19,"Вірно","Помилка") -> Вірно | AE19: =IF(M19>=N19,"Вірно","Помилка") -> Вірно | AF19: =IF(M19>=O19,"Вірно","Помилка") -> Вірно | AG19: =IF(P19>=Q19,"Вірно","Помилка") -> Вірно | AH19: =IF(P19>=R19,"Вірно","Помилка") -> Вірно | AI19: =IF(P19>=T19,"Вірно","Помилка") -> Вірно | AJ19: =IF(T19>=S19,"Вірно","Помилка") -> Вірно | AK19: =IF(P19>=U19,"Вірно","Помилка") -> Вірно | AL19: =IF(P19>=V19,"Вірно","Помилка") -> Вірно | AM19: =IF((I19+K19+L19)<=F19,"Вірно","Помилка") -> Вірно | AN19: =IF((J19+L19)<=F19,"Вірно","Помилка") -> Вірно | AO19: =IF((N19+O19)<=M19,"Вірно","Помилка") -> Вірно | AP19: =IF((S19+U19+V19)<=P19,"Вірно","Помилка") -> Вірно | AQ19: =IF((T19+V19)<=P19,"Вірно","Помилка") -> Вірно
A20: f_1[0:9] | B20: внаслідок уживання ПАР | C20: 3.0 | D20: F10-F19 | E20: 408 | F20: 408 | G20: 351 | H20: 205 | K20: 91 | L20: 41 | M20: 459 | N20: 378 | O20: 25 | P20: 1186 | Q20: 1080 | R20: 783 | U20: 214 | V20: 191 | X20: =IF(E20>=F20,"Вірно","Помилка") -> Вірно | Y20: =IF(F20>=G20,"Вірно","Помилка") -> Вірно | Z20: =IF(F20>=H20,"Вірно","Помилка") -> Вірно | AA20: =IF(F20>=J20,"Вірно","Помилка") -> Вірно | AB20: =IF(J20>=I20,"Вірно","Помилка") -> Вірно | AC20: =IF(F20>=K20,"Вірно","Помилка") -> Вірно | AD20: =IF(F20>=L20,"Вірно","Помилка") -> Вірно | AE20: =IF(M20>=N20,"Вірно","Помилка") -> Вірно | AF20: =IF(M20>=O20,"Вірно","Помилка") -> Вірно | AG20: =IF(P20>=Q20,"Вірно","Помилка") -> Вірно | AH20: =IF(P20>=R20,"Вірно","Помилка") -> Вірно | AI20: =IF(P20>=T20,"Вірно","Помилка") -> Вірно | AJ20: =IF(T20>=S20,"Вірно","Помилка") -> Вірно | AK20: =IF(P20>=U20,"Вірно","Помилка") -> Вірно | AL20: =IF(P20>=V20,"Вірно","Помилка") -> Вірно | AM20: =IF((I20+K20+L20)<=F20,"Вірно","Помилка") -> Вірно | AN20: =IF((J20+L20)<=F20,"Вірно","Помилка") -> Вірно | AO20: =IF((N20+O20)<=M20,"Вірно","Помилка") -> Вірно | AP20: =IF((S20+U20+V20)<=P20,"Вірно","Помилка") -> Вірно | AQ20: =IF((T20+V20)<=P20,"Вірно","Помилка") -> Вірно
B21: з них:
A22: f_1[0:9].[0:1] | B22: гостра інтоксикація та вживання зі шкідливими наслідками | C22: 3.1 | D22: F1x.0,1 | E22: 377 | F22: 377 | G22: 320 | H22: 185 | K22: 84 | L22: 37 | M22: 378 | N22: 378 | P22: 377 | Q22: 320 | R22: 185 | U22: 84 | V22: 37 | X22: =IF(E22>=F22,"Вірно","Помилка") -> Вірно | Y22: =IF(F22>=G22,"Вірно","Помилка") -> Вірно | Z22: =IF(F22>=H22,"Вірно","Помилка") -> Вірно | AA22: =IF(F22>=J22,"Вірно","Помилка") -> Вірно | AB22: =IF(J22>=I22,"Вірно","Помилка") -> Вірно | AC22: =IF(F22>=K22,"Вірно","Помилка") -> Вірно | AD22: =IF(F22>=L22,"Вірно","Помилка") -> Вірно | AE22: =IF(M22>=N22,"Вірно","Помилка") -> Вірно | AF22: =IF(M22>=O22,"Вірно","Помилка") -> Вірно | AG22: =IF(P22>=Q22,"Вірно","Помилка") -> Вірно | AH22: =IF(P22>=R22,"Вірно","Помилка") -> Вірно | AI22: =IF(P22>=T22,"Вірно","Помилка") -> Вірно | AJ22: =IF(T22>=S22,"Вірно","Помилка") -> Вірно | AK22: =IF(P22>=U22,"Вірно","Помилка") -> Вірно | AL22: =IF(P22>=V22,"Вірно","Помилка") -> Вірно | AM22: =IF((I22+K22+L22)<=F22,"Вірно","Помилка") -> Вірно | AN22: =IF((J22+L22)<=F22,"Вірно","Помилка") -> Вірно | AO22: =IF((N22+O22)<=M22,"Вірно","Помилка") -> Вірно | AP22: =IF((S22+U22+V22)<=P22,"Вірно","Помилка") -> Вірно | AQ22: =IF((T22+V22)<=P22,"Вірно","Помилка") -> Вірно
B23: у тому числі внаслідок уживання:
A24: f_10.[0:1] | B24: алкоголю | C24: 3.1.1 | D24: F10.0,1 | E24: 231 | F24: 231 | G24: 219 | H24: 112 | K24: 35 | L24: 32 | M24: 220 | N24: 220 | P24: 231 | Q24: 219 | R24: 112 | U24: 35 | V24: 32 | X24: =IF(E24>=F24,"Вірно","Помилка") -> Вірно | Y24: =IF(F24>=G24,"Вірно","Помилка") -> Вірно | Z24: =IF(F24>=H24,"Вірно","Помилка") -> Вірно | AA24: =IF(F24>=J24,"Вірно","Помилка") -> Вірно | AB24: =IF(J24>=I24,"Вірно","Помилка") -> Вірно | AC24: =IF(F24>=K24,"Вірно","Помилка") -> Вірно | AD24: =IF(F24>=L24,"Вірно","Помилка") -> Вірно | AE24: =IF(M24>=N24,"Вірно","Помилка") -> Вірно | AF24: =IF(M24>=O24,"Вірно","Помилка") -> Вірно | AG24: =IF(P24>=Q24,"Вірно","Помилка") -> Вірно | AH24: =IF(P24>=R24,"Вірно","Помилка") -> Вірно | AI24: =IF(P24>=T24,"Вірно","Помилка") -> Вірно | AJ24: =IF(T24>=S24,"Вірно","Помилка") -> Вірно | AK24: =IF(P24>=U24,"Вірно","Помилка") -> Вірно | AL24: =IF(P24>=V24,"Вірно","Помилка") -> Вірно | AM24: =IF((I24+K24+L24)<=F24,"Вірно","Помилка") -> Вірно | AN24: =IF((J24+L24)<=F24,"Вірно","Помилка") -> Вірно | AO24: =IF((N24+O24)<=M24,"Вірно","Помилка") -> Вірно | AP24: =IF((S24+U24+V24)<=P24,"Вірно","Помилка") -> Вірно | AQ24: =IF((T24+V24)<=P24,"Вірно","Помилка") -> Вірно
A25: f_11.[0:1] | B25: опіоїдів | C25: 3.1.2 | D25: F11.0,1 | M25: 3 | N25: 3 | X25: =IF(E25>=F25,"Вірно","Помилка") -> Вірно | Y25: =IF(F25>=G25,"Вірно","Помилка") -> Вірно | Z25: =IF(F25>=H25,"Вірно","Помилка") -> Вірно | AA25: =IF(F25>=J25,"Вірно","Помилка") -> Вірно | AB25: =IF(J25>=I25,"Вірно","Помилка") -> Вірно | AC25: =IF(F25>=K25,"Вірно","Помилка") -> Вірно | AD25: =IF(F25>=L25,"Вірно","Помилка") -> Вірно | AE25: =IF(M25>=N25,"Вірно","Помилка") -> Вірно | AF25: =IF(M25>=O25,"Вірно","Помилка") -> Вірно | AG25: =IF(P25>=Q25,"Вірно","Помилка") -> Вірно | AH25: =IF(P25>=R25,"Вірно","Помилка") -> Вірно | AI25: =IF(P25>=T25,"Вірно","Помилка") -> Вірно | AJ25: =IF(T25>=S25,"Вірно","Помилка") -> Вірно | AK25: =IF(P25>=U25,"Вірно","Помилка") -> Вірно | AL25: =IF(P25>=V25,"Вірно","Помилка") -> Вірно | AM25: =IF((I25+K25+L25)<=F25,"Вірно","Помилка") -> Вірно | AN25: =IF((J25+L25)<=F25,"Вірно","Помилка") -> Вірно | AO25: =IF((N25+O25)<=M25,"Вірно","Помилка") -> Вірно | AP25: =IF((S25+U25+V25)<=P25,"Вірно","Помилка") -> Вірно | AQ25: =IF((T25+V25)<=P25,"Вірно","Помилка") -> Вірно
A26: f_11.[0:1]_opm | B26: з них: опій | C26: 3.1.2.1 | D26: F11.0,1 (частина) | M26: 3 | N26: 3 | X26: =IF(E26>=F26,"Вірно","Помилка") -> Вірно | Y26: =IF(F26>=G26,"Вірно","Помилка") -> Вірно | Z26: =IF(F26>=H26,"Вірно","Помилка") -> Вірно | AA26: =IF(F26>=J26,"Вірно","Помилка") -> Вірно | AB26: =IF(J26>=I26,"Вірно","Помилка") -> Вірно | AC26: =IF(F26>=K26,"Вірно","Помилка") -> Вірно | AD26: =IF(F26>=L26,"Вірно","Помилка") -> Вірно | AE26: =IF(M26>=N26,"Вірно","Помилка") -> Вірно | AF26: =IF(M26>=O26,"Вірно","Помилка") -> Вірно | AG26: =IF(P26>=Q26,"Вірно","Помилка") -> Вірно | AH26: =IF(P26>=R26,"Вірно","Помилка") -> Вірно | AI26: =IF(P26>=T26,"Вірно","Помилка") -> Вірно | AJ26: =IF(T26>=S26,"Вірно","Помилка") -> Вірно | AK26: =IF(P26>=U26,"Вірно","Помилка") -> Вірно | AL26: =IF(P26>=V26,"Вірно","Помилка") -> Вірно | AM26: =IF((I26+K26+L26)<=F26,"Вірно","Помилка") -> Вірно | AN26: =IF((J26+L26)<=F26,"Вірно","Помилка") -> Вірно | AO26: =IF((N26+O26)<=M26,"Вірно","Помилка") -> Вірно | AP26: =IF((S26+U26+V26)<=P26,"Вірно","Помилка") -> Вірно | AQ26: =IF((T26+V26)<=P26,"Вірно","Помилка") -> Вірно
A27: f_11.[0:1]_opm_a | B27: опій ацетильований | C27: 3.1.2.2 | D27: F11.0,1 (частина) | X27: =IF(E27>=F27,"Вірно","Помилка") -> Вірно | Y27: =IF(F27>=G27,"Вірно","Помилка") -> Вірно | Z27: =IF(F27>=H27,"Вірно","Помилка") -> Вірно | AA27: =IF(F27>=J27,"Вірно","Помилка") -> Вірно | AB27: =IF(J27>=I27,"Вірно","Помилка") -> Вірно | AC27: =IF(F27>=K27,"Вірно","Помилка") -> Вірно | AD27: =IF(F27>=L27,"Вірно","Помилка") -> Вірно | AE27: =IF(M27>=N27,"Вірно","Помилка") -> Вірно | AF27: =IF(M27>=O27,"Вірно","Помилка") -> Вірно | AG27: =IF(P27>=Q27,"Вірно","Помилка") -> Вірно | AH27: =IF(P27>=R27,"Вірно","Помилка") -> Вірно | AI27: =IF(P27>=T27,"Вірно","Помилка") -> Вірно | AJ27: =IF(T27>=S27,"Вірно","Помилка") -> Вірно | AK27: =IF(P27>=U27,"Вірно","Помилка") -> Вірно | AL27: =IF(P27>=V27,"Вірно","Помилка") -> Вірно | AM27: =IF((I27+K27+L27)<=F27,"Вірно","Помилка") -> Вірно | AN27: =IF((J27+L27)<=F27,"Вірно","Помилка") -> Вірно | AO27: =IF((N27+O27)<=M27,"Вірно","Помилка") -> Вірно | AP27: =IF((S27+U27+V27)<=P27,"Вірно","Помилка") -> Вірно | AQ27: =IF((T27+V27)<=P27,"Вірно","Помилка") -> Вірно
A28: f_11.[0:1]_hrn | B28: героїн | C28: 3.1.2.3 | D28: F11.0,1 (частина) | X28: =IF(E28>=F28,"Вірно","Помилка") -> Вірно | Y28: =IF(F28>=G28,"Вірно","Помилка") -> Вірно | Z28: =IF(F28>=H28,"Вірно","Помилка") -> Вірно | AA28: =IF(F28>=J28,"Вірно","Помилка") -> Вірно | AB28: =IF(J28>=I28,"Вірно","Помилка") -> Вірно | AC28: =IF(F28>=K28,"Вірно","Помилка") -> Вірно | AD28: =IF(F28>=L28,"Вірно","Помилка") -> Вірно | AE28: =IF(M28>=N28,"Вірно","Помилка") -> Вірно | AF28: =IF(M28>=O28,"Вірно","Помилка") -> Вірно | AG28: =IF(P28>=Q28,"Вірно","Помилка") -> Вірно | AH28: =IF(P28>=R28,"Вірно","Помилка") -> Вірно | AI28: =IF(P28>=T28,"Вірно","Помилка") -> Вірно | AJ28: =IF(T28>=S28,"Вірно","Помилка") -> Вірно | AK28: =IF(P28>=U28,"Вірно","Помилка") -> Вірно | AL28: =IF(P28>=V28,"Вірно","Помилка") -> Вірно | AM28: =IF((I28+K28+L28)<=F28,"Вірно","Помилка") -> Вірно | AN28: =IF((J28+L28)<=F28,"Вірно","Помилка") -> Вірно | AO28: =IF((N28+O28)<=M28,"Вірно","Помилка") -> Вірно | AP28: =IF((S28+U28+V28)<=P28,"Вірно","Помилка") -> Вірно | AQ28: =IF((T28+V28)<=P28,"Вірно","Помилка") -> Вірно
A29: f_11.[0:1]_mtd | B29: метадон | C29: 3.1.2.4 | D29: F11.0,1 (частина) | X29: =IF(E29>=F29,"Вірно","Помилка") -> Вірно | Y29: =IF(F29>=G29,"Вірно","Помилка") -> Вірно | Z29: =IF(F29>=H29,"Вірно","Помилка") -> Вірно | AA29: =IF(F29>=J29,"Вірно","Помилка") -> Вірно | AB29: =IF(J29>=I29,"Вірно","Помилка") -> Вірно | AC29: =IF(F29>=K29,"Вірно","Помилка") -> Вірно | AD29: =IF(F29>=L29,"Вірно","Помилка") -> Вірно | AE29: =IF(M29>=N29,"Вірно","Помилка") -> Вірно | AF29: =IF(M29>=O29,"Вірно","Помилка") -> Вірно | AG29: =IF(P29>=Q29,"Вірно","Помилка") -> Вірно | AH29: =IF(P29>=R29,"Вірно","Помилка") -> Вірно | AI29: =IF(P29>=T29,"Вірно","Помилка") -> Вірно | AJ29: =IF(T29>=S29,"Вірно","Помилка") -> Вірно | AK29: =IF(P29>=U29,"Вірно","Помилка") -> Вірно | AL29: =IF(P29>=V29,"Вірно","Помилка") -> Вірно | AM29: =IF((I29+K29+L29)<=F29,"Вірно","Помилка") -> Вірно | AN29: =IF((J29+L29)<=F29,"Вірно","Помилка") -> Вірно | AO29: =IF((N29+O29)<=M29,"Вірно","Помилка") -> Вірно | AP29: =IF((S29+U29+V29)<=P29,"Вірно","Помилка") -> Вірно | AQ29: =IF((T29+V29)<=P29,"Вірно","Помилка") -> Вірно
A30: f_11.[0:1]_bpr | B30: бупренорфін | C30: 3.1.2.5 | D30: F11.0,1 (частина) | X30: =IF(E30>=F30,"Вірно","Помилка") -> Вірно | Y30: =IF(F30>=G30,"Вірно","Помилка") -> Вірно | Z30: =IF(F30>=H30,"Вірно","Помилка") -> Вірно | AA30: =IF(F30>=J30,"Вірно","Помилка") -> Вірно | AB30: =IF(J30>=I30,"Вірно","Помилка") -> Вірно | AC30: =IF(F30>=K30,"Вірно","Помилка") -> Вірно | AD30: =IF(F30>=L30,"Вірно","Помилка") -> Вірно | AE30: =IF(M30>=N30,"Вірно","Помилка") -> Вірно | AF30: =IF(M30>=O30,"Вірно","Помилка") -> Вірно | AG30: =IF(P30>=Q30,"Вірно","Помилка") -> Вірно | AH30: =IF(P30>=R30,"Вірно","Помилка") -> Вірно | AI30: =IF(P30>=T30,"Вірно","Помилка") -> Вірно | AJ30: =IF(T30>=S30,"Вірно","Помилка") -> Вірно | AK30: =IF(P30>=U30,"Вірно","Помилка") -> Вірно | AL30: =IF(P30>=V30,"Вірно","Помилка") -> Вірно | AM30: =IF((I30+K30+L30)<=F30,"Вірно","Помилка") -> Вірно | AN30: =IF((J30+L30)<=F30,"Вірно","Помилка") -> Вірно | AO30: =IF((N30+O30)<=M30,"Вірно","Помилка") -> Вірно | AP30: =IF((S30+U30+V30)<=P30,"Вірно","Помилка") -> Вірно | AQ30: =IF((T30+V30)<=P30,"Вірно","Помилка") -> Вірно
A31: f_11.[0:1]_mrf | B31: морфін | C31: 3.1.2.6 | D31: F11.0,1 (частина) | X31: =IF(E31>=F31,"Вірно","Помилка") -> Вірно | Y31: =IF(F31>=G31,"Вірно","Помилка") -> Вірно | Z31: =IF(F31>=H31,"Вірно","Помилка") -> Вірно | AA31: =IF(F31>=J31,"Вірно","Помилка") -> Вірно | AB31: =IF(J31>=I31,"Вірно","Помилка") -> Вірно | AC31: =IF(F31>=K31,"Вірно","Помилка") -> Вірно | AD31: =IF(F31>=L31,"Вірно","Помилка") -> Вірно | AE31: =IF(M31>=N31,"Вірно","Помилка") -> Вірно | AF31: =IF(M31>=O31,"Вірно","Помилка") -> Вірно | AG31: =IF(P31>=Q31,"Вірно","Помилка") -> Вірно | AH31: =IF(P31>=R31,"Вірно","Помилка") -> Вірно | AI31: =IF(P31>=T31,"Вірно","Помилка") -> Вірно | AJ31: =IF(T31>=S31,"Вірно","Помилка") -> Вірно | AK31: =IF(P31>=U31,"Вірно","Помилка") -> Вірно | AL31: =IF(P31>=V31,"Вірно","Помилка") -> Вірно | AM31: =IF((I31+K31+L31)<=F31,"Вірно","Помилка") -> Вірно | AN31: =IF((J31+L31)<=F31,"Вірно","Помилка") -> Вірно | AO31: =IF((N31+O31)<=M31,"Вірно","Помилка") -> Вірно | AP31: =IF((S31+U31+V31)<=P31,"Вірно","Помилка") -> Вірно | AQ31: =IF((T31+V31)<=P31,"Вірно","Помилка") -> Вірно
A32: f_11.[0:1]_fnt | B32: фентаніл та його похідні | C32: 3.1.2.7 | D32: F11.0,1 (частина) | X32: =IF(E32>=F32,"Вірно","Помилка") -> Вірно | Y32: =IF(F32>=G32,"Вірно","Помилка") -> Вірно | Z32: =IF(F32>=H32,"Вірно","Помилка") -> Вірно | AA32: =IF(F32>=J32,"Вірно","Помилка") -> Вірно | AB32: =IF(J32>=I32,"Вірно","Помилка") -> Вірно | AC32: =IF(F32>=K32,"Вірно","Помилка") -> Вірно | AD32: =IF(F32>=L32,"Вірно","Помилка") -> Вірно | AE32: =IF(M32>=N32,"Вірно","Помилка") -> Вірно | AF32: =IF(M32>=O32,"Вірно","Помилка") -> Вірно | AG32: =IF(P32>=Q32,"Вірно","Помилка") -> Вірно | AH32: =IF(P32>=R32,"Вірно","Помилка") -> Вірно | AI32: =IF(P32>=T32,"Вірно","Помилка") -> Вірно | AJ32: =IF(T32>=S32,"Вірно","Помилка") -> Вірно | AK32: =IF(P32>=U32,"Вірно","Помилка") -> Вірно | AL32: =IF(P32>=V32,"Вірно","Помилка") -> Вірно | AM32: =IF((I32+K32+L32)<=F32,"Вірно","Помилка") -> Вірно | AN32: =IF((J32+L32)<=F32,"Вірно","Помилка") -> Вірно | AO32: =IF((N32+O32)<=M32,"Вірно","Помилка") -> Вірно | AP32: =IF((S32+U32+V32)<=P32,"Вірно","Помилка") -> Вірно | AQ32: =IF((T32+V32)<=P32,"Вірно","Помилка") -> Вірно
A33: f_11.[0:1]_cdn | B33: кодеїн та кодеїновмісні препарати | C33: 3.1.2.8 | D33: F11.0,1 (частина) | X33: =IF(E33>=F33,"Вірно","Помилка") -> Вірно | Y33: =IF(F33>=G33,"Вірно","Помилка") -> Вірно | Z33: =IF(F33>=H33,"Вірно","Помилка") -> Вірно | AA33: =IF(F33>=J33,"Вірно","Помилка") -> Вірно | AB33: =IF(J33>=I33,"Вірно","Помилка") -> Вірно | AC33: =IF(F33>=K33,"Вірно","Помилка") -> Вірно | AD33: =IF(F33>=L33,"Вірно","Помилка") -> Вірно | AE33: =IF(M33>=N33,"Вірно","Помилка") -> Вірно | AF33: =IF(M33>=O33,"Вірно","Помилка") -> Вірно | AG33: =IF(P33>=Q33,"Вірно","Помилка") -> Вірно | AH33: =IF(P33>=R33,"Вірно","Помилка") -> Вірно | AI33: =IF(P33>=T33,"Вірно","Помилка") -> Вірно | AJ33: =IF(T33>=S33,"Вірно","Помилка") -> Вірно | AK33: =IF(P33>=U33,"Вірно","Помилка") -> Вірно | AL33: =IF(P33>=V33,"Вірно","Помилка") -> Вірно | AM33: =IF((I33+K33+L33)<=F33,"Вірно","Помилка") -> Вірно | AN33: =IF((J33+L33)<=F33,"Вірно","Помилка") -> Вірно | AO33: =IF((N33+O33)<=M33,"Вірно","Помилка") -> Вірно | AP33: =IF((S33+U33+V33)<=P33,"Вірно","Помилка") -> Вірно | AQ33: =IF((T33+V33)<=P33,"Вірно","Помилка") -> Вірно
A34: f_11.[0:1]_trm | B34: трамадол | C34: 3.1.2.9 | D34: F11.0,1 (частина) | X34: =IF(E34>=F34,"Вірно","Помилка") -> Вірно | Y34: =IF(F34>=G34,"Вірно","Помилка") -> Вірно | Z34: =IF(F34>=H34,"Вірно","Помилка") -> Вірно | AA34: =IF(F34>=J34,"Вірно","Помилка") -> Вірно | AB34: =IF(J34>=I34,"Вірно","Помилка") -> Вірно | AC34: =IF(F34>=K34,"Вірно","Помилка") -> Вірно | AD34: =IF(F34>=L34,"Вірно","Помилка") -> Вірно | AE34: =IF(M34>=N34,"Вірно","Помилка") -> Вірно | AF34: =IF(M34>=O34,"Вірно","Помилка") -> Вірно | AG34: =IF(P34>=Q34,"Вірно","Помилка") -> Вірно | AH34: =IF(P34>=R34,"Вірно","Помилка") -> Вірно | AI34: =IF(P34>=T34,"Вірно","Помилка") -> Вірно | AJ34: =IF(T34>=S34,"Вірно","Помилка") -> Вірно | AK34: =IF(P34>=U34,"Вірно","Помилка") -> Вірно | AL34: =IF(P34>=V34,"Вірно","Помилка") -> Вірно | AM34: =IF((I34+K34+L34)<=F34,"Вірно","Помилка") -> Вірно | AN34: =IF((J34+L34)<=F34,"Вірно","Помилка") -> Вірно | AO34: =IF((N34+O34)<=M34,"Вірно","Помилка") -> Вірно | AP34: =IF((S34+U34+V34)<=P34,"Вірно","Помилка") -> Вірно | AQ34: =IF((T34+V34)<=P34,"Вірно","Помилка") -> Вірно
A35: f_11.[0:1]_nlb | B35: налбуфін | C35: 3.1.2.10 | D35: F11.0,1 (частина) | X35: =IF(E35>=F35,"Вірно","Помилка") -> Вірно | Y35: =IF(F35>=G35,"Вірно","Помилка") -> Вірно | Z35: =IF(F35>=H35,"Вірно","Помилка") -> Вірно | AA35: =IF(F35>=J35,"Вірно","Помилка") -> Вірно | AB35: =IF(J35>=I35,"Вірно","Помилка") -> Вірно | AC35: =IF(F35>=K35,"Вірно","Помилка") -> Вірно | AD35: =IF(F35>=L35,"Вірно","Помилка") -> Вірно | AE35: =IF(M35>=N35,"Вірно","Помилка") -> Вірно | AF35: =IF(M35>=O35,"Вірно","Помилка") -> Вірно | AG35: =IF(P35>=Q35,"Вірно","Помилка") -> Вірно | AH35: =IF(P35>=R35,"Вірно","Помилка") -> Вірно | AI35: =IF(P35>=T35,"Вірно","Помилка") -> Вірно | AJ35: =IF(T35>=S35,"Вірно","Помилка") -> Вірно | AK35: =IF(P35>=U35,"Вірно","Помилка") -> Вірно | AL35: =IF(P35>=V35,"Вірно","Помилка") -> Вірно | AM35: =IF((I35+K35+L35)<=F35,"Вірно","Помилка") -> Вірно | AN35: =IF((J35+L35)<=F35,"Вірно","Помилка") -> Вірно | AO35: =IF((N35+O35)<=M35,"Вірно","Помилка") -> Вірно | AP35: =IF((S35+U35+V35)<=P35,"Вірно","Помилка") -> Вірно | AQ35: =IF((T35+V35)<=P35,"Вірно","Помилка") -> Вірно
A36: f_11.[0:1]_opd_othr_s | B36: інші синтетичні опіоїди | C36: 3.1.2.11 | D36: F11.0,1 (частина) | X36: =IF(E36>=F36,"Вірно","Помилка") -> Вірно | Y36: =IF(F36>=G36,"Вірно","Помилка") -> Вірно | Z36: =IF(F36>=H36,"Вірно","Помилка") -> Вірно | AA36: =IF(F36>=J36,"Вірно","Помилка") -> Вірно | AB36: =IF(J36>=I36,"Вірно","Помилка") -> Вірно | AC36: =IF(F36>=K36,"Вірно","Помилка") -> Вірно | AD36: =IF(F36>=L36,"Вірно","Помилка") -> Вірно | AE36: =IF(M36>=N36,"Вірно","Помилка") -> Вірно | AF36: =IF(M36>=O36,"Вірно","Помилка") -> Вірно | AG36: =IF(P36>=Q36,"Вірно","Помилка") -> Вірно | AH36: =IF(P36>=R36,"Вірно","Помилка") -> Вірно | AI36: =IF(P36>=T36,"Вірно","Помилка") -> Вірно | AJ36: =IF(T36>=S36,"Вірно","Помилка") -> Вірно | AK36: =IF(P36>=U36,"Вірно","Помилка") -> Вірно | AL36: =IF(P36>=V36,"Вірно","Помилка") -> Вірно | AM36: =IF((I36+K36+L36)<=F36,"Вірно","Помилка") -> Вірно | AN36: =IF((J36+L36)<=F36,"Вірно","Помилка") -> Вірно | AO36: =IF((N36+O36)<=M36,"Вірно","Помилка") -> Вірно | AP36: =IF((S36+U36+V36)<=P36,"Вірно","Помилка") -> Вірно | AQ36: =IF((T36+V36)<=P36,"Вірно","Помилка") -> Вірно
A37: f_12.[0:1] | B37: канабіноїдів | C37: 3.1.3 | D37: F12.0,1 | E37: 2 | F37: 2 | G37: 2 | K37: 2 | M37: 4 | N37: 4 | P37: 2 | Q37: 2 | U37: 2 | X37: =IF(E37>=F37,"Вірно","Помилка") -> Вірно | Y37: =IF(F37>=G37,"Вірно","Помилка") -> Вірно | Z37: =IF(F37>=H37,"Вірно","Помилка") -> Вірно | AA37: =IF(F37>=J37,"Вірно","Помилка") -> Вірно | AB37: =IF(J37>=I37,"Вірно","Помилка") -> Вірно | AC37: =IF(F37>=K37,"Вірно","Помилка") -> Вірно | AD37: =IF(F37>=L37,"Вірно","Помилка") -> Вірно | AE37: =IF(M37>=N37,"Вірно","Помилка") -> Вірно | AF37: =IF(M37>=O37,"Вірно","Помилка") -> Вірно | AG37: =IF(P37>=Q37,"Вірно","Помилка") -> Вірно | AH37: =IF(P37>=R37,"Вірно","Помилка") -> Вірно | AI37: =IF(P37>=T37,"Вірно","Помилка") -> Вірно | AJ37: =IF(T37>=S37,"Вірно","Помилка") -> Вірно | AK37: =IF(P37>=U37,"Вірно","Помилка") -> Вірно | AL37: =IF(P37>=V37,"Вірно","Помилка") -> Вірно | AM37: =IF((I37+K37+L37)<=F37,"Вірно","Помилка") -> Вірно | AN37: =IF((J37+L37)<=F37,"Вірно","Помилка") -> Вірно | AO37: =IF((N37+O37)<=M37,"Вірно","Помилка") -> Вірно | AP37: =IF((S37+U37+V37)<=P37,"Вірно","Помилка") -> Вірно | AQ37: =IF((T37+V37)<=P37,"Вірно","Помилка") -> Вірно
A38: f_12.[0:1]_cnb_synth | B38: з них синтетичні канабіноїди | C38: 3.1.3.1 | D38: F12.0,1 (частина) | X38: =IF(E38>=F38,"Вірно","Помилка") -> Вірно | Y38: =IF(F38>=G38,"Вірно","Помилка") -> Вірно | Z38: =IF(F38>=H38,"Вірно","Помилка") -> Вірно | AA38: =IF(F38>=J38,"Вірно","Помилка") -> Вірно | AB38: =IF(J38>=I38,"Вірно","Помилка") -> Вірно | AC38: =IF(F38>=K38,"Вірно","Помилка") -> Вірно | AD38: =IF(F38>=L38,"Вірно","Помилка") -> Вірно | AE38: =IF(M38>=N38,"Вірно","Помилка") -> Вірно | AF38: =IF(M38>=O38,"Вірно","Помилка") -> Вірно | AG38: =IF(P38>=Q38,"Вірно","Помилка") -> Вірно | AH38: =IF(P38>=R38,"Вірно","Помилка") -> Вірно | AI38: =IF(P38>=T38,"Вірно","Помилка") -> Вірно | AJ38: =IF(T38>=S38,"Вірно","Помилка") -> Вірно | AK38: =IF(P38>=U38,"Вірно","Помилка") -> Вірно | AL38: =IF(P38>=V38,"Вірно","Помилка") -> Вірно | AM38: =IF((I38+K38+L38)<=F38,"Вірно","Помилка") -> Вірно | AN38: =IF((J38+L38)<=F38,"Вірно","Помилка") -> Вірно | AO38: =IF((N38+O38)<=M38,"Вірно","Помилка") -> Вірно | AP38: =IF((S38+U38+V38)<=P38,"Вірно","Помилка") -> Вірно | AQ38: =IF((T38+V38)<=P38,"Вірно","Помилка") -> Вірно
A39: f_13.[0:1] | B39: седативних чи снодійних засобів | C39: 3.1.4 | D39: F13.0,1 | E39: 15 | F39: 15 | G39: 9 | H39: 8 | K39: 9 | L39: 5 | M39: 15 | N39: 15 | P39: 15 | Q39: 9 | R39: 8 | U39: 9 | V39: 5 | X39: =IF(E39>=F39,"Вірно","Помилка") -> Вірно | Y39: =IF(F39>=G39,"Вірно","Помилка") -> Вірно | Z39: =IF(F39>=H39,"Вірно","Помилка") -> Вірно | AA39: =IF(F39>=J39,"Вірно","Помилка") -> Вірно | AB39: =IF(J39>=I39,"Вірно","Помилка") -> Вірно | AC39: =IF(F39>=K39,"Вірно","Помилка") -> Вірно | AD39: =IF(F39>=L39,"Вірно","Помилка") -> Вірно | AE39: =IF(M39>=N39,"Вірно","Помилка") -> Вірно | AF39: =IF(M39>=O39,"Вірно","Помилка") -> Вірно | AG39: =IF(P39>=Q39,"Вірно","Помилка") -> Вірно | AH39: =IF(P39>=R39,"Вірно","Помилка") -> Вірно | AI39: =IF(P39>=T39,"Вірно","Помилка") -> Вірно | AJ39: =IF(T39>=S39,"Вірно","Помилка") -> Вірно | AK39: =IF(P39>=U39,"Вірно","Помилка") -> Вірно | AL39: =IF(P39>=V39,"Вірно","Помилка") -> Вірно | AM39: =IF((I39+K39+L39)<=F39,"Вірно","Помилка") -> Вірно | AN39: =IF((J39+L39)<=F39,"Вірно","Помилка") -> Вірно | AO39: =IF((N39+O39)<=M39,"Вірно","Помилка") -> Вірно | AP39: =IF((S39+U39+V39)<=P39,"Вірно","Помилка") -> Вірно | AQ39: =IF((T39+V39)<=P39,"Вірно","Помилка") -> Вірно
A40: f_13.[0:1]_bzd | B40: з них: бензодіазепіни | C40: 3.1.4.1 | D40: F13.0,1 (частина) | E40: 10 | F40: 10 | G40: 5 | H40: 3 | K40: 4 | L40: 4 | M40: 10 | N40: 10 | P40: 10 | Q40: 5 | R40: 3 | U40: 4 | V40: 4 | X40: =IF(E40>=F40,"Вірно","Помилка") -> Вірно | Y40: =IF(F40>=G40,"Вірно","Помилка") -> Вірно | Z40: =IF(F40>=H40,"Вірно","Помилка") -> Вірно | AA40: =IF(F40>=J40,"Вірно","Помилка") -> Вірно | AB40: =IF(J40>=I40,"Вірно","Помилка") -> Вірно | AC40: =IF(F40>=K40,"Вірно","Помилка") -> Вірно | AD40: =IF(F40>=L40,"Вірно","Помилка") -> Вірно | AE40: =IF(M40>=N40,"Вірно","Помилка") -> Вірно | AF40: =IF(M40>=O40,"Вірно","Помилка") -> Вірно | AG40: =IF(P40>=Q40,"Вірно","Помилка") -> Вірно | AH40: =IF(P40>=R40,"Вірно","Помилка") -> Вірно | AI40: =IF(P40>=T40,"Вірно","Помилка") -> Вірно | AJ40: =IF(T40>=S40,"Вірно","Помилка") -> Вірно | AK40: =IF(P40>=U40,"Вірно","Помилка") -> Вірно | AL40: =IF(P40>=V40,"Вірно","Помилка") -> Вірно | AM40: =IF((I40+K40+L40)<=F40,"Вірно","Помилка") -> Вірно | AN40: =IF((J40+L40)<=F40,"Вірно","Помилка") -> Вірно | AO40: =IF((N40+O40)<=M40,"Вірно","Помилка") -> Вірно | AP40: =IF((S40+U40+V40)<=P40,"Вірно","Помилка") -> Вірно | AQ40: =IF((T40+V40)<=P40,"Вірно","Помилка") -> Вірно
A41: f_13.[0:1]_brb | B41: барбітурати | C41: 3.1.4.2 | D41: F13.0,1 (частина) | E41: 5 | F41: 5 | G41: 4 | H41: 5 | K41: 4 | L41: 1 | M41: 5 | N41: 5 | P41: 5 | Q41: 4 | R41: 5 | U41: 4 | V41: 1 | X41: =IF(E41>=F41,"Вірно","Помилка") -> Вірно | Y41: =IF(F41>=G41,"Вірно","Помилка") -> Вірно | Z41: =IF(F41>=H41,"Вірно","Помилка") -> Вірно | AA41: =IF(F41>=J41,"Вірно","Помилка") -> Вірно | AB41: =IF(J41>=I41,"Вірно","Помилка") -> Вірно | AC41: =IF(F41>=K41,"Вірно","Помилка") -> Вірно | AD41: =IF(F41>=L41,"Вірно","Помилка") -> Вірно | AE41: =IF(M41>=N41,"Вірно","Помилка") -> Вірно | AF41: =IF(M41>=O41,"Вірно","Помилка") -> Вірно | AG41: =IF(P41>=Q41,"Вірно","Помилка") -> Вірно | AH41: =IF(P41>=R41,"Вірно","Помилка") -> Вірно | AI41: =IF(P41>=T41,"Вірно","Помилка") -> Вірно | AJ41: =IF(T41>=S41,"Вірно","Помилка") -> Вірно | AK41: =IF(P41>=U41,"Вірно","Помилка") -> Вірно | AL41: =IF(P41>=V41,"Вірно","Помилка") -> Вірно | AM41: =IF((I41+K41+L41)<=F41,"Вірно","Помилка") -> Вірно | AN41: =IF((J41+L41)<=F41,"Вірно","Помилка") -> Вірно | AO41: =IF((N41+O41)<=M41,"Вірно","Помилка") -> Вірно | AP41: =IF((S41+U41+V41)<=P41,"Вірно","Помилка") -> Вірно | AQ41: =IF((T41+V41)<=P41,"Вірно","Помилка") -> Вірно
...

Sheet 1100
A1: cd | B1: dsrdr | C1: clmn | D1: icd10 | E1: op | F1: op_inc | G1: op_inc_m | H1: op_inc_r | I1: op_inc_u18 | J1: op_inc_y | K1: op_inc_e | L1: op_hiv | M1: op_hbv | N1: op_hbc | O1: op_tbc | P1: op_od | Q1: op_stp | R1: op_stp_c | S1: op_stp_d_od | T1: op_stp_d_othr | U1: op_prv | V1: op_prv_m | W1: op_prv_r | X1: op_prv_u18 | Y1: op_prv_y | Z1: op_prv_e
B2: Таблиця 1100 | C2: Амбулаторна психіатрична допомога особам з розладами психіки та поведінки внаслідок ін’єкційного вживання ПАР
B3: Найменування розладів | C3: Номер | D3: Код за МКХ-10 | E3: Кількість осіб, яким було розпочато надання амбулаторної психіатричної допомоги | Q3: Кількість осіб, які припинили отримувати | U3: Кількість осіб, яким надавалась амбулаторна психіатрична допомога на кінець року
C4: рядка | E4: усього | F4: з них з уперше встановленим розладом психіки та поведінки | L4: у тому числі (з графи 1) | Q4: амбулаторну психіатричну допомогу | U4: усього | V4: у тому числі
F5: усього | G5: у тому числі | L5: пацієнти | M5: пацієнти | N5: пацієнти | O5: пацієнти | P5: з випадками | Q5: усього | R5: з них у зв’язку | V5: чоловіки | W5: сільське | X5: за віковими групами
G6: чоловіки | H6: сільське | I6: за віковими групами | L6: з ВІЛ | M6: з гепатитом B | N6: з гепатитом C | O6: з туберкульозом | P6: передозування ПАР без | R6: з одужанням, | S6: зі смертю | T6: зі смертю | W6: населення | X6: діти | Y6: молодь | Z6: особи
H7: населення | I7: діти | J7: молодь | K7: особи похилого віку | P7: летального наслідку у звітному році | R7: стійкою ремісією | S7: від передозу-вання ПАР | T7: від інших причин | Z7: похилого віку
B9: А | C9: Б | D9: В | E9: 1 | F9: 2 | G9: 3 | H9: 4 | I9: 5 | J9: 6 | K9: 7 | L9: 8 | M9: 9 | N9: 10 | O9: 11 | P9: 12 | Q9: 13 | R9: 14 | S9: 15 | T9: 16 | U9: 17 | V9: 18 | W9: 19 | X9: 20 | Y9: 21 | Z9: 22
A10: f_1[0:9] | B10: Усього, внаслідок уживання ПАР | C10: 1.0 | D10: F10-F19 | E10: 2 | F10: 2 | G10: 2 | H10: 2 | J10: 2 | Q10: 2 | T10: 1 | U10: 6 | V10: 6 | W10: 5 | Y10: 2 | Z10: 1 | AB10: =IF(E10>=F10,"Вірно","Помилка") -> Вірно | AC10: =IF(F10>=G10,"Вірно","Помилка") -> Вірно | AD10: =IF(F10>=H10,"Вірно","Помилка") -> Вірно | AE10: =IF(F10>=I10,"Вірно","Помилка") -> Вірно | AF10: =IF(F10>=J10,"Вірно","Помилка") -> Вірно | AG10: =IF(F10>=K10,"Вірно","Помилка") -> Вірно | AH10: =IF(E10>=L10,"Вірно","Помилка") -> Вірно | AI10: =IF(E10>=M10,"Вірно","Помилка") -> Вірно | AJ10: =IF(E10>=N10,"Вірно","Помилка") -> Вірно | AK10: =IF(E10>=O10,"Вірно","Помилка") -> Вірно | AL10: =IF(E10>=P10,"Вірно","Помилка") -> Вірно | AM10: =IF(U10>=V10,"Вірно","Помилка") -> Вірно | AN10: =IF(U10>=W10,"Вірно","Помилка") -> Вірно | AO10: =IF(U10>=X10,"Вірно","Помилка") -> Вірно | AP10: =IF(U10>=Y10,"Вірно","Помилка") -> Вірно | AQ10: =IF(U10>=Z10,"Вірно","Помилка") -> Вірно | AR10: =IF(F10>=I10+K10,"Вірно","Помилка") -> Вірно | AS10: =IF(F10>=J10+K10,"Вірно","Помилка") -> Вірно | AT10: =IF(Q10>=R10+S10+T10,"Вірно","Помилка") -> Вірно | AU10: =IF(U10>=X10+Z10,"Вірно","Помилка") -> Вірно | AV10: =IF(U10>=Y10+Z10,"Вірно","Помилка") -> Вірно
B11: з них:
A12: f_1[0:9].[0:1] | B12: гостра інтоксикація та вживання зі шкідливими наслідками | C12: 2.0 | D12: F1x.0,1 | AB12: =IF(E12>=F12,"Вірно","Помилка") -> Вірно | AC12: =IF(F12>=G12,"Вірно","Помилка") -> Вірно | AD12: =IF(F12>=H12,"Вірно","Помилка") -> Вірно | AE12: =IF(F12>=I12,"Вірно","Помилка") -> Вірно | AF12: =IF(F12>=J12,"Вірно","Помилка") -> Вірно | AG12: =IF(F12>=K12,"Вірно","Помилка") -> Вірно | AH12: =IF(E12>=L12,"Вірно","Помилка") -> Вірно | AI12: =IF(E12>=M12,"Вірно","Помилка") -> Вірно | AJ12: =IF(E12>=N12,"Вірно","Помилка") -> Вірно | AK12: =IF(E12>=O12,"Вірно","Помилка") -> Вірно | AL12: =IF(E12>=P12,"Вірно","Помилка") -> Вірно | AM12: =IF(U12>=V12,"Вірно","Помилка") -> Вірно | AN12: =IF(U12>=W12,"Вірно","Помилка") -> Вірно | AO12: =IF(U12>=X12,"Вірно","Помилка") -> Вірно | AP12: =IF(U12>=Y12,"Вірно","Помилка") -> Вірно | AQ12: =IF(U12>=Z12,"Вірно","Помилка") -> Вірно | AR12: =IF(F12>=I12+K12,"Вірно","Помилка") -> Вірно | AS12: =IF(F12>=J12+K12,"Вірно","Помилка") -> Вірно | AT12: =IF(Q12>=R12+S12+T12,"Вірно","Помилка") -> Вірно | AU12: =IF(U12>=X12+Z12,"Вірно","Помилка") -> Вірно | AV12: =IF(U12>=Y12+Z12,"Вірно","Помилка") -> Вірно
B13: у тому числі внаслідок уживання:
A14: f_10.[0:1] | B14: алкоголю | C14: 2.1 | D14: F10.0,1 | AB14: =IF(E14>=F14,"Вірно","Помилка") -> Вірно | AC14: =IF(F14>=G14,"Вірно","Помилка") -> Вірно | AD14: =IF(F14>=H14,"Вірно","Помилка") -> Вірно | AE14: =IF(F14>=I14,"Вірно","Помилка") -> Вірно | AF14: =IF(F14>=J14,"Вірно","Помилка") -> Вірно | AG14: =IF(F14>=K14,"Вірно","Помилка") -> Вірно | AH14: =IF(E14>=L14,"Вірно","Помилка") -> Вірно | AI14: =IF(E14>=M14,"Вірно","Помилка") -> Вірно | AJ14: =IF(E14>=N14,"Вірно","Помилка") -> Вірно | AK14: =IF(E14>=O14,"Вірно","Помилка") -> Вірно | AL14: =IF(E14>=P14,"Вірно","Помилка") -> Вірно | AM14: =IF(U14>=V14,"Вірно","Помилка") -> Вірно | AN14: =IF(U14>=W14,"Вірно","Помилка") -> Вірно | AO14: =IF(U14>=X14,"Вірно","Помилка") -> Вірно | AP14: =IF(U14>=Y14,"Вірно","Помилка") -> Вірно | AQ14: =IF(U14>=Z14,"Вірно","Помилка") -> Вірно | AR14: =IF(F14>=I14+K14,"Вірно","Помилка") -> Вірно | AS14: =IF(F14>=J14+K14,"Вірно","Помилка") -> Вірно | AT14: =IF(Q14>=R14+S14+T14,"Вірно","Помилка") -> Вірно | AU14: =IF(U14>=X14+Z14,"Вірно","Помилка") -> Вірно | AV14: =IF(U14>=Y14+Z14,"Вірно","Помилка") -> Вірно
A15: f_11.[0:1] | B15: опіоїдів | C15: 2.2 | D15: F11.0,1 | AB15: =IF(E15>=F15,"Вірно","Помилка") -> Вірно | AC15: =IF(F15>=G15,"Вірно","Помилка") -> Вірно | AD15: =IF(F15>=H15,"Вірно","Помилка") -> Вірно | AE15: =IF(F15>=I15,"Вірно","Помилка") -> Вірно | AF15: =IF(F15>=J15,"Вірно","Помилка") -> Вірно | AG15: =IF(F15>=K15,"Вірно","Помилка") -> Вірно | AH15: =IF(E15>=L15,"Вірно","Помилка") -> Вірно | AI15: =IF(E15>=M15,"Вірно","Помилка") -> Вірно | AJ15: =IF(E15>=N15,"Вірно","Помилка") -> Вірно | AK15: =IF(E15>=O15,"Вірно","Помилка") -> Вірно | AL15: =IF(E15>=P15,"Вірно","Помилка") -> Вірно | AM15: =IF(U15>=V15,"Вірно","Помилка") -> Вірно | AN15: =IF(U15>=W15,"Вірно","Помилка") -> Вірно | AO15: =IF(U15>=X15,"Вірно","Помилка") -> Вірно | AP15: =IF(U15>=Y15,"Вірно","Помилка") -> Вірно | AQ15: =IF(U15>=Z15,"Вірно","Помилка") -> Вірно | AR15: =IF(F15>=I15+K15,"Вірно","Помилка") -> Вірно | AS15: =IF(F15>=J15+K15,"Вірно","Помилка") -> Вірно | AT15: =IF(Q15>=R15+S15+T15,"Вірно","Помилка") -> Вірно | AU15: =IF(U15>=X15+Z15,"Вірно","Помилка") -> Вірно | AV15: =IF(U15>=Y15+Z15,"Вірно","Помилка") -> Вірно
A16: f_11.[0:1]_opm | B16: з них: опій | C16: 2.2.1 | D16: F11.0,1 (частина) | AB16: =IF(E16>=F16,"Вірно","Помилка") -> Вірно | AC16: =IF(F16>=G16,"Вірно","Помилка") -> Вірно | AD16: =IF(F16>=H16,"Вірно","Помилка") -> Вірно | AE16: =IF(F16>=I16,"Вірно","Помилка") -> Вірно | AF16: =IF(F16>=J16,"Вірно","Помилка") -> Вірно | AG16: =IF(F16>=K16,"Вірно","Помилка") -> Вірно | AH16: =IF(E16>=L16,"Вірно","Помилка") -> Вірно | AI16: =IF(E16>=M16,"Вірно","Помилка") -> Вірно | AJ16: =IF(E16>=N16,"Вірно","Помилка") -> Вірно | AK16: =IF(E16>=O16,"Вірно","Помилка") -> Вірно | AL16: =IF(E16>=P16,"Вірно","Помилка") -> Вірно | AM16: =IF(U16>=V16,"Вірно","Помилка") -> Вірно | AN16: =IF(U16>=W16,"Вірно","Помилка") -> Вірно | AO16: =IF(U16>=X16,"Вірно","Помилка") -> Вірно | AP16: =IF(U16>=Y16,"Вірно","Помилка") -> Вірно | AQ16: =IF(U16>=Z16,"Вірно","Помилка") -> Вірно | AR16: =IF(F16>=I16+K16,"Вірно","Помилка") -> Вірно | AS16: =IF(F16>=J16+K16,"Вірно","Помилка") -> Вірно | AT16: =IF(Q16>=R16+S16+T16,"Вірно","Помилка") -> Вірно | AU16: =IF(U16>=X16+Z16,"Вірно","Помилка") -> Вірно | AV16: =IF(U16>=Y16+Z16,"Вірно","Помилка") -> Вірно
A17: f_11.[0:1]_opm_a | B17: опій ацетильований | C17: 2.2.2 | D17: F11.0,1 (частина) | AB17: =IF(E17>=F17,"Вірно","Помилка") -> Вірно | AC17: =IF(F17>=G17,"Вірно","Помилка") -> Вірно | AD17: =IF(F17>=H17,"Вірно","Помилка") -> Вірно | AE17: =IF(F17>=I17,"Вірно","Помилка") -> Вірно | AF17: =IF(F17>=J17,"Вірно","Помилка") -> Вірно | AG17: =IF(F17>=K17,"Вірно","Помилка") -> Вірно | AH17: =IF(E17>=L17,"Вірно","Помилка") -> Вірно | AI17: =IF(E17>=M17,"Вірно","Помилка") -> Вірно | AJ17: =IF(E17>=N17,"Вірно","Помилка") -> Вірно | AK17: =IF(E17>=O17,"Вірно","Помилка") -> Вірно | AL17: =IF(E17>=P17,"Вірно","Помилка") -> Вірно | AM17: =IF(U17>=V17,"Вірно","Помилка") -> Вірно | AN17: =IF(U17>=W17,"Вірно","Помилка") -> Вірно | AO17: =IF(U17>=X17,"Вірно","Помилка") -> Вірно | AP17: =IF(U17>=Y17,"Вірно","Помилка") -> Вірно | AQ17: =IF(U17>=Z17,"Вірно","Помилка") -> Вірно | AR17: =IF(F17>=I17+K17,"Вірно","Помилка") -> Вірно | AS17: =IF(F17>=J17+K17,"Вірно","Помилка") -> Вірно | AT17: =IF(Q17>=R17+S17+T17,"Вірно","Помилка") -> Вірно | AU17: =IF(U17>=X17+Z17,"Вірно","Помилка") -> Вірно | AV17: =IF(U17>=Y17+Z17,"Вірно","Помилка") -> Вірно
A18: f_11.[0:1]_hrn | B18: героїн | C18: 2.2.3 | D18: F11.0,1 (частина) | AB18: =IF(E18>=F18,"Вірно","Помилка") -> Вірно | AC18: =IF(F18>=G18,"Вірно","Помилка") -> Вірно | AD18: =IF(F18>=H18,"Вірно","Помилка") -> Вірно | AE18: =IF(F18>=I18,"Вірно","Помилка") -> Вірно | AF18: =IF(F18>=J18,"Вірно","Помилка") -> Вірно | AG18: =IF(F18>=K18,"Вірно","Помилка") -> Вірно | AH18: =IF(E18>=L18,"Вірно","Помилка") -> Вірно | AI18: =IF(E18>=M18,"Вірно","Помилка") -> Вірно | AJ18: =IF(E18>=N18,"Вірно","Помилка") -> Вірно | AK18: =IF(E18>=O18,"Вірно","Помилка") -> Вірно | AL18: =IF(E18>=P18,"Вірно","Помилка") -> Вірно | AM18: =IF(U18>=V18,"Вірно","Помилка") -> Вірно | AN18: =IF(U18>=W18,"Вірно","Помилка") -> Вірно | AO18: =IF(U18>=X18,"Вірно","Помилка") -> Вірно | AP18: =IF(U18>=Y18,"Вірно","Помилка") -> Вірно | AQ18: =IF(U18>=Z18,"Вірно","Помилка") -> Вірно | AR18: =IF(F18>=I18+K18,"Вірно","Помилка") -> Вірно | AS18: =IF(F18>=J18+K18,"Вірно","Помилка") -> Вірно | AT18: =IF(Q18>=R18+S18+T18,"Вірно","Помилка") -> Вірно | AU18: =IF(U18>=X18+Z18,"Вірно","Помилка") -> Вірно | AV18: =IF(U18>=Y18+Z18,"Вірно","Помилка") -> Вірно
A19: f_11.[0:1]_mtd | B19: метадон | C19: 2.2.4 | D19: F11.0,1 (частина) | AB19: =IF(E19>=F19,"Вірно","Помилка") -> Вірно | AC19: =IF(F19>=G19,"Вірно","Помилка") -> Вірно | AD19: =IF(F19>=H19,"Вірно","Помилка") -> Вірно | AE19: =IF(F19>=I19,"Вірно","Помилка") -> Вірно | AF19: =IF(F19>=J19,"Вірно","Помилка") -> Вірно | AG19: =IF(F19>=K19,"Вірно","Помилка") -> Вірно | AH19: =IF(E19>=L19,"Вірно","Помилка") -> Вірно | AI19: =IF(E19>=M19,"Вірно","Помилка") -> Вірно | AJ19: =IF(E19>=N19,"Вірно","Помилка") -> Вірно | AK19: =IF(E19>=O19,"Вірно","Помилка") -> Вірно | AL19: =IF(E19>=P19,"Вірно","Помилка") -> Вірно | AM19: =IF(U19>=V19,"Вірно","Помилка") -> Вірно | AN19: =IF(U19>=W19,"Вірно","Помилка") -> Вірно | AO19: =IF(U19>=X19,"Вірно","Помилка") -> Вірно | AP19: =IF(U19>=Y19,"Вірно","Помилка") -> Вірно | AQ19: =IF(U19>=Z19,"Вірно","Помилка") -> Вірно | AR19: =IF(F19>=I19+K19,"Вірно","Помилка") -> Вірно | AS19: =IF(F19>=J19+K19,"Вірно","Помилка") -> Вірно | AT19: =IF(Q19>=R19+S19+T19,"Вірно","Помилка") -> Вірно | AU19: =IF(U19>=X19+Z19,"Вірно","Помилка") -> Вірно | AV19: =IF(U19>=Y19+Z19,"Вірно","Помилка") -> Вірно
A20: f_11.[0:1]_bpr | B20: бупренорфін | C20: 2.2.5 | D20: F11.0,1 (частина) | AB20: =IF(E20>=F20,"Вірно","Помилка") -> Вірно | AC20: =IF(F20>=G20,"Вірно","Помилка") -> Вірно | AD20: =IF(F20>=H20,"Вірно","Помилка") -> Вірно | AE20: =IF(F20>=I20,"Вірно","Помилка") -> Вірно | AF20: =IF(F20>=J20,"Вірно","Помилка") -> Вірно | AG20: =IF(F20>=K20,"Вірно","Помилка") -> Вірно | AH20: =IF(E20>=L20,"Вірно","Помилка") -> Вірно | AI20: =IF(E20>=M20,"Вірно","Помилка") -> Вірно | AJ20: =IF(E20>=N20,"Вірно","Помилка") -> Вірно | AK20: =IF(E20>=O20,"Вірно","Помилка") -> Вірно | AL20: =IF(E20>=P20,"Вірно","Помилка") -> Вірно | AM20: =IF(U20>=V20,"Вірно","Помилка") -> Вірно | AN20: =IF(U20>=W20,"Вірно","Помилка") -> Вірно | AO20: =IF(U20>=X20,"Вірно","Помилка") -> Вірно | AP20: =IF(U20>=Y20,"Вірно","Помилка") -> Вірно | AQ20: =IF(U20>=Z20,"Вірно","Помилка") -> Вірно | AR20: =IF(F20>=I20+K20,"Вірно","Помилка") -> Вірно | AS20: =IF(F20>=J20+K20,"Вірно","Помилка") -> Вірно | AT20: =IF(Q20>=R20+S20+T20,"Вірно","Помилка") -> Вірно | AU20: =IF(U20>=X20+Z20,"Вірно","Помилка") -> Вірно | AV20: =IF(U20>=Y20+Z20,"Вірно","Помилка") -> Вірно
A21: f_11.[0:1]_mrf | B21: морфін | C21: 2.2.6 | D21: F11.0,1 (частина) | AB21: =IF(E21>=F21,"Вірно","Помилка") -> Вірно | AC21: =IF(F21>=G21,"Вірно","Помилка") -> Вірно | AD21: =IF(F21>=H21,"Вірно","Помилка") -> Вірно | AE21: =IF(F21>=I21,"Вірно","Помилка") -> Вірно | AF21: =IF(F21>=J21,"Вірно","Помилка") -> Вірно | AG21: =IF(F21>=K21,"Вірно","Помилка") -> Вірно | AH21: =IF(E21>=L21,"Вірно","Помилка") -> Вірно | AI21: =IF(E21>=M21,"Вірно","Помилка") -> Вірно | AJ21: =IF(E21>=N21,"Вірно","Помилка") -> Вірно | AK21: =IF(E21>=O21,"Вірно","Помилка") -> Вірно | AL21: =IF(E21>=P21,"Вірно","Помилка") -> Вірно | AM21: =IF(U21>=V21,"Вірно","Помилка") -> Вірно | AN21: =IF(U21>=W21,"Вірно","Помилка") -> Вірно | AO21: =IF(U21>=X21,"Вірно","Помилка") -> Вірно | AP21: =IF(U21>=Y21,"Вірно","Помилка") -> Вірно | AQ21: =IF(U21>=Z21,"Вірно","Помилка") -> Вірно | AR21: =IF(F21>=I21+K21,"Вірно","Помилка") -> Вірно | AS21: =IF(F21>=J21+K21,"Вірно","Помилка") -> Вірно | AT21: =IF(Q21>=R21+S21+T21,"Вірно","Помилка") -> Вірно | AU21: =IF(U21>=X21+Z21,"Вірно","Помилка") -> Вірно | AV21: =IF(U21>=Y21+Z21,"Вірно","Помилка") -> Вірно
A22: f_11.[0:1]_fnt | B22: фентаніл та його похідні | C22: 2.2.7 | D22: F11.0,1 (частина) | AB22: =IF(E22>=F22,"Вірно","Помилка") -> Вірно | AC22: =IF(F22>=G22,"Вірно","Помилка") -> Вірно | AD22: =IF(F22>=H22,"Вірно","Помилка") -> Вірно | AE22: =IF(F22>=I22,"Вірно","Помилка") -> Вірно | AF22: =IF(F22>=J22,"Вірно","Помилка") -> Вірно | AG22: =IF(F22>=K22,"Вірно","Помилка") -> Вірно | AH22: =IF(E22>=L22,"Вірно","Помилка") -> Вірно | AI22: =IF(E22>=M22,"Вірно","Помилка") -> Вірно | AJ22: =IF(E22>=N22,"Вірно","Помилка") -> Вірно | AK22: =IF(E22>=O22,"Вірно","Помилка") -> Вірно | AL22: =IF(E22>=P22,"Вірно","Помилка") -> Вірно | AM22: =IF(U22>=V22,"Вірно","Помилка") -> Вірно | AN22: =IF(U22>=W22,"Вірно","Помилка") -> Вірно | AO22: =IF(U22>=X22,"Вірно","Помилка") -> Вірно | AP22: =IF(U22>=Y22,"Вірно","Помилка") -> Вірно | AQ22: =IF(U22>=Z22,"Вірно","Помилка") -> Вірно | AR22: =IF(F22>=I22+K22,"Вірно","Помилка") -> Вірно | AS22: =IF(F22>=J22+K22,"Вірно","Помилка") -> Вірно | AT22: =IF(Q22>=R22+S22+T22,"Вірно","Помилка") -> Вірно | AU22: =IF(U22>=X22+Z22,"Вірно","Помилка") -> Вірно | AV22: =IF(U22>=Y22+Z22,"Вірно","Помилка") -> Вірно
A23: f_11.[0:1]_cdn | B23: кодеїн та кодеїновмісні препарати | C23: 2.2.8 | D23: F11.0,1 (частина) | AB23: =IF(E23>=F23,"Вірно","Помилка") -> Вірно | AC23: =IF(F23>=G23,"Вірно","Помилка") -> Вірно | AD23: =IF(F23>=H23,"Вірно","Помилка") -> Вірно | AE23: =IF(F23>=I23,"Вірно","Помилка") -> Вірно | AF23: =IF(F23>=J23,"Вірно","Помилка") -> Вірно | AG23: =IF(F23>=K23,"Вірно","Помилка") -> Вірно | AH23: =IF(E23>=L23,"Вірно","Помилка") -> Вірно | AI23: =IF(E23>=M23,"Вірно","Помилка") -> Вірно | AJ23: =IF(E23>=N23,"Вірно","Помилка") -> Вірно | AK23: =IF(E23>=O23,"Вірно","Помилка") -> Вірно | AL23: =IF(E23>=P23,"Вірно","Помилка") -> Вірно | AM23: =IF(U23>=V23,"Вірно","Помилка") -> Вірно | AN23: =IF(U23>=W23,"Вірно","Помилка") -> Вірно | AO23: =IF(U23>=X23,"Вірно","Помилка") -> Вірно | AP23: =IF(U23>=Y23,"Вірно","Помилка") -> Вірно | AQ23: =IF(U23>=Z23,"Вірно","Помилка") -> Вірно | AR23: =IF(F23>=I23+K23,"Вірно","Помилка") -> Вірно | AS23: =IF(F23>=J23+K23,"Вірно","Помилка") -> Вірно | AT23: =IF(Q23>=R23+S23+T23,"Вірно","Помилка") -> Вірно | AU23: =IF(U23>=X23+Z23,"Вірно","Помилка") -> Вірно | AV23: =IF(U23>=Y23+Z23,"Вірно","Помилка") -> Вірно
A24: f_11.[0:1]_trm | B24: трамадол | C24: 2.2.9 | D24: F11.0,1 (частина) | AB24: =IF(E24>=F24,"Вірно","Помилка") -> Вірно | AC24: =IF(F24>=G24,"Вірно","Помилка") -> Вірно | AD24: =IF(F24>=H24,"Вірно","Помилка") -> Вірно | AE24: =IF(F24>=I24,"Вірно","Помилка") -> Вірно | AF24: =IF(F24>=J24,"Вірно","Помилка") -> Вірно | AG24: =IF(F24>=K24,"Вірно","Помилка") -> Вірно | AH24: =IF(E24>=L24,"Вірно","Помилка") -> Вірно | AI24: =IF(E24>=M24,"Вірно","Помилка") -> Вірно | AJ24: =IF(E24>=N24,"Вірно","Помилка") -> Вірно | AK24: =IF(E24>=O24,"Вірно","Помилка") -> Вірно | AL24: =IF(E24>=P24,"Вірно","Помилка") -> Вірно | AM24: =IF(U24>=V24,"Вірно","Помилка") -> Вірно | AN24: =IF(U24>=W24,"Вірно","Помилка") -> Вірно | AO24: =IF(U24>=X24,"Вірно","Помилка") -> Вірно | AP24: =IF(U24>=Y24,"Вірно","Помилка") -> Вірно | AQ24: =IF(U24>=Z24,"Вірно","Помилка") -> Вірно | AR24: =IF(F24>=I24+K24,"Вірно","Помилка") -> Вірно | AS24: =IF(F24>=J24+K24,"Вірно","Помилка") -> Вірно | AT24: =IF(Q24>=R24+S24+T24,"Вірно","Помилка") -> Вірно | AU24: =IF(U24>=X24+Z24,"Вірно","Помилка") -> Вірно | AV24: =IF(U24>=Y24+Z24,"Вірно","Помилка") -> Вірно
A25: f_11.[0:1]_nlb | B25: налбуфін | C25: 2.2.10 | D25: F11.0,1 (частина) | AB25: =IF(E25>=F25,"Вірно","Помилка") -> Вірно | AC25: =IF(F25>=G25,"Вірно","Помилка") -> Вірно | AD25: =IF(F25>=H25,"Вірно","Помилка") -> Вірно | AE25: =IF(F25>=I25,"Вірно","Помилка") -> Вірно | AF25: =IF(F25>=J25,"Вірно","Помилка") -> Вірно | AG25: =IF(F25>=K25,"Вірно","Помилка") -> Вірно | AH25: =IF(E25>=L25,"Вірно","Помилка") -> Вірно | AI25: =IF(E25>=M25,"Вірно","Помилка") -> Вірно | AJ25: =IF(E25>=N25,"Вірно","Помилка") -> Вірно | AK25: =IF(E25>=O25,"Вірно","Помилка") -> Вірно | AL25: =IF(E25>=P25,"Вірно","Помилка") -> Вірно | AM25: =IF(U25>=V25,"Вірно","Помилка") -> Вірно | AN25: =IF(U25>=W25,"Вірно","Помилка") -> Вірно | AO25: =IF(U25>=X25,"Вірно","Помилка") -> Вірно | AP25: =IF(U25>=Y25,"Вірно","Помилка") -> Вірно | AQ25: =IF(U25>=Z25,"Вірно","Помилка") -> Вірно | AR25: =IF(F25>=I25+K25,"Вірно","Помилка") -> Вірно | AS25: =IF(F25>=J25+K25,"Вірно","Помилка") -> Вірно | AT25: =IF(Q25>=R25+S25+T25,"Вірно","Помилка") -> Вірно | AU25: =IF(U25>=X25+Z25,"Вірно","Помилка") -> Вірно | AV25: =IF(U25>=Y25+Z25,"Вірно","Помилка") -> Вірно
... A42: f_19.[0:1] | B42: поєднаних ПАР | C42: 2.9 | D42: F19.0,1 | AB42: =IF(E42>=F42,"Вірно","Помилка") -> Вірно | AC42: =IF(F42>=G42,"Вірно","Помилка") -> Вірно | AD42: =IF(F42>=H42,"Вірно","Помилка") -> Вірно | AE42: =IF(F42>=I42,"Вірно","Помилка") -> Вірно | AF42: =IF(F42>=J42,"Вірно","Помилка") -> Вірно | AG42: =IF(F42>=K42,"Вірно","Помилка") -> Вірно | AH42: =IF(E42>=L42,"Вірно","Помилка") -> Вірно | AI42: =IF(E42>=M42,"Вірно","Помилка") -> Вірно | AJ42: =IF(E42>=N42,"Вірно","Помилка") -> Вірно | AK42: =IF(E42>=O42,"Вірно","Помилка") -> Вірно | AL42: =IF(E42>=P42,"Вірно","Помилка") -> Вірно | AM42: =IF(U42>=V42,"Вірно","Помилка") -> Вірно | AN42: =IF(U42>=W42,"Вірно","Помилка") -> Вірно | AO42: =IF(U42>=X42,"Вірно","Помилка") -> Вірно | AP42: =IF(U42>=Y42,"Вірно","Помилка") -> Вірно | AQ42: =IF(U42>=Z42,"Вірно","Помилка") -> Вірно | AR42: =IF(F42>=I42+K42,"Вірно","Помилка") -> Вірно | AS42: =IF(F42>=J42+K42,"Вірно","Помилка") -> Вірно | AT42: =IF(Q42>=R42+S42+T42,"Вірно","Помилка") -> Вірно | AU42: =IF(U42>=X42+Z42,"Вірно","Помилка") -> Вірно | AV42: =IF(U42>=Y42+Z42,"Вірно","Помилка") -> Вірно
A43: f_1[0:9].[2:3] | B43: синдром залежності та стан відміни (абстинентний) | C43: 3.0 | D43: F1x.2,3 | E43: 2 | F43: 2 | G43: 2 | H43: 2 | J43: 2 | Q43: 2 | T43: 1 | U43: 6 | V43: 6 | W43: 5 | Y43: 2 | Z43: 1 | AB43: =IF(E43>=F43,"Вірно","Помилка") -> Вірно | AC43: =IF(F43>=G43,"Вірно","Помилка") -> Вірно | AD43: =IF(F43>=H43,"Вірно","Помилка") -> Вірно | AE43: =IF(F43>=I43,"Вірно","Помилка") -> Вірно | AF43: =IF(F43>=J43,"Вірно","Помилка") -> Вірно | AG43: =IF(F43>=K43,"Вірно","Помилка") -> Вірно | AH43: =IF(E43>=L43,"Вірно","Помилка") -> Вірно | AI43: =IF(E43>=M43,"Вірно","Помилка") -> Вірно | AJ43: =IF(E43>=N43,"Вірно","Помилка") -> Вірно | AK43: =IF(E43>=O43,"Вірно","Помилка") -> Вірно | AL43: =IF(E43>=P43,"Вірно","Помилка") -> Вірно | AM43: =IF(U43>=V43,"Вірно","Помилка") -> Вірно | AN43: =IF(U43>=W43,"Вірно","Помилка") -> Вірно | AO43: =IF(U43>=X43,"Вірно","Помилка") -> Вірно | AP43: =IF(U43>=Y43,"Вірно","Помилка") -> Вірно | AQ43: =IF(U43>=Z43,"Вірно","Помилка") -> Вірно | AR43: =IF(F43>=I43+K43,"Вірно","Помилка") -> Вірно | AS43: =IF(F43>=J43+K43,"Вірно","Помилка") -> Вірно | AT43: =IF(Q43>=R43+S43+T43,"Вірно","Помилка") -> Вірно | AU43: =IF(U43>=X43+Z43,"Вірно","Помилка") -> Вірно | AV43: =IF(U43>=Y43+Z43,"Вірно","Помилка") -> Вірно
B44: у тому числі внаслідок уживання:
A45: f_10.[2:3] | B45: алкоголю | C45: 3.1 | D45: F10.2,3 | AB45: =IF(E45>=F45,"Вірно","Помилка") -> Вірно | AC45: =IF(F45>=G45,"Вірно","Помилка") -> Вірно | AD45: =IF(F45>=H45,"Вірно","Помилка") -> Вірно | AE45: =IF(F45>=I45,"Вірно","Помилка") -> Вірно | AF45: =IF(F45>=J45,"Вірно","Помилка") -> Вірно | AG45: =IF(F45>=K45,"Вірно","Помилка") -> Вірно | AH45: =IF(E45>=L45,"Вірно","Помилка") -> Вірно | AI45: =IF(E45>=M45,"Вірно","Помилка") -> Вірно | AJ45: =IF(E45>=N45,"Вірно","Помилка") -> Вірно | AK45: =IF(E45>=O45,"Вірно","Помилка") -> Вірно | AL45: =IF(E45>=P45,"Вірно","Помилка") -> Вірно | AM45: =IF(U45>=V45,"Вірно","Помилка") -> Вірно | AN45: =IF(U45>=W45,"Вірно","Помилка") -> Вірно | AO45: =IF(U45>=X45,"Вірно","Помилка") -> Вірно | AP45: =IF(U45>=Y45,"Вірно","Помилка") -> Вірно | AQ45: =IF(U45>=Z45,"Вірно","Помилка") -> Вірно | AR45: =IF(F45>=I45+K45,"Вірно","Помилка") -> Вірно | AS45: =IF(F45>=J45+K45,"Вірно","Помилка") -> Вірно | AT45: =IF(Q45>=R45+S45+T45,"Вірно","Помилка") -> Вірно | AU45: =IF(U45>=X45+Z45,"Вірно","Помилка") -> Вірно | AV45: =IF(U45>=Y45+Z45,"Вірно","Помилка") -> Вірно
