Workbook

Sheet Output
C2: Aid Pioneers 'menu' of medical supplies available to send to Ukraine
C3: Note: A single forty-foot shipping container can hold ~700 boxes, collectively worth approx. $400K; each container costs us approx. $20K to send
H4: Please complete!
C5: HS Code | D5: Product code | E5: Description | F5: Quantity / box | G5: Average no. of boxes / shipment | H5: Quantity needed | I5: Priority (1 - highest, 3 - is lowest) | J5: Recipient hospital (if delivering to multiple hospitals)
C6: 101 | D6: 3926100000 | E6: Office Supplies, ALL | F6: Unknown | G6: 2
C7: 301 | D7: 6302210000 | E7: Bed Linens And Towels | F7: Unknown | G7: 11.888889
C8: 302 | D8: 6307909800 | E8: Surgical Caps And Hats, Shoe Covers | F8: 1550 | G8: 15
C9: 303 | D9: 6307.90.9995 | E9: Cloth Products Not Fitting In Other Items, Cubical Curtains | F9: Unknown | G9: 5
C10: 305.99 | D10: 3926201010 | E10: Gloves, Non-sterile | F10: 325 | G10: 43.333333
C11: 306 | D11: 3926201010 | E11: Gloves, Non-sterile | F11: Unknown | G11: 31.666667
C12: 306.99 | D12: 3926201010 | E12: Gloves, Sterile | F12: Unknown | G12: 10
C13: 307 | D13: 3926201010 | E13: Gloves, Sterile | F13: Unknown | G13: 6.6666667
C14: 307 | D14: 9004909000 | E14: Goggles and Face Protection | F14: Unknown | G14: 10
C15: 307 | D15: 9004909000 | E15: Masks, surgical | F15: Unknown | G15: 5
C16: 307.199 | D16: 9004909000 | E16: Masks, surgical | F16: Unknown | G16: 18
C17: 307.299 | D17: 9004909000 | E17: Goggles and Face Protection | F17: Unknown | G17: 22
C18: 307.3 | D18: 9004909000 | E18: Masks, Cloth | F18: Unknown | G18: 15
C19: 307.99 | D19: 9004909000 | E19: Goggles, Masks, and Face Protection | F19: 97.5 | G19: 16.25
C20: 308 | D20: 4823909000 | E20: Gowns, Isolation Level 1 and Level 2 | F20: Unknown | G20: 10
C21: 308 | D21: 4823909000 | E21: Gowns, Isolation or Biohazard, Level 3 and Level 4 | F21: Unknown | G21: 5
C22: 308 | D22: 4823909000 | E22: Gowns, Patient (incl. Cloth, Paper Protector, Cover- up) | F22: Unknown | G22: 26.666667
C23: 308 | D23: 9004909000 | E23: Goggles, Masks, and Face Protection | F23: Unknown | G23: 30
C24: 308.199 | D24: 4823909000 | E24: Gowns, Isolation Level 1 and Level 2 | F24: 97.5 | G24: 14
C25: 308.299 | D25: 4823909000 | E25: Gowns, Isolation or Biohazard, Level 3 and Level 4 | F25: 97.5 | G25: 20
C26: 308.99 | D26: 4823909000 | E26: Gowns, Patient (incl. Cloth, Paper Protector, Cover- up) | F26: 52.5 | G26: 16.25
C27: 309 | D27: 4823909000 | E27: Gowns, Patient (incl. Cloth, Paper Protector, Cover- up) | F27: 52.5 | G27: 10
C28: 309 | D28: 4823909000 | E28: Gowns, Surgical, Non-sterile | F28: 52.5 | G28: 21.25
C29: 310.99 | D29: 6211320000 | E29: Gowns, Surgical, Sterile | F29: Unknown | G29: 31.875
C30: 311 | D30: 6211320000 | E30: Gowns, Surgical, Sterile | F30: Unknown | G30: 30
C31: 311 | D31: 6211320000 | E31: Lab Coats And Tunics, Scrub Suits, Surgical | F31: Unknown | G31: 16.428571
C32: 311.1 | D32: 6211320000 | E32: Scrubs, FIG | F32: Unknown | G32: 10
C33: 312 | D33: 9004909000 | E33: BYD Masks | F33: Unknown | G33: 15
C34: 312.99 | D34: 9004909000 | E34: N-95 Masks | F34: 1050 | G34: 25
C35: 313 | D35: 9004909000 | E35: N-95 Masks | F35: Unknown | G35: 20
C36: 313.99 | D36: 6307.90.9889 | E36: KN95 - Masks | F36: Unknown | G36: 26.666667
C37: 314 | D37: 6307.90.9889 | E37: KN95 - Masks | F37: Unknown | G37: 5
C38: 401.99 | D38: 4421900000 | E38: Dental Supplies | F38: Unknown | G38: 10
C39: 501.99 | D39: 3006100100 | E39: 2x2, 4x4, Abd Sterile Dressings | F39: Unknown | G39: 9
C40: 502 | D40: 3006100100 | E40: 2x2, 4x4, Abd Sterile Dressings | F40: Unknown | G40: 5
C41: 504.99 | D41: 3005909900 | E41: Bandaids, Steristrips, Tape, Transparent Dressings (tegaderm) | F41: 214.5 | G41: 15
...

Sheet Analysis>>>

Sheet Pivot
A3: Product Code | B3: HS Code | C3: Description | D3: Quantity / box | E3: Average of Number Ordered
A4: 101 | B4: 3926100000 | C4: Office Supplies, ALL | D4: NA | E4: 2
A5: 301 | B5: 6302210000 | C5: Bed Linens And Towels | D5: NA | E5: 11.888889
A6: 302 | B6: 6307909800 | C6: Surgical Caps And Hats, Shoe Covers | D6: 1550 | E6: 15
A7: 303 | B7: 6307.90.9995 | C7: Cloth Products Not Fitting In Other Items, Cubical Curtains | D7: NA | E7: 5
A8: 305.99 | B8: 3926201010 | C8: Gloves, Non-sterile | D8: 325 | E8: 43.333333
A9: 306 | B9: 3926201010 | C9: Gloves, Non-sterile | D9: NA | E9: 31.666667
A10: 306.99 | B10: 3926201010 | C10: Gloves, Sterile | D10: NA | E10: 10
A11: 307 | B11: 3926201010 | C11: Gloves, Sterile | D11: NA | E11: 6.6666667
B12: 9004909000 | C12: Goggles and Face Protection | D12: NA | E12: 10
C13: Masks, surgical | D13: NA | E13: 5
A14: 307.199 | B14: 9004909000 | C14: Masks, surgical | D14: NA | E14: 18
A15: 307.299 | B15: 9004909000 | C15: Goggles and Face Protection | D15: NA | E15: 22
A16: 307.3 | B16: 9004909000 | C16: Masks, Cloth | D16: NA | E16: 15
A17: 307.99 | B17: 9004909000 | C17: Goggles, Masks, and Face Protection | D17: 97.5 | E17: 16.25
A18: 308 | B18: 4823909000 | C18: Gowns, Isolation Level 1 and Level 2 | D18: NA | E18: 10
C19: Gowns, Isolation or Biohazard, Level 3 and Level 4 | D19: NA | E19: 5
C20: Gowns, Patient (incl. Cloth, Paper Protector, Cover- up) | D20: NA | E20: 26.666667
B21: 9004909000 | C21: Goggles, Masks, and Face Protection | D21: NA | E21: 30
A22: 308.199 | B22: 4823909000 | C22: Gowns, Isolation Level 1 and Level 2 | D22: 97.5 | E22: 14
A23: 308.299 | B23: 4823909000 | C23: Gowns, Isolation or Biohazard, Level 3 and Level 4 | D23: 97.5 | E23: 20
A24: 308.99 | B24: 4823909000 | C24: Gowns, Patient (incl. Cloth, Paper Protector, Cover- up) | D24: 52.5 | E24: 16.25
A25: 309 | B25: 4823909000 | C25: Gowns, Patient (incl. Cloth, Paper Protector, Cover- up) | D25: 52.5 | E25: 10
C26: Gowns, Surgical, Non-sterile | D26: 52.5 | E26: 21.25
A27: 310.99 | B27: 6211320000 | C27: Gowns, Surgical, Sterile | D27: NA | E27: 31.875
A28: 311 | B28: 6211320000 | C28: Gowns, Surgical, Sterile | D28: NA | E28: 30
C29: Lab Coats And Tunics, Scrub Suits, Surgical | D29: NA | E29: 16.428571
A30: 311.1 | B30: 6211320000 | C30: Scrubs, FIG | D30: NA | E30: 10
A31: 312 | B31: 9004909000 | C31: BYD Masks | D31: NA | E31: 15
A32: 312.99 | B32: 9004909000 | C32: N-95 Masks | D32: 1050 | E32: 25
A33: 313 | B33: 9004909000 | C33: N-95 Masks | D33: NA | E33: 20
A34: 313.99 | B34: 6307.90.9889 | C34: KN95 - Masks | D34: NA | E34: 26.666667
A35: 314 | B35: 6307.90.9889 | C35: KN95 - Masks | D35: NA | E35: 5
A36: 401.99 | B36: 4421900000 | C36: Dental Supplies | D36: NA | E36: 10
A37: 501.99 | B37: 3006100100 | C37: 2x2, 4x4, Abd Sterile Dressings | D37: NA | E37: 9
A38: 502 | B38: 3006100100 | C38: 2x2, 4x4, Abd Sterile Dressings | D38: NA | E38: 5
A39: 504.99 | B39: 3005909900 | C39: Bandaids, Steristrips, Tape, Transparent Dressings (tegaderm) | D39: 214.5 | E39: 15
A40: 505 | B40: 3005909900 | C40: Bandaids, Steristrips, Tape, Transparent Dressings (tegaderm) | D40: NA | E40: 10
A41: 505.99 | B41: 3005590000 | C41: Dressing Change Kits, Laceration Trays, Wound Care Kits | D41: NA | E41: 3.5
A42: 506 | B42: 3005590000 | C42: Dressing Change Kits, Laceration Trays, Wound Care Kits | D42: NA | E42: 7.5
...

Sheet Aggregated Data
A1: Shipment | B1: Unique ID | C1: Product Code | D1: HS Code | E1: Description | F1: Average quantity per shipment | G1: Quantity / box | H1: Number Ordered | I1: Pieces/ Cartons | J1: Total Quantity | K1: Net Weight (kg) | L1: Unit Value ($) | M1: Total Value ($) | N1: Country destination
A2: 22203 | B2: =C2&D2&E2 -> 3016302210000Bed Linens And Towels | C2: 301 | D2: 6302210000 | E2: Bed Linens And Towels | G2: {=IFERROR(INDEX('Quantity in each box'!$H$8:$H$153,MATCH('Aggregated Data'!C2,'Quantity in each box'!$E$8:$E$153,0)),"NA")} -> NA | H2: 10 | K2: 22203 | M2: 22203 | N2: Ukraine
A3: 22203 | B3: =C3&D3&E3 -> 3026307909800Surgical Caps And Hats, Shoe Covers | C3: 302 | D3: 6307909800 | E3: Surgical Caps And Hats, Shoe Covers | G3: {=IFERROR(INDEX('Quantity in each box'!$H$8:$H$153,MATCH('Aggregated Data'!C3,'Quantity in each box'!$E$8:$E$153,0)),"NA")} -> 1550 | H3: 5 | K3: 22214 | M3: 72224 | N3: Ukraine
A4: 22203 | B4: =C4&D4&E4 -> 3063926201010Gloves, Non-sterile | C4: 306 | D4: 3926201010 | E4: Gloves, Non-sterile | G4: {=IFERROR(INDEX('Quantity in each box'!$H$8:$H$153,MATCH('Aggregated Data'!C4,'Quantity in each box'!$E$8:$E$153,0)),"NA")} -> NA | H4: 30 | K4: 52216 | M4: 52216 | N4: Ukraine
A5: 22203 | B5: =C5&D5&E5 -> 3073926201010Gloves, Sterile | C5: 307 | D5: 3926201010 | E5: Gloves, Sterile | G5: {=IFERROR(INDEX('Quantity in each box'!$H$8:$H$153,MATCH('Aggregated Data'!C5,'Quantity in each box'!$E$8:$E$153,0)),"NA")} -> NA | H5: 5 | K5: 42218 | M5: 42215 | N5: Ukraine
A6: 22203 | B6: =C6&D6&E6 -> 3084823909000Gowns, Isolation Level 1 and Level 2 | C6: 308 | D6: 4823909000 | E6: Gowns, Isolation Level 1 and Level 2 | G6: {=IFERROR(INDEX('Quantity in each box'!$H$8:$H$153,MATCH('Aggregated Data'!C6,'Quantity in each box'!$E$8:$E$153,0)),"NA")} -> NA | H6: 10 | K6: 42215 | M6: 42218 | N6: Ukraine
A7: 22203 | B7: =C7&D7&E7 -> 3094823909000Gowns, Patient (incl. Cloth, Paper Protector, Cover- up) | C7: 309 | D7: 4823909000 | E7: Gowns, Patient (incl. Cloth, Paper Protector, Cover- up) | G7: {=IFERROR(INDEX('Quantity in each box'!$H$8:$H$153,MATCH('Aggregated Data'!C7,'Quantity in each box'!$E$8:$E$153,0)),"NA")} -> 52.5 | H7: 10 | K7: 72224 | M7: 22214 | N7: Ukraine
A8: 22203 | B8: =C8&D8&E8 -> 3094823909000Gowns, Surgical, Non-sterile | C8: 309 | D8: 4823909000 | E8: Gowns, Surgical, Non-sterile | G8: {=IFERROR(INDEX('Quantity in each box'!$H$8:$H$153,MATCH('Aggregated Data'!C8,'Quantity in each box'!$E$8:$E$153,0)),"NA")} -> 52.5 | H8: 10 | K8: 72236 | M8: 72228 | N8: Ukraine
A9: 22203 | B9: =C9&D9&E9 -> 3116211320000Gowns, Surgical, Sterile | C9: 311 | D9: 6211320000 | E9: Gowns, Surgical, Sterile | G9: {=IFERROR(INDEX('Quantity in each box'!$H$8:$H$153,MATCH('Aggregated Data'!C9,'Quantity in each box'!$E$8:$E$153,0)),"NA")} -> NA | H9: 30 | K9: 52222 | M9: 12259 | N9: Ukraine
A10: 22203 | B10: =C10&D10&E10 -> 3116211320000Lab Coats And Tunics, Scrub Suits, Surgical | C10: 311 | D10: 6211320000 | E10: Lab Coats And Tunics, Scrub Suits, Surgical | G10: {=IFERROR(INDEX('Quantity in each box'!$H$8:$H$153,MATCH('Aggregated Data'!C10,'Quantity in each box'!$E$8:$E$153,0)),"NA")} -> NA | H10: 5 | K10: 72228 | M10: 22226 | N10: Ukraine
A11: 22203 | B11: =C11&D11&E11 -> 50230061001002x2, 4x4, Abd Sterile Dressings | C11: 502 | D11: 3006100100 | E11: 2x2, 4x4, Abd Sterile Dressings | G11: {=IFERROR(INDEX('Quantity in each box'!$H$8:$H$153,MATCH('Aggregated Data'!C11,'Quantity in each box'!$E$8:$E$153,0)),"NA")} -> NA | H11: 5 | K11: Sample packing list | M11: 42226 | N11: Ukraine
A12: 22203 | B12: =C12&D12&E12 -> 5053005909900Bandaids, Steristrips, Tape, Transparent Dressings (tegaderm) | C12: 505 | D12: 3005909900 | E12: Bandaids, Steristrips, Tape, Transparent Dressings (tegaderm) | G12: {=IFERROR(INDEX('Quantity in each box'!$H$8:$H$153,MATCH('Aggregated Data'!C12,'Quantity in each box'!$E$8:$E$153,0)),"NA")} -> NA | H12: 15 | M12: 62219 | N12: Ukraine
A13: 22203 | B13: =C13&D13&E13 -> 5063005590000Dressing Change Kits, Laceration Trays, Wound Care Kits | C13: 506 | D13: 3005590000 | E13: Dressing Change Kits, Laceration Trays, Wound Care Kits | G13: {=IFERROR(INDEX('Quantity in each box'!$H$8:$H$153,MATCH('Aggregated Data'!C13,'Quantity in each box'!$E$8:$E$153,0)),"NA")} -> NA | H13: 5 | M13: Shipping donated by CURE | N13: Ukraine
A14: 22203 | B14: =C14&D14&E14 -> 5073005900000Gauze and All Other Non Sterile Dressings | C14: 507 | D14: 3005900000 | E14: Gauze and All Other Non Sterile Dressings | G14: {=IFERROR(INDEX('Quantity in each box'!$H$8:$H$153,MATCH('Aggregated Data'!C14,'Quantity in each box'!$E$8:$E$153,0)),"NA")} -> NA | H14: 5 | M14: 72236 | N14: Ukraine
A15: 22203 | B15: =C15&D15&E15 -> 5083005909900Kerlix/Kling Dressing | C15: 508 | D15: 3005909900 | E15: Kerlix/Kling Dressing | G15: {=IFERROR(INDEX('Quantity in each box'!$H$8:$H$153,MATCH('Aggregated Data'!C15,'Quantity in each box'!$E$8:$E$153,0)),"NA")} -> NA | H15: 5 | M15: 52222 | N15: Ukraine
A16: 22203 | B16: =C16&D16&E16 -> 5103005909900Trauma Dressing | C16: 510 | D16: 3005909900 | E16: Trauma Dressing | G16: {=IFERROR(INDEX('Quantity in each box'!$H$8:$H$153,MATCH('Aggregated Data'!C16,'Quantity in each box'!$E$8:$E$153,0)),"NA")} -> NA | H16: 1 | N16: Ukraine
A17: 22203 | B17: =C17&D17&E17 -> 5123006100100Specialty Dressings (and All Other Dressings Not Fitting In Other Categories) | C17: 512 | D17: 3006100100 | E17: Specialty Dressings (and All Other Dressings Not Fitting In Other Categories) | G17: {=IFERROR(INDEX('Quantity in each box'!$H$8:$H$153,MATCH('Aggregated Data'!C17,'Quantity in each box'!$E$8:$E$153,0)),"NA")} -> NA | H17: 5 | N17: Ukraine
A18: 22203 | B18: =C18&D18&E18 -> 6013006500000Bags, Red, Spill Kits And Isolyszer | C18: 601 | D18: 3006500000 | E18: Bags, Red, Spill Kits And Isolyszer | G18: {=IFERROR(INDEX('Quantity in each box'!$H$8:$H$153,MATCH('Aggregated Data'!C18,'Quantity in each box'!$E$8:$E$153,0)),"NA")} -> NA | H18: 2 | N18: Ukraine
A19: 22203 | B19: =C19&D19&E19 -> 6063923100000Sharps Containers, Send Only w/ Lids | C19: 606 | D19: 3923100000 | E19: Sharps Containers, Send Only w/ Lids | G19: {=IFERROR(INDEX('Quantity in each box'!$H$8:$H$153,MATCH('Aggregated Data'!C19,'Quantity in each box'!$E$8:$E$153,0)),"NA")} -> NA | H19: 2 | N19: Ukraine
A20: 22203 | B20: =C20&D20&E20 -> 7029018390000Buffalo caps, prn adaptors and other iv infusion supplies, vial spikes and adaptators | C20: 702 | D20: 9018390000 | E20: Buffalo caps, prn adaptors and other iv infusion supplies, vial spikes and adaptators | G20: {=IFERROR(INDEX('Quantity in each box'!$H$8:$H$153,MATCH('Aggregated Data'!C20,'Quantity in each box'!$E$8:$E$153,0)),"NA")} -> NA | H20: 5 | N20: Ukraine
A21: 22203 | B21: =C21&D21&E21 -> 7039018390000Central Percutaneous Lines | C21: 703 | D21: 9018390000 | E21: Central Percutaneous Lines | G21: {=IFERROR(INDEX('Quantity in each box'!$H$8:$H$153,MATCH('Aggregated Data'!C21,'Quantity in each box'!$E$8:$E$153,0)),"NA")} -> NA | H21: 5 | N21: Ukraine
A22: 22203 | B22: =C22&D22&E22 -> 7049018390030IV Catheters/ Including Huber, Butterfly, Fistula | C22: 704 | D22: 9018390030 | E22: IV Catheters/ Including Huber, Butterfly, Fistula | G22: {=IFERROR(INDEX('Quantity in each box'!$H$8:$H$153,MATCH('Aggregated Data'!C22,'Quantity in each box'!$E$8:$E$153,0)),"NA")} -> NA | H22: 15 | N22: Ukraine
A23: 22203 | B23: =C23&D23&E23 -> 7059018390000IV Extension & Secondary Tubing | C23: 705 | D23: 9018390000 | E23: IV Extension & Secondary Tubing | G23: {=IFERROR(INDEX('Quantity in each box'!$H$8:$H$153,MATCH('Aggregated Data'!C23,'Quantity in each box'!$E$8:$E$153,0)),"NA")} -> NA | H23: 5 | N23: Ukraine
A24: 22203 | B24: =C24&D24&E24 -> 7069018390000IV Primary Tubing, Including Blood Tubing | C24: 706 | D24: 9018390000 | E24: IV Primary Tubing, Including Blood Tubing | G24: {=IFERROR(INDEX('Quantity in each box'!$H$8:$H$153,MATCH('Aggregated Data'!C24,'Quantity in each box'!$E$8:$E$153,0)),"NA")} -> NA | H24: 10 | N24: Ukraine
A25: 22203 | B25: =C25&D25&E25 -> 7099018310040Needles, Mixed Gauges | C25: 709 | D25: 9018310040 | E25: Needles, Mixed Gauges | G25: {=IFERROR(INDEX('Quantity in each box'!$H$8:$H$153,MATCH('Aggregated Data'!C25,'Quantity in each box'!$E$8:$E$153,0)),"NA")} -> NA | H25: 20 | N25: Ukraine
A26: 22203 | B26: =C26&D26&E26 -> 7109018310040Syringes, 1 cc/tb | C26: 710 | D26: 9018310040 | E26: Syringes, 1 cc/tb | G26: {=IFERROR(INDEX('Quantity in each box'!$H$8:$H$153,MATCH('Aggregated Data'!C26,'Quantity in each box'!$E$8:$E$153,0)),"NA")} -> NA | H26: 2 | N26: Ukraine
A27: 22203 | B27: =C27&D27&E27 -> 7119018310040Syringes, 3cc | C27: 711 | D27: 9018310040 | E27: Syringes, 3cc | G27: {=IFERROR(INDEX('Quantity in each box'!$H$8:$H$153,MATCH('Aggregated Data'!C27,'Quantity in each box'!$E$8:$E$153,0)),"NA")} -> NA | H27: 2 | N27: Ukraine
... A74: 22203 | B74: =C74&D74&E74 -> 52379021101000Crutches | C74: 5237 | D74: 9021101000 | E74: Crutches | G74: {=IFERROR(INDEX('Quantity in each box'!$H$8:$H$153,MATCH('Aggregated Data'!C74,'Quantity in each box'!$E$8:$E$153,0)),"NA")} -> 1 | H74: 5 | N74: Ukraine
A75: 22203 | B75: =C75&D75&E75 -> 56019402.90.0020Gurney | C75: 5601 | D75: 9402.90.0020 | E75: Gurney | G75: {=IFERROR(INDEX('Quantity in each box'!$H$8:$H$153,MATCH('Aggregated Data'!C75,'Quantity in each box'!$E$8:$E$153,0)),"NA")} -> 1 | H75: 4 | N75: Ukraine
A76: 22203 | B76: =C76&D76&E76 -> 58029018390000IV Pole | C76: 5802 | D76: 9018390000 | E76: IV Pole | G76: {=IFERROR(INDEX('Quantity in each box'!$H$8:$H$153,MATCH('Aggregated Data'!C76,'Quantity in each box'!$E$8:$E$153,0)),"NA")} -> 1 | H76: 5 | N76: Ukraine
A77: 22203 | B77: =C77&D77&E77 -> 62019402900000Vinyl Bed Surface, ERB | C77: 6201 | D77: 9402900000 | E77: Vinyl Bed Surface, ERB | G77: {=IFERROR(INDEX('Quantity in each box'!$H$8:$H$153,MATCH('Aggregated Data'!C77,'Quantity in each box'!$E$8:$E$153,0)),"NA")} -> 1 | H77: 55 | N77: Ukraine
A78: 22203 | B78: =C78&D78&E78 -> 62039403208009Mayo Stand | C78: 6203 | D78: 9403208009 | E78: Mayo Stand | G78: {=IFERROR(INDEX('Quantity in each box'!$H$8:$H$153,MATCH('Aggregated Data'!C78,'Quantity in each box'!$E$8:$E$153,0)),"NA")} -> NA | H78: 1 | N78: Ukraine
A79: 22203 | B79: =C79&D79&E79 -> 65004819100000Paper, Exam Table Rolls in Boxes | C79: 6500 | D79: 4819100000 | E79: Paper, Exam Table Rolls in Boxes | G79: {=IFERROR(INDEX('Quantity in each box'!$H$8:$H$153,MATCH('Aggregated Data'!C79,'Quantity in each box'!$E$8:$E$153,0)),"NA")} -> NA | H79: 2 | N79: Ukraine
A80: 22203 | B80: =C80&D80&E80 -> 68169401300009Stool, Exam | C80: 6816 | D80: 9401300009 | E80: Stool, Exam | G80: {=IFERROR(INDEX('Quantity in each box'!$H$8:$H$153,MATCH('Aggregated Data'!C80,'Quantity in each box'!$E$8:$E$153,0)),"NA")} -> 1 | H80: 2 | N80: Ukraine
A81: 22203 | B81: =C81&D81&E81 -> 68229018908409Surgical Instrument Kit, Suture Set | C81: 6822 | D81: 9018908409 | E81: Surgical Instrument Kit, Suture Set | G81: {=IFERROR(INDEX('Quantity in each box'!$H$8:$H$153,MATCH('Aggregated Data'!C81,'Quantity in each box'!$E$8:$E$153,0)),"NA")} -> 1 | H81: 4 | N81: Ukraine
A82: 22203 | B82: =C82&D82&E82 -> 68259018908409Surgical Instrument Kit, General | C82: 6825 | D82: 9018908409 | E82: Surgical Instrument Kit, General | G82: {=IFERROR(INDEX('Quantity in each box'!$H$8:$H$153,MATCH('Aggregated Data'!C82,'Quantity in each box'!$E$8:$E$153,0)),"NA")} -> 1 | H82: 1 | N82: Ukraine
A83: 22203 | B83: =C83&D83&E83 -> 68359018900000Surgical Instrument Kit, Delivery | C83: 6835 | D83: 9018900000 | E83: Surgical Instrument Kit, Delivery | G83: {=IFERROR(INDEX('Quantity in each box'!$H$8:$H$153,MATCH('Aggregated Data'!C83,'Quantity in each box'!$E$8:$E$153,0)),"NA")} -> 1 | H83: 1 | N83: Ukraine
A84: 22203 | B84: =C84&D84&E84 -> 68389018908409Surgical Instrument Kit, Ortho | C84: 6838 | D84: 9018908409 | E84: Surgical Instrument Kit, Ortho | G84: {=IFERROR(INDEX('Quantity in each box'!$H$8:$H$153,MATCH('Aggregated Data'!C84,'Quantity in each box'!$E$8:$E$153,0)),"NA")} -> 1 | H84: 1 | N84: Ukraine
A85: 22203 | B85: =C85&D85&E85 -> 68479018908409Surgical Instrument Kit, Minor | C85: 6847 | D85: 9018908409 | E85: Surgical Instrument Kit, Minor | G85: {=IFERROR(INDEX('Quantity in each box'!$H$8:$H$153,MATCH('Aggregated Data'!C85,'Quantity in each box'!$E$8:$E$153,0)),"NA")} -> NA | H85: 1 | N85: Ukraine
A86: 22203 | B86: =C86&D86&E86 -> 69059402900000Table, Exam | C86: 6905 | D86: 9402900000 | E86: Table, Exam | G86: {=IFERROR(INDEX('Quantity in each box'!$H$8:$H$153,MATCH('Aggregated Data'!C86,'Quantity in each box'!$E$8:$E$153,0)),"NA")} -> 1 | H86: 4 | N86: Ukraine
...

Sheet Clean Data (5 shipments)
A1: Shipment ID | B1: Product Code | C1: HS Code | D1: Description | E1: Unique Ids | F1: Number Ordered | G1: Pieces/ Cartons | H1: Total Quantity | I1: Net Weight (kg) | J1: Unit Value ($) | K1: Total Value ($)
A2: 62219 | B2: 301 | C2: 6302210000 | D2: Bed Linens And Towels | E2: =A2&+C2 -> 622196302210000 | F2: 10
A3: 62219 | B3: 302 | C3: 6307909800 | D3: Surgical Caps And Hats, Shoe Covers | E3: =A3&+C3 -> 622196307909800 | F3: 10
A4: 62219 | B4: 305.99 | C4: 3926201010 | D4: Gloves, Non-sterile | E4: =A4&+C4 -> 622193926201010 | F4: 40
A5: 62219 | B5: 310.99 | C5: 6211320000 | D5: Gowns, Surgical, Sterile | E5: =A5&+C5 -> 622196211320000 | F5: 30
A6: 62219 | B6: 311.1 | C6: 6211320000 | D6: Scrubs, FIG | E6: =A6&+C6 -> 622196211320000 | F6: 10
A7: 62219 | B7: 501.99 | C7: 3006100100 | D7: 2x2, 4x4, Abd Sterile Dressings | E7: =A7&+C7 -> 622193006100100 | F7: 15
A8: 62219 | B8: 506.99 | C8: 3005900000 | D8: Gauze and All Other Non Sterile Dressings | E8: =A8&+C8 -> 622193005900000 | F8: 2
A9: 62219 | B9: 507.99 | C9: 3005909900 | D9: Kerlix/Kling Dressing | E9: =A9&+C9 -> 622193005909900 | F9: 10
A10: 62219 | B10: 511.99 | C10: 3006100100 | D10: Specialty Dressings (and All Other Dressings Not Fitting In Other Categories) | E10: =A10&+C10 -> 622193006100100 | F10: 2
A11: 62219 | B11: 601 | C11: 3006500000 | D11: Bags, Red, Spill Kits And Isolyszer | E11: =A11&+C11 -> 622193006500000 | F11: 10
A12: 62219 | B12: 602.99 | C12: 3808940000 | D12: Disinfectant, Non-Patient; Also Sterilization Products & Sprays (Cidex, Etc) | E12: =A12&+C12 -> 622193808940000 | F12: 10
A13: 62219 | B13: 604 | C13: 3923100000 | D13: Liners, Trash Can, Laundry & Plastic Bags, Mopheads | E13: =A13&+C13 -> 622193923100000 | F13: 5
... A47: 62219 | B47: 1707.99 | C47: 9018390030 | D47: Suction Catheter, Tips, Tubings & Connectors | E47: =A47&+C47 -> 622199018390030 | F47: 5
A48: 62219 | B48: 1801.99 | C48: 3923.29.0000 | D48: Urinary Bags (Leg and Bedside) And Urinary Supplies | E48: =A48&+C48 -> 622193923.29.0000 | F48: 2
A49: 62219 | B49: 1802.99 | C49: 9018390030 | D49: Urinary Catheters, Trays & Insertion Sets | E49: =A49&+C49 -> 622199018390030 | F49: 5
A50: 62219 | B50: 1913 | C50: 8419200000 | D50: Autoclave, Sterilizer, Desktop | E50: =A50&+C50 -> 622198419200000 | F50: 1
A51: 62219 | B51: 2104 | C51: 9018900000 | D51: Cast Saw | E51: =A51&+C51 -> 622199018900000 | F51: 1
A52: 62219 | B52: 2113 | C52: 9019200000 | D52: Cold Therapy Unit / Portable | E52: =A52&+C52 -> 622199019200000 | F52: 2
A53: 62219 | B53: 2117.1 | C53: 9019200000 | D53: Concentrator, Oxygen | E53: =A53&+C53 -> 622199019200000 | F53: 23
A54: 62219 | B54: 2120.0199 | C54: 9019200000 | D54: CPAP Supplies | E54: =A54&+C54 -> 622199019200000 | F54: 1
A55: 62219 | B55: 2120.1 | C55: 9019200000 | D55: CPAP Unit W/ Humidifier | E55: =A55&+C55 -> 622199019200000 | F55: 1
A56: 62219 | B56: 3006 | C56: 9018902000 | D56: Laryngoscope | E56: =A56&+C56 -> 622199018902000 | F56: 4
A57: 62219 | B57: 3013 | C57: 9405204001 | D57: Light, Exam | E57: =A57&+C57 -> 622199405204001 | F57: 2
A58: 62219 | B58: 3110 | C58: 9018199000 | D58: Monitor, vital signs, 5 function (NIPB,Pulse, Optional TEMP,SPO2,ECG) | E58: =A58&+C58 -> 622199018199000 | F58: 1
A59: 62219 | B59: 3200 | C59: 9019200000 | D59: Nebulizer | E59: =A59&+C59 -> 622199019200000 | F59: 2
A60: 62219 | B60: 3308 | C60: 9018908409 | D60: Otoscope / Ophthalmoscope Wall Mounted AC Powered | E60: =A60&+C60 -> 622199018908409 | F60: 2
... A73: 62219 | B73: 5112 | C73: 9402900010 | D73: Bed, ICU | E73: =A73&+C73 -> 622199402900010 | F73: 2
A74: 62219 | B74: 5112.1 | C74: 9403.20.0010 | D74: Bed, ICU with Air Mattress | E74: =A74&+C74 -> 622199403.20.0010 | F74: 2
A75: 62219 | B75: 5203 | C75: 9403109809 | D75: Cabinet, Misc | E75: =A75&+C75 -> 622199403109809 | F75: 2
A76: 62219 | B76: 5206 | C76: 9021101000 | D76: Cane, Quad | E76: =A76&+C76 -> 622199021101000 | F76: 15
A77: 62219 | B77: 5213 | C77: 9402900000 | D77: Cart, Oxygen Cylinder | E77: =A77&+C77 -> 622199402900000 | F77: 1
A78: 62219 | B78: 5228 | C78: 9403208009 | D78: Commode, Bedside | E78: =A78&+C78 -> 622199403208009 | F78: 15
A79: 62219 | B79: 5237 | C79: 9021101000 | D79: Crutches | E79: =A79&+C79 -> 622199021101000 | F79: 15
A80: 62219 | B80: 5501 | C80: 9403109300 | D80: File Cabinet | E80: =A80&+C80 -> 622199403109300 | F80: 1
A81: 62219 | B81: 5601 | C81: 9402.90.0020 | D81: Gurney | E81: =A81&+C81 -> 622199402.90.0020 | F81: 4
A82: 62219 | B82: 5701 | C82: 9402900000 | D82: Hoyer Lift | E82: =A82&+C82 -> 622199402900000 | F82: 5
A83: 62219 | B83: 5802 | C83: 9018390000 | D83: IV Pole | E83: =A83&+C83 -> 622199018390000 | F83: 5
A84: 62219 | B84: 6201 | C84: 9402900000 | D84: Vinyl Bed Surface | E84: =A84&+C84 -> 622199402900000 | F84: 12
A85: 62219 | B85: 6201.1 | C85: 9402900000 | D85: Vinyl Bed Surface, ERB | E85: =A85&+C85 -> 622199402900000 | F85: 15
...

Sheet Input data>>>

Sheet Quantity in each box
E7: Product Code | F7: HS Code | G7: Description | H7: Quantity per box
E8: 3416.0199 | F8: 90189099 | G8: Pump, IV Tubing | H8: 0
E9: 3600 | F9: 9018907500 | G9: Reflex Hammer | H9: 0
E10: 3710 | F10: 9018901000 | G10: Sphygmomanometer, Wall Mount | H10: 0
E11: 3815.45 | F11: 85043300 | G11: Transformer, 2,000 watt | H11: 0
E12: 2111 | F12: 8421192009 | G12: Centrifuge, Lab | H12: 1
E13: 2117 | F13: 9019200000 | G13: Concentrator, Oxygen | H13: 1
E14: 3013 | F14: 9405204001 | G14: Light, Exam | H14: 1
E15: 3106 | F15: 9018199000 | G15: Monitor, Clinical, 2 -4 function (NIBP, Pulse, optional TEMP & SPO2) | H15: 1
E16: 3309.1 | F16: 9019200000 | G16: Oximeter, Pulse, Battery Operated | H16: 1
E17: 3416 | F17: 90189099 | G17: Pump, IV | H17: 1
E18: 3708 | F18: 9018908409 | G18: Speculum, Non Disposable, Vaginal | H18: 1
E19: 3710.01 | F19: 9018901000 | G19: Sphygmomanometer Cuffs | H19: 1
... E33: 5108 | F33: 9402900020 | G33: Bed, Birthing | H33: 1
E34: 5108.2 | F34: 9402.90.0020 | G34: Birthing Gurney | H34: 1
E35: 5112 | F35: 9402900010 | G35: Bed, ICU | H35: 1
E36: 5115 | F36: 9402900010 | G36: Bed, Roll Out, Cot | H36: 1
E37: 5205 | F37: 9021100090 | G37: Cane, Forearm, Other | H37: 1
E38: 5206 | F38: 9021101000 | G38: Cane, Quad | H38: 1
E39: 5208 | F39: 3923100000 | G39: Cart, Crash | H39: 1
E40: 5210 | F40: 9403200000 | G40: Cart, Linen | H40: 1
E41: 5212 | F41: 3924900009 | G41: Cart, Misc / Utility | H41: 1
E42: 5221 | F42: 9401790009 | G42: Chair, Office | H42: 1
E43: 5225 | F43: 9401790009 | G43: Chair, Waiting Room | H43: 1
E44: 5228 | F44: 9403208009 | G44: Commode, Bedside | H44: 1
E45: 5236 | F45: 9402900000 | G45: Crib | H45: 1
E46: 5237 | F46: 9021101000 | G46: Crutches | H46: 1
E47: 5601 | F47: 9402.90.0020 | G47: Gurney | H47: 1
E48: 5701 | F48: 9402900000 | G48: Hoyer Lift | H48: 1
E49: 5802 | F49: 9018390000 | G49: IV Pole | H49: 1
E50: 6201 | F50: 9402900000 | G50: Vinyl Bed Surface | H50: 1
E51: 6201.1 | F51: 9402900000 | G51: Vinyl Bed Surface, ERB | H51: 1
E52: 6508 | F52: 9404900000 | G52: Pillow | H52: 1
E53: 6512 | F53: 9019200000 | G53: Privacy Curtain | H53: 1
E54: 6800.1 | F54: (blank) | G54: Scale, Adult, Electric | H54: 1
E55: 6816 | F55: 9401300009 | G55: Stool, Exam | H55: 1
E56: 6822 | F56: 9018908409 | G56: Surgical Instrument Kit, Suture Set | H56: 1
E57: 6825 | F57: 9018908409 | G57: Surgical Instrument Kit, General | H57: 1
E58: 6835 | F58: 9018900000 | G58: Surgical Instrument Kit, Delivery | H58: 1
E59: 6838 | F59: 9018908409 | G59: Surgical Instrument Kit, Ortho | H59: 1
...

Sheet 12259
A1: Shipper: Project C.U.R.E. Project # 12259 Planned Manifest Country of Destination Ukraine
A2: Product Code | B2: HS Code | D2: Description | F2: Transformer Needed (only for 220-240V countries) | G2: Number Ordered
A3: Aid Pioneers - Ukraine Relief
A4: 301 | B4: 6302210000 | D4: Bed Linens And Towels | G4: 20
A5: 302 | B5: 6307909800 | D5: Surgical Caps And Hats, Shoe Covers | G5: 20
A6: 303 | B6: 6307.90.9995 | D6: Cloth Products Not Fitting In Other Items, Cubical Curtains | G6: 5
A7: 305.99 | B7: 3926201010 | D7: Gloves, Non-sterile | G7: 160
A8: 310.99 | B8: 6211320000 | D8: Gowns, Surgical, Sterile | G8: 50
A9: 501.99 | B9: 3006100100 | D9: 2x2, 4x4, Abd Sterile Dressings | G9: 10
A10: 504.99 | B10: 3005909900 | D10: Bandaids, Steristrips, Tape, Transparent Dressings (tegaderm) | G10: 15
A11: 507.99 | B11: 3005909900 | D11: Kerlix/Kling Dressing | G11: 5
A12: 511.99 | B12: 3006100100 | D12: Specialty Dressings (and All Other Dressings Not Fitting In Other Categories) | G12: 15
A13: 601 | B13: 3006500000 | D13: Bags, Red, Spill Kits And Isolyszer | G13: 15
A14: 606 | B14: 3923100000 | D14: Sharps Containers, Send Only w/ Lids | G14: 10
A15: 608.99 | B15: 3006101000 | D15: Sterilization, Tapes, Indicators, Wraps & Pouches | G15: 10
A16: 701.99 | B16: 9018390000 | D16: Buffalo caps, prn adaptors and other iv infusion supplies, vial spikes and adaptators | G16: 7
A17: 702.99 | B17: 9018390000 | D17: Central Percutaneous Lines | G17: 5
A18: 703.99 | B18: 9018390030 | D18: IV Catheters/ Including Huber, Butterfly, Fistula | G18: 5
... A30: 1006 | B30: 9619009000 | D30: Feminine Supplies - (including Pads, Belts, Perineal Wash, Sitz Baths) | G30: 5
A31: Product Code | B31: HS Code | D31: Description | F31: Transformer Needed (only for 220-240V countries) | G31: Number Ordered
A32: Aid Pioneers - Ukraine Relief
A33: 1103.99 | B33: 3005909900 | D33: Casting Supplies, Stockinette, Web Roll, Plaster, Fiberglass, Cast Shoes, Cast Heels | G33: 15
A34: 1108 | B34: 9021109000 | D34: Splints, Wraps (including Ace), and Slings, Hose Ted (anti-embolism) | G34: 20
A35: 1202.99 | B35: 3005905000 | D35: Applicator Swabs (Q-Tips), Tongue Depressors, Cotton Balls | G35: 5
A36: 1205 | B36: 7010901009 | D36: Containers, Basins, Emesis, Water Mugs, Pitchers, Glassware | G36: 5
A37: 1207 | B37: 9619008901 | D37: Diapers, Adult | G37: 40
A38: 1216 | B38: 4818909000 | D38: Paper Supplies, Towels, Cups, Napkins, Toilet Paper, Dishes | G38: 15
A39: 1217.99 | B39: 3307900008 | D39: Patient Supplies (Soaps, Shampoos, Mouthwash, Toothpaste, Belonging Bags),slippers | G39: 40
A40: 1222.99 | B40: 9619008109 | D40: Underpads, (Chux and Blue Pads) | G40: 20
A41: 1403.99 | B41: 9019200000 | D41: Nebulizer Supplies | G41: 5
A42: 1405.99 | B42: 9033000000 | D42: Respiratory Supplies, Other | G42: 2
A43: 1406.99 | B43: 9018390030 | D43: Suction Catheter & Glove Kit | G43: 20
A44: 1602.99 | B44: 9018903000 | D44: Anesthesia Facemasks | G44: 5
... A54: 1707.99 | B54: 9018390030 | D54: Suction Catheter, Tips, Tubings & Connectors | G54: 10
A55: 1801.99 | B55: 3923.29.0000 | D55: Urinary Bags (Leg and Bedside) And Urinary Supplies | G55: 2
A56: 1802.99 | B56: 9018390030 | D56: Urinary Catheters, Trays & Insertion Sets | G56: 5
A57: 2111 | B57: 8421192009 | D57: Centrifuge, Lab | F57: 3815.4 | G57: 1
A58: 2117.1 | B58: 9019200000 | D58: Concentrator, Oxygen | G58: 34
A59: 2120.0199 | B59: 9019200000 | D59: CPAP Supplies | F59: none | G59: 1
A60: 2120.1 | B60: 9019200000 | D60: CPAP Unit W/ Humidifier | F60: 3815.25 | G60: 1
...

Sheet 22226
A1: Shipper: Project C.U.R.E. Project # 22226 Planned Manifest Country of Destination Ukraine
A2: Product Code | B2: HS Code | D2: Description | F2: Transformer Needed (only for 220-240V countries) | G2: Number Ordered
A3: Aid Pioneers Ukraine Relief
A4: 302 | B4: 6307909800 | D4: Surgical Caps And Hats, Shoe Covers | G4: 20
A5: 305.99 | B5: 3926201010 | D5: Gloves, Non-sterile | G5: 75
A6: 306.99 | B6: 3926201010 | D6: Gloves, Sterile | G6: 10
A7: 308.99 | B7: 4823909000 | D7: Gowns, Patient (incl. Cloth, Paper Protector, Cover- up) | G7: 15
A8: 310.99 | B8: 6211320000 | D8: Gowns, Surgical, Sterile | G8: 35
A9: 311.1 | B9: 6211320000 | D9: Scrubs, FIG | F9: none | G9: 10
A10: 501.99 | B10: 3006100100 | D10: 2x2, 4x4, Abd Sterile Dressings | G10: 5
A11: 504.99 | B11: 3005909900 | D11: Bandaids, Steristrips, Tape, Transparent Dressings (tegaderm) | G11: 10
A12: 511.99 | B12: 3006100100 | D12: Specialty Dressings (and All Other Dressings Not Fitting In Other Categories) | G12: 5
A13: 602.99 | B13: 3808940000 | D13: Disinfectant, Non-Patient; Also Sterilization Products & Sprays (Cidex, Etc) | G13: 5
A14: 608.99 | B14: 3006101000 | D14: Sterilization, Tapes, Indicators, Wraps & Pouches | G14: 5
A15: 708.99 | B15: 9018310040 | D15: Needles, Mixed Gauges | G15: 20
A16: 710.99 | B16: 9018310040 | D16: Syringes, 3cc | G16: 20
A17: 801.99 | B17: 9018900000 | D17: Blood Drawing Supplies (Vacutainer Holders & Needles, Butterflies, Lancets, Tourniquets) | G17: 10
A18: 803.99 | B18: 3923100000 | D18: Containers and Labels, Lab | G18: 5
A19: 1004 | B19: 9619009000 | D19: Diapers and Wipes | G19: 20
A20: 1006 | B20: 9619009000 | D20: Feminine Supplies - (including Pads, Belts, Perineal Wash, Sitz Baths) | G20: 10
A21: 1103.99 | B21: 3005909900 | D21: Casting Supplies, Stockinette, Web Roll, Plaster, Fiberglass, Cast Shoes, Cast Heels | G21: 5
... A30: 1603.99 | B30: 9018900000 | D30: Ambu Bags | G30: 5
A31: Product Code | B31: HS Code | D31: Description | F31: Transformer Needed (only for 220-240V countries) | G31: Number Ordered
A32: Aid Pioneers Ukraine Relief
A33: 1607.99 | B33: 9018908409 | D33: Drains, Surgical, including Penrose and Suction Types | G33: 2
A34: 1609.99 | B34: 9020000000 | D34: Endotracheal Tubes | G34: 5
A35: 1610.99 | B35: 9018321000 | D35: Epidural / Spinal Needles and Kits | G35: 2
A36: 1619.99 | B36: 90180000000 | D36: OB/GYN Surgery Packs & Supplies | G36: 8
A37: 1620.99 | B37: 9021101000 | D37: Orthopedic Surgery Packs and Supplies | G37: 15
A38: 1624.99 | B38: 6307906500 | D38: Drapes, Sterile | G38: 10
A39: 1625.99 | B39: 901819 | D39: Tracheostomy & Cricothyroidotomy supplies, tubes and kits | G39: 2
A40: 1633.99 | B40: 9018903000 | D40: Anesthesia Laryngeal Mask Airway, lma | G40: 8
A41: 1706.99 | B41: 9018390000 | D41: Suction Canisters & Lids | G41: 2
A42: 1707.99 | B42: 9018390030 | D42: Suction Catheter, Tips, Tubings & Connectors | G42: 5
A43: 2117.1 | B43: 9019200000 | D43: Concentrator, Oxygen | G43: 46
A44: 2120.0199 | B44: 9019200000 | D44: CPAP Supplies | F44: none | G44: 1
A45: 2120.1 | B45: 9019200000 | D45: CPAP Unit W/ Humidifier | F45: 3815.25 | G45: 1
A46: 2602 | B46: 8479891000 | D46: Humidifier, Whole Room Air Mist | F46: 3815.15 | G46: 2
A47: 3006 | B47: 9018902000 | D47: Laryngoscope | F47: none | G47: 3
A48: 3013 | B48: 9405204001 | D48: Light, Exam | F48: 3815.15 | G48: 2
...

Sheet 42226
A1: Shipper: Project C.U.R.E. Project # 42226 Planned Manifest Country of Destination Ukraine
A2: Product Code | B2: HS Code | D2: Description | F2: Transformer Needed (only for 220-240V countries) | G2: Number Ordered
A3: Aid Pioneers - Ukraine Relief
A4: 302 | B4: 6307909800 | D4: Surgical Caps And Hats, Shoe Covers | G4: 20
A5: 305.99 | B5: 3926201010 | D5: Gloves, Non-sterile | G5: 40
A6: 308.99 | B6: 4823909000 | D6: Gowns, Patient (incl. Cloth, Paper Protector, Cover- up) | G6: 10
A7: 310.99 | B7: 6211320000 | D7: Gowns, Surgical, Sterile | G7: 25
A8: 311.1 | B8: 6211320000 | D8: Scrubs, FIG | F8: none | G8: 10
A9: 401.99 | B9: 4421900000 | D9: Dental Supplies | G9: 10
A10: 501.99 | B10: 3006100100 | D10: 2x2, 4x4, Abd Sterile Dressings | G10: 10
A11: 504.99 | B11: 3005909900 | D11: Bandaids, Steristrips, Tape, Transparent Dressings (tegaderm) | G11: 5
A12: 505.99 | B12: 3005590000 | D12: Dressing Change Kits, Laceration Trays, Wound Care Kits | G12: 10
A13: 507.99 | B13: 3005909900 | D13: Kerlix/Kling Dressing | G13: 2
A14: 511.99 | B14: 3006100100 | D14: Specialty Dressings (and All Other Dressings Not Fitting In Other Categories) | G14: 5
A15: 601 | B15: 3006500000 | D15: Bags, Red, Spill Kits And Isolyszer | G15: 10
A16: 604 | B16: 3923100000 | D16: Liners, Trash Can, Laundry & Plastic Bags, Mopheads | G16: 15
A17: 606 | B17: 3923100000 | D17: Sharps Containers, Send Only w/ Lids | G17: 15
A18: 608.99 | B18: 3006101000 | D18: Sterilization, Tapes, Indicators, Wraps & Pouches | G18: 5
A19: 701.99 | B19: 9018390000 | D19: Buffalo caps, prn adaptors and other iv infusion supplies, vial spikes and adaptators | G19: 2
A20: 702.99 | B20: 9018390000 | D20: Central Percutaneous Lines | G20: 2
... A31: 1001.99 | B31: 9619008101 | D31: Baby and birthing supplies | G31: 5
A32: Product Code | B32: HS Code | D32: Description | F32: Transformer Needed (only for 220-240V countries) | G32: Number Ordered
A33: Aid Pioneers - Ukraine Relief
A34: 1004 | B34: 9619009000 | D34: Diapers and Wipes | G34: 10
A35: 1006 | B35: 9619009000 | D35: Feminine Supplies - (including Pads, Belts, Perineal Wash, Sitz Baths) | G35: 5
A36: 1101 | B36: 3005900000 | D36: Activities Of Daily Living Aids (including Dressing Aids), Pt Supplies | G36: 5
A37: 1103.99 | B37: 3005909900 | D37: Casting Supplies, Stockinette, Web Roll, Plaster, Fiberglass, Cast Shoes, Cast Heels | G37: 15
A38: 1106 | B38: 9404909000 | D38: Pads, Wedges, Positioning Pillows | G38: 15
A39: 1108 | B39: 9021109000 | D39: Splints, Wraps (including Ace), and Slings, Hose Ted (anti-embolism) | G39: 40
A40: 1201 | B40: 7017900000 | D40: Admission Kits | G40: 2
A41: 1203 | B41: 9021101000 | D41: Bedpans And Urinals | G41: 10
A42: 1205 | B42: 7010901009 | D42: Containers, Basins, Emesis, Water Mugs, Pitchers, Glassware | G42: 2
A43: 1207 | B43: 9619008901 | D43: Diapers, Adult | G43: 30
A44: 1216 | B44: 4818909000 | D44: Paper Supplies, Towels, Cups, Napkins, Toilet Paper, Dishes | G44: 20
A45: 1222.99 | B45: 9619008109 | D45: Underpads, (Chux and Blue Pads) | G45: 15
... A56: 1701 | B56: 3005909900 | D56: Drapes, Non-sterile | G56: 10
A57: 1801.99 | B57: 3923.29.0000 | D57: Urinary Bags (Leg and Bedside) And Urinary Supplies | G57: 5
A58: 1802.99 | B58: 9018390030 | D58: Urinary Catheters, Trays & Insertion Sets | G58: 5
A59: 2002.0199 | B59: 9019200000 | D59: Bipap Supplies | F59: none | G59: 1
A60: 2104 | B60: 9018900000 | D60: Cast Saw | F60: 3815.4 | G60: 1
...

Sheet 72204
A1: Commercial Invoice
A2: Exporter Name and Address Project C.U.R.E. 10377 E. Geddes Ave Ste. 200 Centennial, CO 80112, USA Contact: Steven Wagener, Director of Logistics Phone: 303-792-0729, stevenwagener@projectcure.org | F2: Shipper Name and Address Project C.U.R.E. 10377 E. Geddes Ave Ste. 200 Centennial, CO 80112, USA Contact: Steven Wagener, Director of Logistics Phone: 303-792-0729, stevenwagener@projectcure.org
A3: Exporter Tax ID 84-1568566 | D3: Date Issued | F3: Invoice # 72204
A4: Freight Forwarder Name / Address Flexport , | F4: Final Destination Name / Address ,
A5: Commodity: Donated Medical Equipment and Supplies
A6: Consignee Name and Address "Heart for the Children of Ukraine" 2, Budivelnykiv Street Rivne City, Rivne Region 33004 Ukraine Tetiana Kidruk +380 63 995 1389 tetiana.kidruk@gmail.com | F6: Notify Party (if applicable) ,
A7: Vessel Name | D7: Voyage Number | F7: Port of Export | J7: Incoterms Handling Only to EXW Kansas City
A8: Carrier Name | D8: Container # | F8: Seal #
A9: Country of Destination Ukraine | D9: Bill of Lading # | F9: Project # 72204 | J9: Terms of Payment Pre-Paid
A10: Country of Origin / Export: U.S.A. | D10: Method of Transportation Ocean | F10: # of Packages 260 | J10: Weight of Goods (kg) 1495.76
A11: Product Code | B11: HS Code | C11: Description | E11: Transformer Needed (only for 220-240V countries) | G11: # Pieces/ Cartons | H11: Total Quantity | I11: Net Weight (kg) | K11: Unit Value ($) | L11: Total Value ($)
A12: 1108 | B12: 9021109000 | C12: Splints, Wraps (including Ace), and Slings, Hose Ted (anti- embolism) | G12: 14 | H12: 328 | I12: 86.73 | K12: 10.3 | L12: 3378.4
A13: 1402.99 | B13: 9018390000 | C13: Nasal Cannulas | G13: 45 | H13: 2424 | I13: 220.72 | K13: 1.03 | L13: 2496.72
A14: 1404.99 | B14: 90200000 | C14: Oxygen Masks and Tubing | G14: 28 | H14: 1563 | I14: 112.94 | K14: 3.03 | L14: 4735.89
A15: 1603 | B15: 9018900000 | C15: Ambu Bags | G15: 31 | H15: 908 | I15: 108.77 | K15: 25 | L15: 22700
A16: 1603.99 | B16: 9018900000 | C16: Ambu Bags | G16: 18 | H16: 362 | I16: 91.58 | K16: 25 | L16: 9050
A17: 1607 | B17: 9018908409 | C17: Drains, Surgical, including Penrose and Suction Types | G17: 2 | H17: 89 | I17: 10.16 | K17: 15.05 | L17: 1339.45
A18: 1607.99 | B18: 9018908409 | C18: Drains, Surgical, including Penrose and Suction Types | G18: 1 | H18: 20 | I18: 3.4 | K18: 15.05 | L18: 301
A19: 1609 | B19: 9020000000 | C19: Endotracheal Tubes | G19: 8 | H19: 679 | I19: 17.69 | K19: 3.48 | L19: 2362.92
A20: 1609.99 | B20: 9020000000 | C20: Endotracheal Tubes | G20: 6 | H20: 466 | I20: 16.47 | K20: 3.48 | L20: 1621.68
A21: 1617 | B21: 9018908409 | C21: General Surgery Packs & Supplies | G21: 4 | H21: 180 | I21: 23.54 | K21: 22.34 | L21: 4021.2
A22: 1620 | B22: 9021101000 | C22: Orthopedic Surgery Packs & Supplies | G22: 1 | H22: 1 | I22: 7.21 | K22: 20.04 | L22: 20.04
A23: 1625.99 | B23: 901819 | C23: Tracheostomy & Cricothyroidotomy supplies, tubes and kits | G23: 5 | H23: 874 | I23: 18.42 | K23: 30.36 | L23: 26534.64
A24: 6201.1 | B24: 9402900000 | C24: Vinyl Bed Surface, ERB | E24: none | G24: 60 | H24: 60 | I24: 598.74 | K24: 608 | L24: 36480
A25: 6820 | B25: 9018908409 | C25: Surgical Instrument Kit, Arthrex | E25: none | G25: 25 | H25: 25 | I25: 100.92 | K25: 1000 | L25: 25000
A26: 6822 | B26: 9018908409 | C26: Surgical Instrument Kit, Suture Set | E26: none | G26: 2 | H26: 2 | I26: 11.79 | K26: 261 | L26: 522
A27: 6825 | B27: 9018908409 | C27: Surgical Instrument Kit, General | E27: none | G27: 4 | H27: 4 | I27: 29.57 | K27: 658 | L27: 2632
A28: 6835 | B28: 9018900000 | C28: Surgical Instrument Kit, Delivery | E28: none | G28: 2 | H28: 2 | I28: 12.16 | K28: 406 | L28: 812
A29: 6838 | B29: 9018908409 | C29: Surgical Instrument Kit, Ortho | E29: none | G29: 2 | H29: 2 | I29: 13.61 | K29: 1652 | L29: 3304
A30: 6847 | B30: 9018908409 | C30: Surgical Instrument Kit, Minor | E30: none | G30: 2 | H30: 2 | I30: 11.34 | K30: 468 | L30: 936
A31: Total: 148247.94

Sheet 62219
A1: Shipper: Project C.U.R.E. Project # 62219 Planned Manifest Country of Destination Ukraine
A2: Product Code | B2: HS Code | D2: Description | F2: Transformer Needed (only for 220-240V countries) | G2: Number Ordered
A3: Aid Pioneers - Ukraine Relief
A4: 301 | B4: 6302210000 | D4: Bed Linens And Towels | G4: 10
A5: 302 | B5: 6307909800 | D5: Surgical Caps And Hats, Shoe Covers | G5: 10
A6: 305.99 | B6: 3926201010 | D6: Gloves, Non-sterile | G6: 40
A7: 310.99 | B7: 6211320000 | D7: Gowns, Surgical, Sterile | G7: 30
A8: 311.1 | B8: 6211320000 | D8: Scrubs, FIG | F8: none | G8: 10
A9: 501.99 | B9: 3006100100 | D9: 2x2, 4x4, Abd Sterile Dressings | G9: 15
A10: 506.99 | B10: 3005900000 | D10: Gauze and All Other Non Sterile Dressings | G10: 2
A11: 507.99 | B11: 3005909900 | D11: Kerlix/Kling Dressing | G11: 10
A12: 511.99 | B12: 3006100100 | D12: Specialty Dressings (and All Other Dressings Not Fitting In Other Categories) | G12: 2
A13: 601 | B13: 3006500000 | D13: Bags, Red, Spill Kits And Isolyszer | G13: 10
A14: 602.99 | B14: 3808940000 | D14: Disinfectant, Non-Patient; Also Sterilization Products & Sprays (Cidex, Etc) | G14: 10
A15: 604 | B15: 3923100000 | D15: Liners, Trash Can, Laundry & Plastic Bags, Mopheads | G15: 5
A16: 608.99 | B16: 3006101000 | D16: Sterilization, Tapes, Indicators, Wraps & Pouches | G16: 5
A17: 708.99 | B17: 9018310040 | D17: Needles, Mixed Gauges | G17: 30
A18: 709.99 | B18: 9018310040 | D18: Syringes, 1 cc/tb | G18: 10
A19: 710.99 | B19: 9018310040 | D19: Syringes, 3cc | G19: 25
A20: 714.99 | B20: 9018310040 | D20: Syringes, 30cc and 60cc | G20: 5
... A30: 1210.99 | B30: 9018900000 | D30: Feeding Tubes, Bags, Pump Set and Supplies | G30: 10
A31: Product Code | B31: HS Code | D31: Description | F31: Transformer Needed (only for 220-240V countries) | G31: Number Ordered
A32: Aid Pioneers - Ukraine Relief
A33: 1215.99 | B33: 3006910000 | D33: Ostomy (Colostomy, Ileostomy, Urostomy) Supplies, including Pouches, Adhesives, Etc) | G33: 10
A34: 1217.99 | B34: 3307900008 | D34: Patient Supplies (Soaps, Shampoos, Mouthwash, Toothpaste, Belonging Bags),slippers | G34: 15
A35: 1222.99 | B35: 9619008109 | D35: Underpads, (Chux and Blue Pads) | G35: 10
A36: 1402.99 | B36: 9018390000 | D36: Nasal Cannulas | G36: 5
A37: 1404.99 | B37: 90200000 | D37: Oxygen Masks and Tubing | G37: 10
A38: 1501.99 | B38: 3808940000 | D38: Alcohol and Betadine Pads & Swabs | G38: 20
A39: 1601.99 | B39: 9019200000 | D39: Anesthesia Circuit Sets | G39: 5
A40: 1602.99 | B40: 9018903000 | D40: Anesthesia Facemasks | G40: 5
A41: 1603.99 | B41: 9018900000 | D41: Ambu Bags | G41: 5
A42: 1606.99 | B42: 9018908409 | D42: Chest Tubes and Drainage Unites | G42: 10
A43: 1610.99 | B43: 9018321000 | D43: Epidural / Spinal Needles and Kits | G43: 2
A44: 1615.99 | B44: 9018908409 | D44: Ear, Nose & Throat Surgery Packs & Supplies | G44: 5
... A51: 1707.99 | B51: 9018390030 | D51: Suction Catheter, Tips, Tubings & Connectors | G51: 5
A52: 1801.99 | B52: 3923.29.0000 | D52: Urinary Bags (Leg and Bedside) And Urinary Supplies | G52: 2
A53: 1802.99 | B53: 9018390030 | D53: Urinary Catheters, Trays & Insertion Sets | G53: 5
A54: 1913 | B54: 8419200000 | D54: Autoclave, Sterilizer, Desktop | F54: 3815.42 | G54: 1
A55: 2104 | B55: 9018900000 | D55: Cast Saw | F55: 3815.4 | G55: 1
...
