Workbook

Sheet Звіт
F1: ="Аналітичний звіт про роботу надавача ПМД станом на "&TEXT(Dict!A2,"dd.mm.yyyy") -> Аналітичний звіт про роботу надавача ПМД станом на 01.08.2024
G2: =Dict!C2 -> 01996272, КОМУНАЛЬНЕ НЕКОМЕРЦІЙНЕ ПІДПРИЄМСТВО "ЗОЛОЧІВСЬКА ЦЕНТРАЛЬНА РАЙОННА ЛІКАРНЯ" ЗОЛОЧІВСЬКОЇ МІСЬКОЇ РАДИ ЗОЛОЧІВСЬКОГО РАЙОНУ ЛЬВІВСЬКОЇ ОБЛАСТІ
G3: Рівень звіту: | H3: Надавач | I3: <-- Обрати деталізацію звіту
G4: Профіль закладу
I5: =EOMONTH(J5,-2)+1 -> 45413 | J5: =EOMONTH(K5,-2)+1 -> 45444 | K5: =EOMONTH(Dict!$A$2,-2)+1 -> 45474 | L5: =Dict!$A$2 -> 45505 | M5: Зміна, за місяць
A6: 100 | B6: =VLOOKUP(A6,Індикатори!A:E,5,0) -> Заклад/Лікар | C6: =$H$3 -> Надавач | D6: =Dict!$A$2 -> 45505 | E6: Значення | H6: Кількість зареєстрованих місць надання допомоги: | I6: =IF(AND($B6="Надавач",$H$3<>"Надавач"),"-",SUMIFS(Заклад!$E:$E,Заклад!$A:$A,$A6,Заклад!$B:$B,$I$5,Заклад!$C:$C,Звіт!$C6)) -> 8 | J6: =IF(AND($B6="Надавач",$H$3<>"Надавач"),"-",SUMIFS(Заклад!$E:$E,Заклад!$A:$A,$A6,Заклад!$B:$B,$J$5,Заклад!$C:$C,Звіт!$C6)) -> 8 | K6: =IF(AND($B6="Надавач",$H$3<>"Надавач"),"-",SUMIFS(Заклад!$E:$E,Заклад!$A:$A,$A6,Заклад!$B:$B,$K$5,Заклад!$C:$C,Звіт!$C6)) -> 8 | L6: =IF(AND($B6="Надавач",$H$3<>"Надавач"),"-",SUMIFS(Заклад!$E:$E,Заклад!$A:$A,$A6,Заклад!$B:$B,$L$5,Заклад!$C:$C,Звіт!$C6)) -> 8 | M6: =IFERROR(L6-K6,"-") -> 0
A7: 101 | B7: =VLOOKUP(A7,Індикатори!A:E,5,0) -> Заклад/Лікар | C7: =$H$3 -> Надавач | D7: =Dict!$A$2 -> 45505 | E7: Значення | H7: Кількість зареєстрованих сімейних лікарів: | I7: =IF(AND($B7="Надавач",$H$3<>"Надавач"),"-",SUMIFS(Заклад!$E:$E,Заклад!$A:$A,$A7,Заклад!$B:$B,$I$5,Заклад!$C:$C,Звіт!$C7)) -> 27 | J7: =IF(AND($B7="Надавач",$H$3<>"Надавач"),"-",SUMIFS(Заклад!$E:$E,Заклад!$A:$A,$A7,Заклад!$B:$B,$J$5,Заклад!$C:$C,Звіт!$C7)) -> 27 | K7: =IF(AND($B7="Надавач",$H$3<>"Надавач"),"-",SUMIFS(Заклад!$E:$E,Заклад!$A:$A,$A7,Заклад!$B:$B,$K$5,Заклад!$C:$C,Звіт!$C7)) -> 27 | L7: =IF(AND($B7="Надавач",$H$3<>"Надавач"),"-",SUMIFS(Заклад!$E:$E,Заклад!$A:$A,$A7,Заклад!$B:$B,$L$5,Заклад!$C:$C,Звіт!$C7)) -> 27 | M7: =IFERROR(L7-K7,"-") -> 0
A8: 102 | B8: =VLOOKUP(A8,Індикатори!A:E,5,0) -> Заклад/Лікар | C8: =$H$3 -> Надавач | D8: =Dict!$A$2 -> 45505 | E8: Значення | H8: терапевтів: | I8: =IF(AND($B8="Надавач",$H$3<>"Надавач"),"-",SUMIFS(Заклад!$E:$E,Заклад!$A:$A,$A8,Заклад!$B:$B,$I$5,Заклад!$C:$C,Звіт!$C8)) -> 8 | J8: =IF(AND($B8="Надавач",$H$3<>"Надавач"),"-",SUMIFS(Заклад!$E:$E,Заклад!$A:$A,$A8,Заклад!$B:$B,$J$5,Заклад!$C:$C,Звіт!$C8)) -> 9 | K8: =IF(AND($B8="Надавач",$H$3<>"Надавач"),"-",SUMIFS(Заклад!$E:$E,Заклад!$A:$A,$A8,Заклад!$B:$B,$K$5,Заклад!$C:$C,Звіт!$C8)) -> 9 | L8: =IF(AND($B8="Надавач",$H$3<>"Надавач"),"-",SUMIFS(Заклад!$E:$E,Заклад!$A:$A,$A8,Заклад!$B:$B,$L$5,Заклад!$C:$C,Звіт!$C8)) -> 9 | M8: =IFERROR(L8-K8,"-") -> 0
A9: 103 | B9: =VLOOKUP(A9,Індикатори!A:E,5,0) -> Заклад/Лікар | C9: =$H$3 -> Надавач | D9: =Dict!$A$2 -> 45505 | E9: Значення | H9: педіатрів: | I9: =IF(AND($B9="Надавач",$H$3<>"Надавач"),"-",SUMIFS(Заклад!$E:$E,Заклад!$A:$A,$A9,Заклад!$B:$B,$I$5,Заклад!$C:$C,Звіт!$C9)) -> 13 | J9: =IF(AND($B9="Надавач",$H$3<>"Надавач"),"-",SUMIFS(Заклад!$E:$E,Заклад!$A:$A,$A9,Заклад!$B:$B,$J$5,Заклад!$C:$C,Звіт!$C9)) -> 13 | K9: =IF(AND($B9="Надавач",$H$3<>"Надавач"),"-",SUMIFS(Заклад!$E:$E,Заклад!$A:$A,$A9,Заклад!$B:$B,$K$5,Заклад!$C:$C,Звіт!$C9)) -> 13 | L9: =IF(AND($B9="Надавач",$H$3<>"Надавач"),"-",SUMIFS(Заклад!$E:$E,Заклад!$A:$A,$A9,Заклад!$B:$B,$L$5,Заклад!$C:$C,Звіт!$C9)) -> 13 | M9: =IFERROR(L9-K9,"-") -> 0
H10: Кількість декларацій: | I10: =SUM(I15:I19)+SUM(I24:I28) -> 48058 | J10: =SUM(J15:J19)+SUM(J24:J28) -> 48064 | K10: =SUM(K15:K19)+SUM(K24:K28) -> 47971 | L10: =SUM(L15:L19)+SUM(L24:L28) -> 47929 | M10: =L10-K10 -> -42
H12: Структура декларацій:
I13: =EOMONTH(J13,-2)+1 -> 45413 | J13: =EOMONTH(K13,-2)+1 -> 45444 | K13: =EOMONTH(Dict!$A$2,-2)+1 -> 45474 | L13: =Dict!$A$2 -> 45505 | M13: Зміна, за місяць
H14: Кількість задекларованих жінок за віковими групами:
A15: 109 | B15: =VLOOKUP(A15,Індикатори!A:E,5,0) -> Заклад/Лікар | C15: =$H$3 -> Надавач | D15: =Dict!$A$2 -> 45505 | E15: Значення | H15: 0-5 років | I15: =IF(AND($B15="Надавач",$H$3<>"Надавач"),"-",SUMIFS(Заклад!$E:$E,Заклад!$A:$A,$A15,Заклад!$B:$B,$I$5,Заклад!$C:$C,Звіт!$C15)) -> 1119 | J15: =IF(AND($B15="Надавач",$H$3<>"Надавач"),"-",SUMIFS(Заклад!$E:$E,Заклад!$A:$A,$A15,Заклад!$B:$B,$J$5,Заклад!$C:$C,Звіт!$C15)) -> 1111 | K15: =IF(AND($B15="Надавач",$H$3<>"Надавач"),"-",SUMIFS(Заклад!$E:$E,Заклад!$A:$A,$A15,Заклад!$B:$B,$K$5,Заклад!$C:$C,Звіт!$C15)) -> 1089 | L15: =IF(AND($B15="Надавач",$H$3<>"Надавач"),"-",SUMIFS(Заклад!$E:$E,Заклад!$A:$A,$A15,Заклад!$B:$B,$L$5,Заклад!$C:$C,Звіт!$C15)) -> 1078 | M15: =L15-K15 -> -11
A16: 110 | B16: =VLOOKUP(A16,Індикатори!A:E,5,0) -> Заклад/Лікар | C16: =$H$3 -> Надавач | D16: =Dict!$A$2 -> 45505 | E16: Значення | H16: 6-17 років | I16: =IF(AND($B16="Надавач",$H$3<>"Надавач"),"-",SUMIFS(Заклад!$E:$E,Заклад!$A:$A,$A16,Заклад!$B:$B,$I$5,Заклад!$C:$C,Звіт!$C16)) -> 3548 | J16: =IF(AND($B16="Надавач",$H$3<>"Надавач"),"-",SUMIFS(Заклад!$E:$E,Заклад!$A:$A,$A16,Заклад!$B:$B,$J$5,Заклад!$C:$C,Звіт!$C16)) -> 3545 | K16: =IF(AND($B16="Надавач",$H$3<>"Надавач"),"-",SUMIFS(Заклад!$E:$E,Заклад!$A:$A,$A16,Заклад!$B:$B,$K$5,Заклад!$C:$C,Звіт!$C16)) -> 3558 | L16: =IF(AND($B16="Надавач",$H$3<>"Надавач"),"-",SUMIFS(Заклад!$E:$E,Заклад!$A:$A,$A16,Заклад!$B:$B,$L$5,Заклад!$C:$C,Звіт!$C16)) -> 3554 | M16: =L16-K16 -> -4
A17: 111 | B17: =VLOOKUP(A17,Індикатори!A:E,5,0) -> Заклад/Лікар | C17: =$H$3 -> Надавач | D17: =Dict!$A$2 -> 45505 | E17: Значення | H17: 18-39 років | I17: =IF(AND($B17="Надавач",$H$3<>"Надавач"),"-",SUMIFS(Заклад!$E:$E,Заклад!$A:$A,$A17,Заклад!$B:$B,$I$5,Заклад!$C:$C,Звіт!$C17)) -> 6439 | J17: =IF(AND($B17="Надавач",$H$3<>"Надавач"),"-",SUMIFS(Заклад!$E:$E,Заклад!$A:$A,$A17,Заклад!$B:$B,$J$5,Заклад!$C:$C,Звіт!$C17)) -> 6427 | K17: =IF(AND($B17="Надавач",$H$3<>"Надавач"),"-",SUMIFS(Заклад!$E:$E,Заклад!$A:$A,$A17,Заклад!$B:$B,$K$5,Заклад!$C:$C,Звіт!$C17)) -> 6402 | L17: =IF(AND($B17="Надавач",$H$3<>"Надавач"),"-",SUMIFS(Заклад!$E:$E,Заклад!$A:$A,$A17,Заклад!$B:$B,$L$5,Заклад!$C:$C,Звіт!$C17)) -> 6388 | M17: =L17-K17 -> -14
A18: 112 | B18: =VLOOKUP(A18,Індикатори!A:E,5,0) -> Заклад/Лікар | C18: =$H$3 -> Надавач | D18: =Dict!$A$2 -> 45505 | E18: Значення | H18: 40-64 років | I18: =IF(AND($B18="Надавач",$H$3<>"Надавач"),"-",SUMIFS(Заклад!$E:$E,Заклад!$A:$A,$A18,Заклад!$B:$B,$I$5,Заклад!$C:$C,Звіт!$C18)) -> 8722 | J18: =IF(AND($B18="Надавач",$H$3<>"Надавач"),"-",SUMIFS(Заклад!$E:$E,Заклад!$A:$A,$A18,Заклад!$B:$B,$J$5,Заклад!$C:$C,Звіт!$C18)) -> 8736 | K18: =IF(AND($B18="Надавач",$H$3<>"Надавач"),"-",SUMIFS(Заклад!$E:$E,Заклад!$A:$A,$A18,Заклад!$B:$B,$K$5,Заклад!$C:$C,Звіт!$C18)) -> 8729 | L18: =IF(AND($B18="Надавач",$H$3<>"Надавач"),"-",SUMIFS(Заклад!$E:$E,Заклад!$A:$A,$A18,Заклад!$B:$B,$L$5,Заклад!$C:$C,Звіт!$C18)) -> 8737 | M18: =L18-K18 -> 8
A19: 113 | B19: =VLOOKUP(A19,Індикатори!A:E,5,0) -> Заклад/Лікар | C19: =$H$3 -> Надавач | D19: =Dict!$A$2 -> 45505 | E19: Значення | H19: 65+ років | I19: =IF(AND($B19="Надавач",$H$3<>"Надавач"),"-",SUMIFS(Заклад!$E:$E,Заклад!$A:$A,$A19,Заклад!$B:$B,$I$5,Заклад!$C:$C,Звіт!$C19)) -> 5370 | J19: =IF(AND($B19="Надавач",$H$3<>"Надавач"),"-",SUMIFS(Заклад!$E:$E,Заклад!$A:$A,$A19,Заклад!$B:$B,$J$5,Заклад!$C:$C,Звіт!$C19)) -> 5377 | K19: =IF(AND($B19="Надавач",$H$3<>"Надавач"),"-",SUMIFS(Заклад!$E:$E,Заклад!$A:$A,$A19,Заклад!$B:$B,$K$5,Заклад!$C:$C,Звіт!$C19)) -> 5361 | L19: =IF(AND($B19="Надавач",$H$3<>"Надавач"),"-",SUMIFS(Заклад!$E:$E,Заклад!$A:$A,$A19,Заклад!$B:$B,$L$5,Заклад!$C:$C,Звіт!$C19)) -> 5379 | M19: =L19-K19 -> 18
H20: Кількість декларацій: | I20: =SUM(I15:I19) -> 25198 | J20: =SUM(J15:J19) -> 25196 | K20: =SUM(K15:K19) -> 25139 | L20: =SUM(L15:L19) -> 25136 | M20: =L20-K20 -> -3
I22: =EOMONTH(J22,-2)+1 -> 45413 | J22: =EOMONTH(K22,-2)+1 -> 45444 | K22: =EOMONTH(Dict!$A$2,-2)+1 -> 45474 | L22: =Dict!$A$2 -> 45505 | M22: Зміна, за місяць
H23: Кількість задекларованих чоловіків за віковими групами:
A24: 104 | B24: =VLOOKUP(A24,Індикатори!A:E,5,0) -> Заклад/Лікар | C24: =$H$3 -> Надавач | D24: =Dict!$A$2 -> 45505 | E24: Значення | H24: 0-5 років | I24: =IF(AND($B24="Надавач",$H$3<>"Надавач"),"-",SUMIFS(Заклад!$E:$E,Заклад!$A:$A,$A24,Заклад!$B:$B,$I$5,Заклад!$C:$C,Звіт!$C24)) -> 1194 | J24: =IF(AND($B24="Надавач",$H$3<>"Надавач"),"-",SUMIFS(Заклад!$E:$E,Заклад!$A:$A,$A24,Заклад!$B:$B,$J$5,Заклад!$C:$C,Звіт!$C24)) -> 1179 | K24: =IF(AND($B24="Надавач",$H$3<>"Надавач"),"-",SUMIFS(Заклад!$E:$E,Заклад!$A:$A,$A24,Заклад!$B:$B,$K$5,Заклад!$C:$C,Звіт!$C24)) -> 1157 | L24: =IF(AND($B24="Надавач",$H$3<>"Надавач"),"-",SUMIFS(Заклад!$E:$E,Заклад!$A:$A,$A24,Заклад!$B:$B,$L$5,Заклад!$C:$C,Звіт!$C24)) -> 1127 | M24: =L24-K24 -> -30
A25: 105 | B25: =VLOOKUP(A25,Індикатори!A:E,5,0) -> Заклад/Лікар | C25: =$H$3 -> Надавач | D25: =Dict!$A$2 -> 45505 | E25: Значення | H25: 6-17 років | I25: =IF(AND($B25="Надавач",$H$3<>"Надавач"),"-",SUMIFS(Заклад!$E:$E,Заклад!$A:$A,$A25,Заклад!$B:$B,$I$5,Заклад!$C:$C,Звіт!$C25)) -> 3854 | J25: =IF(AND($B25="Надавач",$H$3<>"Надавач"),"-",SUMIFS(Заклад!$E:$E,Заклад!$A:$A,$A25,Заклад!$B:$B,$J$5,Заклад!$C:$C,Звіт!$C25)) -> 3857 | K25: =IF(AND($B25="Надавач",$H$3<>"Надавач"),"-",SUMIFS(Заклад!$E:$E,Заклад!$A:$A,$A25,Заклад!$B:$B,$K$5,Заклад!$C:$C,Звіт!$C25)) -> 3860 | L25: =IF(AND($B25="Надавач",$H$3<>"Надавач"),"-",SUMIFS(Заклад!$E:$E,Заклад!$A:$A,$A25,Заклад!$B:$B,$L$5,Заклад!$C:$C,Звіт!$C25)) -> 3866 | M25: =L25-K25 -> 6
A26: 106 | B26: =VLOOKUP(A26,Індикатори!A:E,5,0) -> Заклад/Лікар | C26: =$H$3 -> Надавач | D26: =Dict!$A$2 -> 45505 | E26: Значення | H26: 18-39 років | I26: =IF(AND($B26="Надавач",$H$3<>"Надавач"),"-",SUMIFS(Заклад!$E:$E,Заклад!$A:$A,$A26,Заклад!$B:$B,$I$5,Заклад!$C:$C,Звіт!$C26)) -> 6799 | J26: =IF(AND($B26="Надавач",$H$3<>"Надавач"),"-",SUMIFS(Заклад!$E:$E,Заклад!$A:$A,$A26,Заклад!$B:$B,$J$5,Заклад!$C:$C,Звіт!$C26)) -> 6770 | K26: =IF(AND($B26="Надавач",$H$3<>"Надавач"),"-",SUMIFS(Заклад!$E:$E,Заклад!$A:$A,$A26,Заклад!$B:$B,$K$5,Заклад!$C:$C,Звіт!$C26)) -> 6769 | L26: =IF(AND($B26="Надавач",$H$3<>"Надавач"),"-",SUMIFS(Заклад!$E:$E,Заклад!$A:$A,$A26,Заклад!$B:$B,$L$5,Заклад!$C:$C,Звіт!$C26)) -> 6738 | M26: =L26-K26 -> -31
A27: 107 | B27: =VLOOKUP(A27,Індикатори!A:E,5,0) -> Заклад/Лікар | C27: =$H$3 -> Надавач | D27: =Dict!$A$2 -> 45505 | E27: Значення | H27: 40-64 років | I27: =IF(AND($B27="Надавач",$H$3<>"Надавач"),"-",SUMIFS(Заклад!$E:$E,Заклад!$A:$A,$A27,Заклад!$B:$B,$I$5,Заклад!$C:$C,Звіт!$C27)) -> 8051 | J27: =IF(AND($B27="Надавач",$H$3<>"Надавач"),"-",SUMIFS(Заклад!$E:$E,Заклад!$A:$A,$A27,Заклад!$B:$B,$J$5,Заклад!$C:$C,Звіт!$C27)) -> 8072 | K27: =IF(AND($B27="Надавач",$H$3<>"Надавач"),"-",SUMIFS(Заклад!$E:$E,Заклад!$A:$A,$A27,Заклад!$B:$B,$K$5,Заклад!$C:$C,Звіт!$C27)) -> 8058 | L27: =IF(AND($B27="Надавач",$H$3<>"Надавач"),"-",SUMIFS(Заклад!$E:$E,Заклад!$A:$A,$A27,Заклад!$B:$B,$L$5,Заклад!$C:$C,Звіт!$C27)) -> 8065 | M27: =L27-K27 -> 7
A28: 108 | B28: =VLOOKUP(A28,Індикатори!A:E,5,0) -> Заклад/Лікар | C28: =$H$3 -> Надавач | D28: =Dict!$A$2 -> 45505 | E28: Значення | H28: 65+ років | I28: =IF(AND($B28="Надавач",$H$3<>"Надавач"),"-",SUMIFS(Заклад!$E:$E,Заклад!$A:$A,$A28,Заклад!$B:$B,$I$5,Заклад!$C:$C,Звіт!$C28)) -> 2962 | J28: =IF(AND($B28="Надавач",$H$3<>"Надавач"),"-",SUMIFS(Заклад!$E:$E,Заклад!$A:$A,$A28,Заклад!$B:$B,$J$5,Заклад!$C:$C,Звіт!$C28)) -> 2990 | K28: =IF(AND($B28="Надавач",$H$3<>"Надавач"),"-",SUMIFS(Заклад!$E:$E,Заклад!$A:$A,$A28,Заклад!$B:$B,$K$5,Заклад!$C:$C,Звіт!$C28)) -> 2988 | L28: =IF(AND($B28="Надавач",$H$3<>"Надавач"),"-",SUMIFS(Заклад!$E:$E,Заклад!$A:$A,$A28,Заклад!$B:$B,$L$5,Заклад!$C:$C,Звіт!$C28)) -> 2997 | M28: =L28-K28 -> 9
H29: Кількість декларацій: | I29: =SUM(I24:I28) -> 22860 | J29: =SUM(J24:J28) -> 22868 | K29: =SUM(K24:K28) -> 22832 | L29: =SUM(L24:L28) -> 22793 | M29: =L29-K29 -> -39
G30: Електронні Медичні записи:
I31: =EOMONTH(J31,-2)+1 -> 45413 | J31: =EOMONTH(K31,-2)+1 -> 45444 | K31: =EOMONTH(Dict!$A$2,-2)+1 -> 45474 | L31: =Dict!$A$2 -> 45505 | M31: Зміна, за місяць
A32: 114 | B32: =VLOOKUP(A32,Індикатори!A:E,5,0) -> Заклад/Лікар | C32: =$H$3 -> Надавач | D32: =Dict!$A$2 -> 45505 | E32: Значення | H32: Загальна кількість прийомів (на основі ЕМЗ) за попередній місяць: | I32: =IF(AND($B32="Надавач",$H$3<>"Надавач"),"-",SUMIFS(Заклад!$E:$E,Заклад!$A:$A,$A32,Заклад!$B:$B,$I$31,Заклад!$C:$C,Звіт!$C32)) -> 17318 | J32: =IF(AND($B32="Надавач",$H$3<>"Надавач"),"-",SUMIFS(Заклад!$E:$E,Заклад!$A:$A,$A32,Заклад!$B:$B,$J$31,Заклад!$C:$C,Звіт!$C32)) -> 16013 | K32: =IF(AND($B32="Надавач",$H$3<>"Надавач"),"-",SUMIFS(Заклад!$E:$E,Заклад!$A:$A,$A32,Заклад!$B:$B,$K$31,Заклад!$C:$C,Звіт!$C32)) -> 11585 | L32: =IF(AND($B32="Надавач",$H$3<>"Надавач"),"-",SUMIFS(Заклад!$E:$E,Заклад!$A:$A,$A32,Заклад!$B:$B,$L$31,Заклад!$C:$C,Звіт!$C32)) -> 13085 | M32: =L32-K32 -> 1500
A33: 115 | B33: =VLOOKUP(A33,Індикатори!A:E,5,0) -> Заклад/Лікар | C33: =$H$3 -> Надавач | D33: =Dict!$A$2 -> 45505 | E33: Значення | H33: з них засобами телемедицини | I33: =IF(AND($B33="Надавач",$H$3<>"Надавач"),"-",SUMIFS(Заклад!$E:$E,Заклад!$A:$A,$A33,Заклад!$B:$B,$I$31,Заклад!$C:$C,Звіт!$C33)) -> 810 | J33: =IF(AND($B33="Надавач",$H$3<>"Надавач"),"-",SUMIFS(Заклад!$E:$E,Заклад!$A:$A,$A33,Заклад!$B:$B,$J$31,Заклад!$C:$C,Звіт!$C33)) -> 548 | K33: =IF(AND($B33="Надавач",$H$3<>"Надавач"),"-",SUMIFS(Заклад!$E:$E,Заклад!$A:$A,$A33,Заклад!$B:$B,$K$31,Заклад!$C:$C,Звіт!$C33)) -> 364 | L33: =IF(AND($B33="Надавач",$H$3<>"Надавач"),"-",SUMIFS(Заклад!$E:$E,Заклад!$A:$A,$A33,Заклад!$B:$B,$L$31,Заклад!$C:$C,Звіт!$C33)) -> 381 | M33: =L33-K33 -> 17
A34: 116 | B34: =VLOOKUP(A34,Індикатори!A:E,5,0) -> Заклад/Лікар | C34: =$H$3 -> Надавач | D34: =Dict!$A$2 -> 45505 | E34: Значення | H34: з них на дому | I34: =IF(AND($B34="Надавач",$H$3<>"Надавач"),"-",SUMIFS(Заклад!$E:$E,Заклад!$A:$A,$A34,Заклад!$B:$B,$I$31,Заклад!$C:$C,Звіт!$C34)) -> 74 | J34: =IF(AND($B34="Надавач",$H$3<>"Надавач"),"-",SUMIFS(Заклад!$E:$E,Заклад!$A:$A,$A34,Заклад!$B:$B,$J$31,Заклад!$C:$C,Звіт!$C34)) -> 75 | K34: =IF(AND($B34="Надавач",$H$3<>"Надавач"),"-",SUMIFS(Заклад!$E:$E,Заклад!$A:$A,$A34,Заклад!$B:$B,$K$31,Заклад!$C:$C,Звіт!$C34)) -> 46 | L34: =IF(AND($B34="Надавач",$H$3<>"Надавач"),"-",SUMIFS(Заклад!$E:$E,Заклад!$A:$A,$A34,Заклад!$B:$B,$L$31,Заклад!$C:$C,Звіт!$C34)) -> 72 | M34: =L34-K34 -> 26
H35: Кількість взаємодій по пакетам ПМГ:
A36: 120 | B36: =VLOOKUP(A36,Індикатори!A:E,5,0) -> Заклад/Лікар | C36: =$H$3 -> Надавач | D36: =Dict!$A$2 -> 45505 | E36: Значення | H36: Взаємодій віднесених до пакету ПМД | I36: =IF(AND($B36="Надавач",$H$3<>"Надавач"),"-",SUMIFS(Заклад!$E:$E,Заклад!$A:$A,$A36,Заклад!$B:$B,$I$31,Заклад!$C:$C,Звіт!$C36)) -> 17123 | J36: =IF(AND($B36="Надавач",$H$3<>"Надавач"),"-",SUMIFS(Заклад!$E:$E,Заклад!$A:$A,$A36,Заклад!$B:$B,$J$31,Заклад!$C:$C,Звіт!$C36)) -> 15847 | K36: =IF(AND($B36="Надавач",$H$3<>"Надавач"),"-",SUMIFS(Заклад!$E:$E,Заклад!$A:$A,$A36,Заклад!$B:$B,$K$31,Заклад!$C:$C,Звіт!$C36)) -> 11370 | L36: =IF(AND($B36="Надавач",$H$3<>"Надавач"),"-",SUMIFS(Заклад!$E:$E,Заклад!$A:$A,$A36,Заклад!$B:$B,$L$31,Заклад!$C:$C,Звіт!$C36)) -> 13031 | M36: =L36-K36 -> 1661
A37: 121 | B37: =VLOOKUP(A37,Індикатори!A:E,5,0) -> Заклад/Лікар | C37: =$H$3 -> Надавач | D37: =Dict!$A$2 -> 45505 | E37: Значення | H37: Взаємодій віднесених до пакету супровід хворих на туберкульоз | I37: =IF(AND($B37="Надавач",$H$3<>"Надавач"),"-",SUMIFS(Заклад!$E:$E,Заклад!$A:$A,$A37,Заклад!$B:$B,$I$31,Заклад!$C:$C,Звіт!$C37)) -> 0 | J37: =IF(AND($B37="Надавач",$H$3<>"Надавач"),"-",SUMIFS(Заклад!$E:$E,Заклад!$A:$A,$A37,Заклад!$B:$B,$J$31,Заклад!$C:$C,Звіт!$C37)) -> 0 | K37: =IF(AND($B37="Надавач",$H$3<>"Надавач"),"-",SUMIFS(Заклад!$E:$E,Заклад!$A:$A,$A37,Заклад!$B:$B,$K$31,Заклад!$C:$C,Звіт!$C37)) -> 0 | L37: =IF(AND($B37="Надавач",$H$3<>"Надавач"),"-",SUMIFS(Заклад!$E:$E,Заклад!$A:$A,$A37,Заклад!$B:$B,$L$31,Заклад!$C:$C,Звіт!$C37)) -> 0 | M37: =L37-K37 -> 0
A38: 122 | B38: =VLOOKUP(A38,Індикатори!A:E,5,0) -> Заклад/Лікар | C38: =$H$3 -> Надавач | D38: =Dict!$A$2 -> 45505 | E38: Значення | H38: Взаємодій віднесених до пакету супровід осіб з психічними розладами | I38: =IF(AND($B38="Надавач",$H$3<>"Надавач"),"-",SUMIFS(Заклад!$E:$E,Заклад!$A:$A,$A38,Заклад!$B:$B,$I$31,Заклад!$C:$C,Звіт!$C38)) -> 195 | J38: =IF(AND($B38="Надавач",$H$3<>"Надавач"),"-",SUMIFS(Заклад!$E:$E,Заклад!$A:$A,$A38,Заклад!$B:$B,$J$31,Заклад!$C:$C,Звіт!$C38)) -> 166 | K38: =IF(AND($B38="Надавач",$H$3<>"Надавач"),"-",SUMIFS(Заклад!$E:$E,Заклад!$A:$A,$A38,Заклад!$B:$B,$K$31,Заклад!$C:$C,Звіт!$C38)) -> 215 | L38: =IF(AND($B38="Надавач",$H$3<>"Надавач"),"-",SUMIFS(Заклад!$E:$E,Заклад!$A:$A,$A38,Заклад!$B:$B,$L$31,Заклад!$C:$C,Звіт!$C38)) -> 54 | M38: =L38-K38 -> -161
A39: 123 | B39: =VLOOKUP(A39,Індикатори!A:E,5,0) -> Заклад/Лікар | C39: =$H$3 -> Надавач | D39: =Dict!$A$2 -> 45505 | E39: Значення | H39: Взаємодій віднесених до пакету ВІЛ | I39: =IF(AND($B39="Надавач",$H$3<>"Надавач"),"-",SUMIFS(Заклад!$E:$E,Заклад!$A:$A,$A39,Заклад!$B:$B,$I$31,Заклад!$C:$C,Звіт!$C39)) -> 0 | J39: =IF(AND($B39="Надавач",$H$3<>"Надавач"),"-",SUMIFS(Заклад!$E:$E,Заклад!$A:$A,$A39,Заклад!$B:$B,$J$31,Заклад!$C:$C,Звіт!$C39)) -> 0 | K39: =IF(AND($B39="Надавач",$H$3<>"Надавач"),"-",SUMIFS(Заклад!$E:$E,Заклад!$A:$A,$A39,Заклад!$B:$B,$K$31,Заклад!$C:$C,Звіт!$C39)) -> 0 | L39: =IF(AND($B39="Надавач",$H$3<>"Надавач"),"-",SUMIFS(Заклад!$E:$E,Заклад!$A:$A,$A39,Заклад!$B:$B,$L$31,Заклад!$C:$C,Звіт!$C39)) -> 0 | M39: =L39-K39 -> 0
A40: 124 | B40: =VLOOKUP(A40,Індикатори!A:E,5,0) -> Заклад/Лікар | C40: =$H$3 -> Надавач | D40: =Dict!$A$2 -> 45505 | E40: Значення | H40: Взаємодій віднесених до пакету ЗПТ | I40: =IF(AND($B40="Надавач",$H$3<>"Надавач"),"-",SUMIFS(Заклад!$E:$E,Заклад!$A:$A,$A40,Заклад!$B:$B,$I$31,Заклад!$C:$C,Звіт!$C40)) -> 0 | J40: =IF(AND($B40="Надавач",$H$3<>"Надавач"),"-",SUMIFS(Заклад!$E:$E,Заклад!$A:$A,$A40,Заклад!$B:$B,$J$31,Заклад!$C:$C,Звіт!$C40)) -> 0 | K40: =IF(AND($B40="Надавач",$H$3<>"Надавач"),"-",SUMIFS(Заклад!$E:$E,Заклад!$A:$A,$A40,Заклад!$B:$B,$K$31,Заклад!$C:$C,Звіт!$C40)) -> 0 | L40: =IF(AND($B40="Надавач",$H$3<>"Надавач"),"-",SUMIFS(Заклад!$E:$E,Заклад!$A:$A,$A40,Заклад!$B:$B,$L$31,Заклад!$C:$C,Звіт!$C40)) -> 0 | M40: =L40-K40 -> 0
A41: 125 | B41: =VLOOKUP(A41,Індикатори!A:E,5,0) -> Заклад/Лікар | C41: =$H$3 -> Надавач | D41: =Dict!$A$2 -> 45505 | E41: Значення | H41: Взаємодій віднесених до пакету моб паліатив | I41: =IF(AND($B41="Надавач",$H$3<>"Надавач"),"-",SUMIFS(Заклад!$E:$E,Заклад!$A:$A,$A41,Заклад!$B:$B,$I$31,Заклад!$C:$C,Звіт!$C41)) -> 0 | J41: =IF(AND($B41="Надавач",$H$3<>"Надавач"),"-",SUMIFS(Заклад!$E:$E,Заклад!$A:$A,$A41,Заклад!$B:$B,$J$31,Заклад!$C:$C,Звіт!$C41)) -> 0 | K41: =IF(AND($B41="Надавач",$H$3<>"Надавач"),"-",SUMIFS(Заклад!$E:$E,Заклад!$A:$A,$A41,Заклад!$B:$B,$K$31,Заклад!$C:$C,Звіт!$C41)) -> 0 | L41: =IF(AND($B41="Надавач",$H$3<>"Надавач"),"-",SUMIFS(Заклад!$E:$E,Заклад!$A:$A,$A41,Заклад!$B:$B,$L$31,Заклад!$C:$C,Звіт!$C41)) -> 0 | M41: =L41-K41 -> 0
A42: 126 | B42: =VLOOKUP(A42,Індикатори!A:E,5,0) -> Заклад/Лікар | C42: =$H$3 -> Надавач | D42: =Dict!$A$2 -> 45505 | E42: Значення | H42: Взаємодій не віднесених до жодного пакету | I42: =IF(AND($B42="Надавач",$H$3<>"Надавач"),"-",SUMIFS(Заклад!$E:$E,Заклад!$A:$A,$A42,Заклад!$B:$B,$I$31,Заклад!$C:$C,Звіт!$C42)) -> 48 | J42: =IF(AND($B42="Надавач",$H$3<>"Надавач"),"-",SUMIFS(Заклад!$E:$E,Заклад!$A:$A,$A42,Заклад!$B:$B,$J$31,Заклад!$C:$C,Звіт!$C42)) -> 28 | K42: =IF(AND($B42="Надавач",$H$3<>"Надавач"),"-",SUMIFS(Заклад!$E:$E,Заклад!$A:$A,$A42,Заклад!$B:$B,$K$31,Заклад!$C:$C,Звіт!$C42)) -> 31 | L42: =IF(AND($B42="Надавач",$H$3<>"Надавач"),"-",SUMIFS(Заклад!$E:$E,Заклад!$A:$A,$A42,Заклад!$B:$B,$L$31,Заклад!$C:$C,Звіт!$C42)) -> 28 | M42: =L42-K42 -> -3
...

Sheet Зведена за лікарями
A1: ="Зведений звіт про роботу лікарів в ЕСОЗ станом на "&TEXT(Dict!A2,"dd.mm.yyyy") -> Зведений звіт про роботу лікарів в ЕСОЗ станом на 01.08.2024
P2: =Dict!C2 -> 01996272, КОМУНАЛЬНЕ НЕКОМЕРЦІЙНЕ ПІДПРИЄМСТВО "ЗОЛОЧІВСЬКА ЦЕНТРАЛЬНА РАЙОННА ЛІКАРНЯ" ЗОЛОЧІВСЬКОЇ МІСЬКОЇ РАДИ ЗОЛОЧІВСЬКОГО РАЙОНУ ЛЬВІВСЬКОЇ ОБЛАСТІ
C3: Індикатори:
B4: Заклад 12 | C4: Всього декларацій | D4: =VLOOKUP(D5,Індикатори!$A:$B,2,0) -> Кількість декларацій чоловіки 0-5. | E4: =VLOOKUP(E5,Індикатори!$A:$B,2,0) -> Кількість декларацій чоловіки 6-17. | F4: =VLOOKUP(F5,Індикатори!$A:$B,2,0) -> Кількість декларацій чоловіки 18-39. | G4: =VLOOKUP(G5,Індикатори!$A:$B,2,0) -> Кількість декларацій чоловіки 40-64. | H4: =VLOOKUP(H5,Індикатори!$A:$B,2,0) -> Кількість декларацій чоловіки 65+. | I4: =VLOOKUP(I5,Індикатори!$A:$B,2,0) -> Кількість декларацій жінки 0-5. | J4: =VLOOKUP(J5,Індикатори!$A:$B,2,0) -> Кількість декларацій жінки 6-17. | K4: =VLOOKUP(K5,Індикатори!$A:$B,2,0) -> Кількість декларацій жінки 18-39. | ... AL4: =VLOOKUP(AL5,Індикатори!$A:$B,2,0) -> Профілактичний огляд осіб вікової групи 65 років і старше
D5: 104 | E5: 105 | F5: 106 | G5: 107 | H5: 108 | I5: 109 | J5: 110 | K5: 111 | L5: 112 | M5: 113 | N5: 114 | O5: 127 | P5: 2 | Q5: 3 | R5: 4 | S5: 5 | T5: 6 | U5: 7 | V5: 8 | W5: 9 | X5: 10 | Y5: 11 | Z5: 12 | AA5: 13 | AB5: 14 | AC5: 15 | AD5: 16 | AE5: 17 | AF5: 18 | AG5: 20 | AH5: 23 | AI5: 24 | AJ5: 25 | AK5: 26 | AL5: 27
B6: По закладу | C6: =SUM(D6:M6) -> 47929 | D6: =SUMIFS(Заклад!$E:$E,Заклад!$C:$C,"Надавач",Заклад!$A:$A,D$5,Заклад!$B:$B,Dict!$A$2) -> 1127 | E6: =SUMIFS(Заклад!$E:$E,Заклад!$C:$C,"Надавач",Заклад!$A:$A,E$5,Заклад!$B:$B,Dict!$A$2) -> 3866 | F6: =SUMIFS(Заклад!$E:$E,Заклад!$C:$C,"Надавач",Заклад!$A:$A,F$5,Заклад!$B:$B,Dict!$A$2) -> 6738 | G6: =SUMIFS(Заклад!$E:$E,Заклад!$C:$C,"Надавач",Заклад!$A:$A,G$5,Заклад!$B:$B,Dict!$A$2) -> 8065 | H6: =SUMIFS(Заклад!$E:$E,Заклад!$C:$C,"Надавач",Заклад!$A:$A,H$5,Заклад!$B:$B,Dict!$A$2) -> 2997 | I6: =SUMIFS(Заклад!$E:$E,Заклад!$C:$C,"Надавач",Заклад!$A:$A,I$5,Заклад!$B:$B,Dict!$A$2) -> 1078 | J6: =SUMIFS(Заклад!$E:$E,Заклад!$C:$C,"Надавач",Заклад!$A:$A,J$5,Заклад!$B:$B,Dict!$A$2) -> 3554 | K6: =SUMIFS(Заклад!$E:$E,Заклад!$C:$C,"Надавач",Заклад!$A:$A,K$5,Заклад!$B:$B,Dict!$A$2) -> 6388 | ... AL6: =SUMIFS(Заклад!$E:$E,Заклад!$C:$C,"Надавач",Заклад!$A:$A,AL$5,Заклад!$B:$B,Dict!$A$2) -> 0.00097713504
B7: Бартошик Лілія Михайлівна | C7: =SUM(D7:M7) -> 661 | D7: =SUMIFS(Заклад!$E:$E,Заклад!$C:$C,$B7,Заклад!$A:$A,D$5,Заклад!$B:$B,Dict!$A$2) -> 67 | E7: =SUMIFS(Заклад!$E:$E,Заклад!$C:$C,$B7,Заклад!$A:$A,E$5,Заклад!$B:$B,Dict!$A$2) -> 285 | F7: =SUMIFS(Заклад!$E:$E,Заклад!$C:$C,$B7,Заклад!$A:$A,F$5,Заклад!$B:$B,Dict!$A$2) -> 0 | G7: =SUMIFS(Заклад!$E:$E,Заклад!$C:$C,$B7,Заклад!$A:$A,G$5,Заклад!$B:$B,Dict!$A$2) -> 0 | H7: =SUMIFS(Заклад!$E:$E,Заклад!$C:$C,$B7,Заклад!$A:$A,H$5,Заклад!$B:$B,Dict!$A$2) -> 0 | I7: =SUMIFS(Заклад!$E:$E,Заклад!$C:$C,$B7,Заклад!$A:$A,I$5,Заклад!$B:$B,Dict!$A$2) -> 84 | J7: =SUMIFS(Заклад!$E:$E,Заклад!$C:$C,$B7,Заклад!$A:$A,J$5,Заклад!$B:$B,Dict!$A$2) -> 225 | K7: =SUMIFS(Заклад!$E:$E,Заклад!$C:$C,$B7,Заклад!$A:$A,K$5,Заклад!$B:$B,Dict!$A$2) -> 0 | ... AL7: =SUMIFS(Заклад!$E:$E,Заклад!$C:$C,$B7,Заклад!$A:$A,AL$5,Заклад!$B:$B,Dict!$A$2) -> 0
B8: Боднар Стефанія Володимирівна | C8: =SUM(D8:M8) -> 1839 | D8: =SUMIFS(Заклад!$E:$E,Заклад!$C:$C,$B8,Заклад!$A:$A,D$5,Заклад!$B:$B,Dict!$A$2) -> 0 | E8: =SUMIFS(Заклад!$E:$E,Заклад!$C:$C,$B8,Заклад!$A:$A,E$5,Заклад!$B:$B,Dict!$A$2) -> 2 | F8: =SUMIFS(Заклад!$E:$E,Заклад!$C:$C,$B8,Заклад!$A:$A,F$5,Заклад!$B:$B,Dict!$A$2) -> 282 | G8: =SUMIFS(Заклад!$E:$E,Заклад!$C:$C,$B8,Заклад!$A:$A,G$5,Заклад!$B:$B,Dict!$A$2) -> 414 | H8: =SUMIFS(Заклад!$E:$E,Заклад!$C:$C,$B8,Заклад!$A:$A,H$5,Заклад!$B:$B,Dict!$A$2) -> 161 | I8: =SUMIFS(Заклад!$E:$E,Заклад!$C:$C,$B8,Заклад!$A:$A,I$5,Заклад!$B:$B,Dict!$A$2) -> 0 | J8: =SUMIFS(Заклад!$E:$E,Заклад!$C:$C,$B8,Заклад!$A:$A,J$5,Заклад!$B:$B,Dict!$A$2) -> 0 | K8: =SUMIFS(Заклад!$E:$E,Заклад!$C:$C,$B8,Заклад!$A:$A,K$5,Заклад!$B:$B,Dict!$A$2) -> 285 | ... AL8: =SUMIFS(Заклад!$E:$E,Заклад!$C:$C,$B8,Заклад!$A:$A,AL$5,Заклад!$B:$B,Dict!$A$2) -> 0
B9: Бурик Олена Василівна | C9: =SUM(D9:M9) -> 900 | D9: =SUMIFS(Заклад!$E:$E,Заклад!$C:$C,$B9,Заклад!$A:$A,D$5,Заклад!$B:$B,Dict!$A$2) -> 56 | E9: =SUMIFS(Заклад!$E:$E,Заклад!$C:$C,$B9,Заклад!$A:$A,E$5,Заклад!$B:$B,Dict!$A$2) -> 149 | F9: =SUMIFS(Заклад!$E:$E,Заклад!$C:$C,$B9,Заклад!$A:$A,F$5,Заклад!$B:$B,Dict!$A$2) -> 153 | G9: =SUMIFS(Заклад!$E:$E,Заклад!$C:$C,$B9,Заклад!$A:$A,G$5,Заклад!$B:$B,Dict!$A$2) -> 67 | H9: =SUMIFS(Заклад!$E:$E,Заклад!$C:$C,$B9,Заклад!$A:$A,H$5,Заклад!$B:$B,Dict!$A$2) -> 10 | I9: =SUMIFS(Заклад!$E:$E,Заклад!$C:$C,$B9,Заклад!$A:$A,I$5,Заклад!$B:$B,Dict!$A$2) -> 35 | J9: =SUMIFS(Заклад!$E:$E,Заклад!$C:$C,$B9,Заклад!$A:$A,J$5,Заклад!$B:$B,Dict!$A$2) -> 137 | K9: =SUMIFS(Заклад!$E:$E,Заклад!$C:$C,$B9,Заклад!$A:$A,K$5,Заклад!$B:$B,Dict!$A$2) -> 195 | ... AL9: =SUMIFS(Заклад!$E:$E,Заклад!$C:$C,$B9,Заклад!$A:$A,AL$5,Заклад!$B:$B,Dict!$A$2) -> 0
B10: Ведмедик Зоряна Михайлівна | C10: =SUM(D10:M10) -> 512 | D10: =SUMIFS(Заклад!$E:$E,Заклад!$C:$C,$B10,Заклад!$A:$A,D$5,Заклад!$B:$B,Dict!$A$2) -> 53 | E10: =SUMIFS(Заклад!$E:$E,Заклад!$C:$C,$B10,Заклад!$A:$A,E$5,Заклад!$B:$B,Dict!$A$2) -> 225 | F10: =SUMIFS(Заклад!$E:$E,Заклад!$C:$C,$B10,Заклад!$A:$A,F$5,Заклад!$B:$B,Dict!$A$2) -> 0 | G10: =SUMIFS(Заклад!$E:$E,Заклад!$C:$C,$B10,Заклад!$A:$A,G$5,Заклад!$B:$B,Dict!$A$2) -> 0 | H10: =SUMIFS(Заклад!$E:$E,Заклад!$C:$C,$B10,Заклад!$A:$A,H$5,Заклад!$B:$B,Dict!$A$2) -> 0 | I10: =SUMIFS(Заклад!$E:$E,Заклад!$C:$C,$B10,Заклад!$A:$A,I$5,Заклад!$B:$B,Dict!$A$2) -> 48 | J10: =SUMIFS(Заклад!$E:$E,Заклад!$C:$C,$B10,Заклад!$A:$A,J$5,Заклад!$B:$B,Dict!$A$2) -> 186 | K10: =SUMIFS(Заклад!$E:$E,Заклад!$C:$C,$B10,Заклад!$A:$A,K$5,Заклад!$B:$B,Dict!$A$2) -> 0 | ... AL10: =SUMIFS(Заклад!$E:$E,Заклад!$C:$C,$B10,Заклад!$A:$A,AL$5,Заклад!$B:$B,Dict!$A$2) -> 0
B11: Волошин Надія Володимирівна | C11: =SUM(D11:M11) -> 1290 | D11: =SUMIFS(Заклад!$E:$E,Заклад!$C:$C,$B11,Заклад!$A:$A,D$5,Заклад!$B:$B,Dict!$A$2) -> 13 | E11: =SUMIFS(Заклад!$E:$E,Заклад!$C:$C,$B11,Заклад!$A:$A,E$5,Заклад!$B:$B,Dict!$A$2) -> 74 | F11: =SUMIFS(Заклад!$E:$E,Заклад!$C:$C,$B11,Заклад!$A:$A,F$5,Заклад!$B:$B,Dict!$A$2) -> 205 | G11: =SUMIFS(Заклад!$E:$E,Заклад!$C:$C,$B11,Заклад!$A:$A,G$5,Заклад!$B:$B,Dict!$A$2) -> 235 | H11: =SUMIFS(Заклад!$E:$E,Заклад!$C:$C,$B11,Заклад!$A:$A,H$5,Заклад!$B:$B,Dict!$A$2) -> 101 | I11: =SUMIFS(Заклад!$E:$E,Заклад!$C:$C,$B11,Заклад!$A:$A,I$5,Заклад!$B:$B,Dict!$A$2) -> 12 | J11: =SUMIFS(Заклад!$E:$E,Заклад!$C:$C,$B11,Заклад!$A:$A,J$5,Заклад!$B:$B,Dict!$A$2) -> 57 | K11: =SUMIFS(Заклад!$E:$E,Заклад!$C:$C,$B11,Заклад!$A:$A,K$5,Заклад!$B:$B,Dict!$A$2) -> 181 | ... AL11: =SUMIFS(Заклад!$E:$E,Заклад!$C:$C,$B11,Заклад!$A:$A,AL$5,Заклад!$B:$B,Dict!$A$2) -> 0
B12: Гадевич Наталія Зіновіївна | C12: =SUM(D12:M12) -> 1028 | D12: =SUMIFS(Заклад!$E:$E,Заклад!$C:$C,$B12,Заклад!$A:$A,D$5,Заклад!$B:$B,Dict!$A$2) -> 0 | E12: =SUMIFS(Заклад!$E:$E,Заклад!$C:$C,$B12,Заклад!$A:$A,E$5,Заклад!$B:$B,Dict!$A$2) -> 0 | F12: =SUMIFS(Заклад!$E:$E,Заклад!$C:$C,$B12,Заклад!$A:$A,F$5,Заклад!$B:$B,Dict!$A$2) -> 245 | G12: =SUMIFS(Заклад!$E:$E,Заклад!$C:$C,$B12,Заклад!$A:$A,G$5,Заклад!$B:$B,Dict!$A$2) -> 246 | H12: =SUMIFS(Заклад!$E:$E,Заклад!$C:$C,$B12,Заклад!$A:$A,H$5,Заклад!$B:$B,Dict!$A$2) -> 39 | I12: =SUMIFS(Заклад!$E:$E,Заклад!$C:$C,$B12,Заклад!$A:$A,I$5,Заклад!$B:$B,Dict!$A$2) -> 0 | J12: =SUMIFS(Заклад!$E:$E,Заклад!$C:$C,$B12,Заклад!$A:$A,J$5,Заклад!$B:$B,Dict!$A$2) -> 0 | K12: =SUMIFS(Заклад!$E:$E,Заклад!$C:$C,$B12,Заклад!$A:$A,K$5,Заклад!$B:$B,Dict!$A$2) -> 240 | ... AL12: =SUMIFS(Заклад!$E:$E,Заклад!$C:$C,$B12,Заклад!$A:$A,AL$5,Заклад!$B:$B,Dict!$A$2) -> 0
B13: Гонтар Марія Любомирівна | C13: =SUM(D13:M13) -> 0 | D13: =SUMIFS(Заклад!$E:$E,Заклад!$C:$C,$B13,Заклад!$A:$A,D$5,Заклад!$B:$B,Dict!$A$2) -> 0 | E13: =SUMIFS(Заклад!$E:$E,Заклад!$C:$C,$B13,Заклад!$A:$A,E$5,Заклад!$B:$B,Dict!$A$2) -> 0 | F13: =SUMIFS(Заклад!$E:$E,Заклад!$C:$C,$B13,Заклад!$A:$A,F$5,Заклад!$B:$B,Dict!$A$2) -> 0 | G13: =SUMIFS(Заклад!$E:$E,Заклад!$C:$C,$B13,Заклад!$A:$A,G$5,Заклад!$B:$B,Dict!$A$2) -> 0 | H13: =SUMIFS(Заклад!$E:$E,Заклад!$C:$C,$B13,Заклад!$A:$A,H$5,Заклад!$B:$B,Dict!$A$2) -> 0 | I13: =SUMIFS(Заклад!$E:$E,Заклад!$C:$C,$B13,Заклад!$A:$A,I$5,Заклад!$B:$B,Dict!$A$2) -> 0 | J13: =SUMIFS(Заклад!$E:$E,Заклад!$C:$C,$B13,Заклад!$A:$A,J$5,Заклад!$B:$B,Dict!$A$2) -> 0 | K13: =SUMIFS(Заклад!$E:$E,Заклад!$C:$C,$B13,Заклад!$A:$A,K$5,Заклад!$B:$B,Dict!$A$2) -> 0 | ... AL13: =SUMIFS(Заклад!$E:$E,Заклад!$C:$C,$B13,Заклад!$A:$A,AL$5,Заклад!$B:$B,Dict!$A$2) -> 0
B14: Горшинський Михайло Михайлович | C14: =SUM(D14:M14) -> 181 | D14: =SUMIFS(Заклад!$E:$E,Заклад!$C:$C,$B14,Заклад!$A:$A,D$5,Заклад!$B:$B,Dict!$A$2) -> 27 | E14: =SUMIFS(Заклад!$E:$E,Заклад!$C:$C,$B14,Заклад!$A:$A,E$5,Заклад!$B:$B,Dict!$A$2) -> 66 | F14: =SUMIFS(Заклад!$E:$E,Заклад!$C:$C,$B14,Заклад!$A:$A,F$5,Заклад!$B:$B,Dict!$A$2) -> 0 | G14: =SUMIFS(Заклад!$E:$E,Заклад!$C:$C,$B14,Заклад!$A:$A,G$5,Заклад!$B:$B,Dict!$A$2) -> 0 | H14: =SUMIFS(Заклад!$E:$E,Заклад!$C:$C,$B14,Заклад!$A:$A,H$5,Заклад!$B:$B,Dict!$A$2) -> 0 | I14: =SUMIFS(Заклад!$E:$E,Заклад!$C:$C,$B14,Заклад!$A:$A,I$5,Заклад!$B:$B,Dict!$A$2) -> 16 | J14: =SUMIFS(Заклад!$E:$E,Заклад!$C:$C,$B14,Заклад!$A:$A,J$5,Заклад!$B:$B,Dict!$A$2) -> 72 | K14: =SUMIFS(Заклад!$E:$E,Заклад!$C:$C,$B14,Заклад!$A:$A,K$5,Заклад!$B:$B,Dict!$A$2) -> 0 | ... AL14: =SUMIFS(Заклад!$E:$E,Заклад!$C:$C,$B14,Заклад!$A:$A,AL$5,Заклад!$B:$B,Dict!$A$2) -> 0
B15: Гунька Ірина Миколаївна | C15: =SUM(D15:M15) -> 0 | D15: =SUMIFS(Заклад!$E:$E,Заклад!$C:$C,$B15,Заклад!$A:$A,D$5,Заклад!$B:$B,Dict!$A$2) -> 0 | E15: =SUMIFS(Заклад!$E:$E,Заклад!$C:$C,$B15,Заклад!$A:$A,E$5,Заклад!$B:$B,Dict!$A$2) -> 0 | F15: =SUMIFS(Заклад!$E:$E,Заклад!$C:$C,$B15,Заклад!$A:$A,F$5,Заклад!$B:$B,Dict!$A$2) -> 0 | G15: =SUMIFS(Заклад!$E:$E,Заклад!$C:$C,$B15,Заклад!$A:$A,G$5,Заклад!$B:$B,Dict!$A$2) -> 0 | H15: =SUMIFS(Заклад!$E:$E,Заклад!$C:$C,$B15,Заклад!$A:$A,H$5,Заклад!$B:$B,Dict!$A$2) -> 0 | I15: =SUMIFS(Заклад!$E:$E,Заклад!$C:$C,$B15,Заклад!$A:$A,I$5,Заклад!$B:$B,Dict!$A$2) -> 0 | J15: =SUMIFS(Заклад!$E:$E,Заклад!$C:$C,$B15,Заклад!$A:$A,J$5,Заклад!$B:$B,Dict!$A$2) -> 0 | K15: =SUMIFS(Заклад!$E:$E,Заклад!$C:$C,$B15,Заклад!$A:$A,K$5,Заклад!$B:$B,Dict!$A$2) -> 0 | ... AL15: =SUMIFS(Заклад!$E:$E,Заклад!$C:$C,$B15,Заклад!$A:$A,AL$5,Заклад!$B:$B,Dict!$A$2) -> 0
B16: Денисюк Наталія Олексіївна | C16: =SUM(D16:M16) -> 1703 | D16: =SUMIFS(Заклад!$E:$E,Заклад!$C:$C,$B16,Заклад!$A:$A,D$5,Заклад!$B:$B,Dict!$A$2) -> 1 | E16: =SUMIFS(Заклад!$E:$E,Заклад!$C:$C,$B16,Заклад!$A:$A,E$5,Заклад!$B:$B,Dict!$A$2) -> 9 | F16: =SUMIFS(Заклад!$E:$E,Заклад!$C:$C,$B16,Заклад!$A:$A,F$5,Заклад!$B:$B,Dict!$A$2) -> 366 | G16: =SUMIFS(Заклад!$E:$E,Заклад!$C:$C,$B16,Заклад!$A:$A,G$5,Заклад!$B:$B,Dict!$A$2) -> 388 | H16: =SUMIFS(Заклад!$E:$E,Заклад!$C:$C,$B16,Заклад!$A:$A,H$5,Заклад!$B:$B,Dict!$A$2) -> 95 | I16: =SUMIFS(Заклад!$E:$E,Заклад!$C:$C,$B16,Заклад!$A:$A,I$5,Заклад!$B:$B,Dict!$A$2) -> 0 | J16: =SUMIFS(Заклад!$E:$E,Заклад!$C:$C,$B16,Заклад!$A:$A,J$5,Заклад!$B:$B,Dict!$A$2) -> 8 | K16: =SUMIFS(Заклад!$E:$E,Заклад!$C:$C,$B16,Заклад!$A:$A,K$5,Заклад!$B:$B,Dict!$A$2) -> 292 | ... AL16: =SUMIFS(Заклад!$E:$E,Заклад!$C:$C,$B16,Заклад!$A:$A,AL$5,Заклад!$B:$B,Dict!$A$2) -> 0
B17: Дика Любов Степанівна | C17: =SUM(D17:M17) -> 1116 | D17: =SUMIFS(Заклад!$E:$E,Заклад!$C:$C,$B17,Заклад!$A:$A,D$5,Заклад!$B:$B,Dict!$A$2) -> 0 | E17: =SUMIFS(Заклад!$E:$E,Заклад!$C:$C,$B17,Заклад!$A:$A,E$5,Заклад!$B:$B,Dict!$A$2) -> 1 | F17: =SUMIFS(Заклад!$E:$E,Заклад!$C:$C,$B17,Заклад!$A:$A,F$5,Заклад!$B:$B,Dict!$A$2) -> 167 | G17: =SUMIFS(Заклад!$E:$E,Заклад!$C:$C,$B17,Заклад!$A:$A,G$5,Заклад!$B:$B,Dict!$A$2) -> 232 | H17: =SUMIFS(Заклад!$E:$E,Заклад!$C:$C,$B17,Заклад!$A:$A,H$5,Заклад!$B:$B,Dict!$A$2) -> 104 | I17: =SUMIFS(Заклад!$E:$E,Заклад!$C:$C,$B17,Заклад!$A:$A,I$5,Заклад!$B:$B,Dict!$A$2) -> 0 | J17: =SUMIFS(Заклад!$E:$E,Заклад!$C:$C,$B17,Заклад!$A:$A,J$5,Заклад!$B:$B,Dict!$A$2) -> 4 | K17: =SUMIFS(Заклад!$E:$E,Заклад!$C:$C,$B17,Заклад!$A:$A,K$5,Заклад!$B:$B,Dict!$A$2) -> 146 | ... AL17: =SUMIFS(Заклад!$E:$E,Заклад!$C:$C,$B17,Заклад!$A:$A,AL$5,Заклад!$B:$B,Dict!$A$2) -> 0
B18: Дуда Оксана Теодорівна | C18: =SUM(D18:M18) -> 1669 | D18: =SUMIFS(Заклад!$E:$E,Заклад!$C:$C,$B18,Заклад!$A:$A,D$5,Заклад!$B:$B,Dict!$A$2) -> 0 | E18: =SUMIFS(Заклад!$E:$E,Заклад!$C:$C,$B18,Заклад!$A:$A,E$5,Заклад!$B:$B,Dict!$A$2) -> 1 | F18: =SUMIFS(Заклад!$E:$E,Заклад!$C:$C,$B18,Заклад!$A:$A,F$5,Заклад!$B:$B,Dict!$A$2) -> 216 | G18: =SUMIFS(Заклад!$E:$E,Заклад!$C:$C,$B18,Заклад!$A:$A,G$5,Заклад!$B:$B,Dict!$A$2) -> 324 | H18: =SUMIFS(Заклад!$E:$E,Заклад!$C:$C,$B18,Заклад!$A:$A,H$5,Заклад!$B:$B,Dict!$A$2) -> 165 | I18: =SUMIFS(Заклад!$E:$E,Заклад!$C:$C,$B18,Заклад!$A:$A,I$5,Заклад!$B:$B,Dict!$A$2) -> 0 | J18: =SUMIFS(Заклад!$E:$E,Заклад!$C:$C,$B18,Заклад!$A:$A,J$5,Заклад!$B:$B,Dict!$A$2) -> 0 | K18: =SUMIFS(Заклад!$E:$E,Заклад!$C:$C,$B18,Заклад!$A:$A,K$5,Заклад!$B:$B,Dict!$A$2) -> 185 | ... AL18: =SUMIFS(Заклад!$E:$E,Заклад!$C:$C,$B18,Заклад!$A:$A,AL$5,Заклад!$B:$B,Dict!$A$2) -> 0
... B53: Ядушинський Ярослав Йосифович | C53: =SUM(D53:M53) -> 1285 | D53: =SUMIFS(Заклад!$E:$E,Заклад!$C:$C,$B53,Заклад!$A:$A,D$5,Заклад!$B:$B,Dict!$A$2) -> 7 | E53: =SUMIFS(Заклад!$E:$E,Заклад!$C:$C,$B53,Заклад!$A:$A,E$5,Заклад!$B:$B,Dict!$A$2) -> 74 | F53: =SUMIFS(Заклад!$E:$E,Заклад!$C:$C,$B53,Заклад!$A:$A,F$5,Заклад!$B:$B,Dict!$A$2) -> 202 | G53: =SUMIFS(Заклад!$E:$E,Заклад!$C:$C,$B53,Заклад!$A:$A,G$5,Заклад!$B:$B,Dict!$A$2) -> 224 | H53: =SUMIFS(Заклад!$E:$E,Заклад!$C:$C,$B53,Заклад!$A:$A,H$5,Заклад!$B:$B,Dict!$A$2) -> 98 | I53: =SUMIFS(Заклад!$E:$E,Заклад!$C:$C,$B53,Заклад!$A:$A,I$5,Заклад!$B:$B,Dict!$A$2) -> 6 | J53: =SUMIFS(Заклад!$E:$E,Заклад!$C:$C,$B53,Заклад!$A:$A,J$5,Заклад!$B:$B,Dict!$A$2) -> 63 | K53: =SUMIFS(Заклад!$E:$E,Заклад!$C:$C,$B53,Заклад!$A:$A,K$5,Заклад!$B:$B,Dict!$A$2) -> 172 | ... AL53: =SUMIFS(Заклад!$E:$E,Заклад!$C:$C,$B53,Заклад!$A:$A,AL$5,Заклад!$B:$B,Dict!$A$2) -> 0

Sheet Порівняння за закладами
A1: ="Аналітичний звіт про роботу надавачів ПМД в межах області станом на "&TEXT(Dict!A2,"dd.mm.yyyy") -> Аналітичний звіт про роботу надавачів ПМД в межах області станом на 01.08.2024
B2: =Dict!C2 -> 01996272, КОМУНАЛЬНЕ НЕКОМЕРЦІЙНЕ ПІДПРИЄМСТВО "ЗОЛОЧІВСЬКА ЦЕНТРАЛЬНА РАЙОННА ЛІКАРНЯ" ЗОЛОЧІВСЬКОЇ МІСЬКОЇ РАДИ ЗОЛОЧІВСЬКОГО РАЙОНУ ЛЬВІВСЬКОЇ ОБЛАСТІ
V4: 1 | Y4: 2 | AB4: 3 | AE4: 4 | AH4: 5 | AK4: 6 | AN4: 7 | AQ4: 8 | AT4: 9 | AW4: 10 | AZ4: 11 | BC4: 12 | BF4: 13 | BI4: 14 | BL4: 15 | BO4: 16 | BR4: 17 | BU4: 18 | BX4: 20 | CA4: 23 | CD4: 24 | CG4: 25 | CJ4: 26 | CM4: 27
V5: =VLOOKUP(V4,Індикатори!$A:$B,2,0) -> Співвідношення кількості медсестер до кількості лікарів на ПМД. | Y5: =VLOOKUP(Y4,Індикатори!$A:$B,2,0) -> Відсоток задекларованих пацієнтів у порівнянні з рекомендованою кількістю. | AB5: =VLOOKUP(AB4,Індикатори!$A:$B,2,0) -> Загальне використання послуг ПМД. | AE5: =VLOOKUP(AE4,Індикатори!$A:$B,2,0) -> Частка консультацій з лікарями ПМД без перескерувань. | AH5: =VLOOKUP(AH4,Індикатори!$A:$B,2,0) -> Завантаженість лікаря, який надає послуги ПМД. | AK5: =VLOOKUP(AK4,Індикатори!$A:$B,2,0) -> Моніторинг розвитку дитини протягом першого року життя. | AN5: =VLOOKUP(AN4,Індикатори!$A:$B,2,0) -> Вакцинація дітей віком до 1 року (включно). | AQ5: =VLOOKUP(AQ4,Індикатори!$A:$B,2,0) -> Вакцинація дітей віком до 6 років (включно). | AT5: =VLOOKUP(AT4,Індикатори!$A:$B,2,0) -> Повне оцінювання серцево-судинного ризику. | AW5: =VLOOKUP(AW4,Індикатори!$A:$B,2,0) -> Оцінювання компенсації гіпертонії. | AZ5: =VLOOKUP(AZ4,Індикатори!$A:$B,2,0) -> Скринінг на виявлення цукрового діабету у групі ризику. | BC5: =VLOOKUP(BC4,Індикатори!$A:$B,2,0) -> Скринінг на виявлення раку передміхурової залози (виписані направлення). | BF5: =VLOOKUP(BF4,Індикатори!$A:$B,2,0) -> Скринінг на виявлення раку передміхурової залози (погашені направлення). | BI5: =VLOOKUP(BI4,Індикатори!$A:$B,2,0) -> Скринінг на виявлення колоректального раку (виписані направлення). | BL5: =VLOOKUP(BL4,Індикатори!$A:$B,2,0) -> Скринінг на виявлення колоректального раку (погашені направлення). | BO5: =VLOOKUP(BO4,Індикатори!$A:$B,2,0) -> Скринінг на виявлення раку молочної залози серед жінок (виписані направлення). | BR5: =VLOOKUP(BR4,Індикатори!$A:$B,2,0) -> Скринінг на виявлення раку молочної залози серед жінок (погашені направлення). | BU5: =VLOOKUP(BU4,Індикатори!$A:$B,2,0) -> Скринінг на наявність туберкульозу. | BX5: =VLOOKUP(BX4,Індикатори!$A:$B,2,0) -> Виявлення ВІЛ у пацієнтів з індикаторними станами. | CA5: =VLOOKUP(CA4,Індикатори!$A:$B,2,0) -> Охоплення реімбурсацією (виписування рецептів). | CD5: =VLOOKUP(CD4,Індикатори!$A:$B,2,0) -> Охоплення реімбурсацією (отоварення рецептів). | CG5: =VLOOKUP(CG4,Індикатори!$A:$B,2,0) -> Виписування антимікробних препаратів на рівні ПМД. | CJ5: =VLOOKUP(CJ4,Індикатори!$A:$B,2,0) -> Профілактичний огляд осіб вікової групи 40-64 роки | CM5: =VLOOKUP(CM4,Індикатори!$A:$B,2,0) -> Профілактичний огляд осіб вікової групи 65 років і старше
V6: Заклад | W6: Значення індикатору | X6: =Dict!B2 -> 01996272 | Y6: Заклад | Z6: Значення індикатору | AA6: =Dict!B2 -> 01996272 | AB6: Заклад | AC6: Значення індикатору | AD6: =Dict!B2 -> 01996272 | AE6: Заклад | AF6: Значення індикатору | AG6: =Dict!B2 -> 01996272 | AH6: Заклад | AI6: Значення індикатору | AJ6: =Dict!B2 -> 01996272 | AK6: Заклад | AL6: Значення індикатору | AM6: =Dict!B2 -> 01996272 | AN6: Заклад | AO6: Значення індикатору | AP6: =Dict!B2 -> 01996272 | AQ6: Заклад | AR6: Значення індикатору | AS6: =Dict!B2 -> 01996272 | AT6: Заклад | AU6: Значення індикатору | AV6: =Dict!B2 -> 01996272 | AW6: Заклад | AX6: Значення індикатору | AY6: =Dict!B2 -> 01996272 | AZ6: Заклад | BA6: Значення індикатору | BB6: =Dict!B2 -> 01996272 | BC6: Заклад | BD6: Значення індикатору | BE6: =Dict!B2 -> 01996272 | BF6: Заклад | BG6: Значення індикатору | BH6: =Dict!B2 -> 01996272 | BI6: Заклад | BJ6: Значення індикатору | BK6: =Dict!B2 -> 01996272 | BL6: Заклад | BM6: Значення індикатору | BN6: =Dict!B2 -> 01996272 | BO6: Заклад | BP6: Значення індикатору | BQ6: =Dict!B2 -> 01996272 | BR6: Заклад | BS6: Значення індикатору | BT6: =Dict!B2 -> 01996272 | BU6: Заклад | BV6: Значення індикатору | BW6: =Dict!B2 -> 01996272 | BX6: Заклад | BY6: Значення індикатору | BZ6: =Dict!B2 -> 01996272 | CA6: Заклад | CB6: Значення індикатору | CC6: =Dict!B2 -> 01996272 | CD6: Заклад | CE6: Значення індикатору | CF6: =Dict!B2 -> 01996272 | CG6: Заклад | CH6: Значення індикатору | CI6: =Dict!B2 -> 01996272 | CJ6: Заклад | CK6: Значення індикатору | CL6: =Dict!B2 -> 01996272 | CM6: Заклад | CN6: Значення індикатору | CO6: =Dict!B2 -> 01996272
V7: ФОП, Рудько Ольга Олександрівна | W7: 0 | X7: -1 | Y7: 38208497 | Z7: 0.0083333333 | AA7: -1 | AB7: ФОП, Рудько Ольга Олександрівна | AC7: 0.025179856 | AD7: -1 | AE7: ФОП, Жук Олег Євгенович | AF7: 0.29230769 | AG7: -1 | AH7: 38208497 | AI7: 1 | AJ7: -1 | AK7: ФОП, Лялька Наталія Петрівна | AL7: 0 | AM7: -1 | AN7: ФОП, Жук Олег Євгенович | AO7: 0.0060790274 | AP7: -1 | AQ7: ФОП, Жук Олег Євгенович | AR7: 0.0035671819 | AS7: -1 | AT7: 45094345 | AU7: 0.00020439448 | AV7: -1 | AW7: 22398210 | AX7: 0.00096571704 | AY7: -1 | AZ7: 44119976 | BA7: 0.00055218112 | BB7: -1 | BC7: 42108962 | BD7: 0.00070871722 | BE7: -1 | BF7: 44925460 | BG7: 0 | BH7: -1 | BI7: 41900490 | BJ7: 9.084715e-05 | BK7: -1 | BL7: ФОП, Лялька Наталія Петрівна | BM7: 0 | BN7: -1 | BO7: 42310851 | BP7: 0.002004008 | BQ7: -1 | BR7: 44925460 | BS7: 0 | BT7: -1 | BU7: 20764314 | BV7: 0.00038417211 | BW7: -1 | BX7: 20851349 | BY7: 0.0091743119 | BZ7: -1 | CA7: ФОП, КРАВЧЕНКО РОМАНА БОГДАНІВНА | CB7: 0.00042918455 | CC7: -1 | CD7: 44114246 | CE7: 0.5 | CF7: -1 | CG7: 42224043 | CH7: 2.637896e-05 | CI7: -1 | CJ7: 41900490 | CK7: 5.1773233e-05 | CL7: -1 | CM7: 01996272 | CN7: 0.00097713504 | CO7: 0.00097713504
V8: 37398906 | W8: 0 | X8: -1 | Y8: 42830922 | Z8: 0.022631579 | AA8: -1 | AB8: 22421239 | AC8: 0.038599701 | AD8: -1 | AE8: ФОП, КОШЛАТА ЛЕСЯ ВАСИЛІВНА | AF8: 0.375 | AG8: -1 | AH8: 42830922 | AI8: 1 | AJ8: -1 | AK8: ФОП, ДІДИК ЛЕСЯ ІВАНІВНА | AL8: 0 | AM8: -1 | AN8: 34327104 | AO8: 0.014492754 | AP8: -1 | AQ8: 34327104 | AR8: 0.0080645161 | AS8: -1 | AT8: 44635101 | AU8: 0.00050787202 | AV8: -1 | AW8: 36761597 | AX8: 0.0017699115 | AY8: -1 | AZ8: 22398210 | BA8: 0.00058186896 | BB8: -1 | BC8: 42310851 | BD8: 0.00095192765 | BE8: -1 | BF8: ФОП, ЗУБРИЦЬКА НАДІЯ СТЕПАНІВНА | BG8: 0 | BH8: -1 | BI8: 20763591 | BJ8: 0.0003136107 | BK8: -1 | BL8: 41900490 | BM8: 0 | BN8: -1 | BO8: ФОП, ДІДИК ЛЕСЯ ІВАНІВНА | BP8: 0.0024213075 | BQ8: -1 | BR8: ФОП, ПОШИВАК ТЕТЯНА ПЕТРІВНА | BS8: 0 | BT8: -1 | BU8: 44712882 | BV8: 0.00040584416 | BW8: -1 | BX8: 40626575 | BY8: 0.010416667 | BZ8: -1 | CA8: ФОП, ГОЙ ОЛЬГА ІВАНІВНА | CB8: 0.00090130689 | CC8: -1 | CD8: ФОП, ЛОМАЄВА ОЛЕКСАНДРА ВАЛЕРІЇВНА | CE8: 0.5 | CF8: -1 | CG8: 45065089 | CH8: 3.0395137e-05 | CI8: -1 | CJ8: 01997633 | CK8: 0.00017857143 | CL8: -1 | CM8: 41160010 | CN8: 0.004074357 | CO8: -1
V9: ФОП, ЗАСТАВНИЙ ІГОР ІГОРОВИЧ | W9: 0 | X9: -1 | Y9: 42138054 | Z9: 0.03893617 | AA9: -1 | AB9: ФОП, СУХОВЕРСЬКИЙ МИРОСЛАВ МИРОНОВИЧ | AC9: 0.053521127 | AD9: -1 | AE9: ФОП, БУНЬКО ВАСИЛЬ МИХАЙЛОВИЧ | AF9: 0.52777778 | AG9: -1 | AH9: ФОП, РОНДЯК БОГДАН ЯРОСЛАВОВИЧ | AI9: 1 | AJ9: -1 | AK9: ФОП, ГОРАЛЬЧУК ОКСАНА МИКОЛАЇВНА | AL9: 0 | AM9: -1 | AN9: 38763426 | AO9: 0.024390244 | AP9: -1 | AQ9: 43923200 | AR9: 0.029017857 | AS9: -1 | AT9: 20765006 | AU9: 0.00097592713 | AV9: -1 | AW9: 20763272 | AX9: 0.0018850141 | AY9: -1 | AZ9: 45094345 | BA9: 0.0012576356 | BB9: -1 | BC9: 20764716 | BD9: 0.00098619329 | BE9: -1 | BF9: ФОП, ЗАСТАВНИЙ ІГОР ІГОРОВИЧ | BG9: 0 | BH9: -1 | BI9: 22398210 | BJ9: 0.00034634034 | BK9: -1 | BL9: ФОП, МАХНО ГАЛИНА ВОЛОДИМИРІВНА | BM9: 0 | BN9: -1 | BO9: 40393866 | BP9: 0.002739726 | BQ9: -1 | BR9: ФОП, ЗУБРИЦЬКА НАДІЯ СТЕПАНІВНА | BS9: 0 | BT9: -1 | BU9: 01996272 | BV9: 0.00041034058 | BW9: 0.00041034058 | BX9: 20761149 | BY9: 0.011673152 | BZ9: -1 | CA9: 43938699 | CB9: 0.0010845987 | CC9: -1 | CD9: ФОП, КРАВЧЕНКО РОМАНА БОГДАНІВНА | CE9: 0.5 | CF9: -1 | CG9: 44925460 | CH9: 4.9096622e-05 | CI9: -1 | CJ9: 42428764 | CK9: 0.00028735632 | CL9: -1 | CM9: 40236036 | CN9: 0.0080645161 | CO9: -1
V10: ФОП, ОЩИПКО ІРИНА ГЕОРГІЇВНА | W10: 0 | X10: -1 | Y10: ФОП, МИСНИК ЛЮДМИЛА ІЛЛІВНА | Z10: 0.0545 | AA10: -1 | AB10: 44925460 | AC10: 0.086091189 | AD10: -1 | AE10: 01997297 | AF10: 0.54285714 | AG10: -1 | AH10: ФОП, ЛОМАЄВА ОЛЕКСАНДРА ВАЛЕРІЇВНА | AI10: 1.375 | AJ10: -1 | AK10: 44976028 | AL10: 0 | AM10: -1 | AN10: 43923200 | AO10: 0.035714286 | AP10: -1 | AQ10: 38763426 | AR10: 0.029411765 | AS10: -1 | AT10: 41180990 | AU10: 0.0010471204 | AV10: -1 | AW10: 41900490 | AX10: 0.0021851953 | AY10: -1 | AZ10: 41209595 | BA10: 0.0020533881 | BB10: -1 | BC10: 20764478 | BD10: 0.001010101 | BE10: -1 | BF10: ФОП, Добрянський Олесь Степанович | BG10: 0 | BH10: -1 | BI10: 36761597 | BJ10: 0.00043365134 | BK10: -1 | BL10: ФОП, ЗУБРИЦЬКА НАДІЯ СТЕПАНІВНА | BM10: 0 | BN10: -1 | BO10: 43871190 | BP10: 0.0055478502 | BQ10: -1 | BR10: ФОП, ЗАСТАВНИЙ ІГОР ІГОРОВИЧ | BS10: 0 | BT10: -1 | BU10: 23957835 | BV10: 0.0005574136 | BW10: -1 | BX10: 23970286 | BY10: 0.012131716 | BZ10: -1 | CA10: 01997679 | CB10: 0.0014484357 | CC10: -1 | CD10: 44848931 | CE10: 0.6 | CF10: -1 | CG10: 20765006 | CH10: 6.0971892e-05 | CI10: -1 | CJ10: 20763272 | CK10: 0.00030376671 | CL10: -1 | CM10: 45065089 | CN10: 0.0082214305 | CO10: -1
V11: 44114246 | W11: 0 | X11: -1 | Y11: ФОП, Добрянський Олесь Степанович | Z11: 0.056842105 | AA11: -1 | AB11: 44625774 | AC11: 0.14758402 | AD11: -1 | AE11: 43260585 | AF11: 0.55128205 | AG11: -1 | AH11: ФОП, МИСНИК ЛЮДМИЛА ІЛЛІВНА | AI11: 1.4545455 | AJ11: -1 | AK11: 22348948 | AL11: 0 | AM11: -1 | AN11: 43288396 | AO11: 0.066666667 | AP11: -1 | AQ11: ФОП, БЕРЕЗНЮК ТЕТЯНА ПАВЛІВНА | AR11: 0.03 | AS11: -1 | AT11: ФОП, МАРУНКЕВИЧ МАРІЯ ВОЛОДИМИРІВНА | AU11: 0.0010793308 | AV11: -1 | AW11: ФОП, НІКОНОРОВ ВАЛЕРІЙ МИКОЛАЙОВИЧ | AX11: 0.0032051282 | AY11: -1 | AZ11: 20765006 | BA11: 0.003987802 | BB11: -1 | BC11: 01998226 | BD11: 0.0012306178 | BE11: -1 | BF11: ФОП, ШКУЛЬСЬКИЙ ВОЛОДИМИР ВОЛОДИМИРОВИЧ | BG11: 0 | BH11: -1 | BI11: 20765006 | BJ11: 0.00046051117 | BK11: -1 | BL11: 38763426 | BM11: 0 | BN11: -1 | BO11: ФОП, ПОШИВАК ТЕТЯНА ПЕТРІВНА | BP11: 0.0055555556 | BQ11: -1 | BR11: 44114246 | BS11: 0 | BT11: -1 | BU11: 44625774 | BV11: 0.0006942034 | BW11: -1 | BX11: 44625774 | BY11: 0.023076923 | BZ11: -1 | CA11: ФОП, Кольченко Леся Михайлівна | CB11: 0.0015302219 | CC11: -1 | CD11: 41066560 | CE11: 0.60869565 | CF11: -1 | CG11: 43526560 | CH11: 6.7317402e-05 | CI11: -1 | CJ11: 01997248 | CK11: 0.00052471403 | CL11: -1 | CM11: 01998226 | CN11: 0.0096483038 | CO11: -1
V12: ФОП, Добрянський Олесь Степанович | W12: 0 | X12: -1 | Y12: ФОП, БАЛЛА РОКСОЛАНА АНДРІЇВНА | Z12: 0.070357143 | AA12: -1 | AB12: 34327104 | AC12: 0.18341709 | AD12: -1 | AE12: ФОП, ДЮК ОКСАНА ЯРОСЛАВІВНА | AF12: 0.56214689 | AG12: -1 | AH12: 37398906 | AI12: 1.5 | AJ12: -1 | AK12: ФОП, КРАВЧУК ГАЛИНА ВАСИЛІВНА | AL12: 0 | AM12: -1 | AN12: 20850964 | AO12: 0.090909091 | AP12: -1 | AQ12: 20850964 | AR12: 0.049180328 | AS12: -1 | AT12: 42769586 | AU12: 0.0012106538 | AV12: -1 | AW12: 01997248 | AX12: 0.0038009675 | AY12: -1 | AZ12: ФОП, ПІКУЛИЦЬКА ЯРИНА ВАСИЛІВНА | BA12: 0.0042918455 | BB12: -1 | BC12: 20763295 | BD12: 0.0016666667 | BE12: -1 | BF12: 20763295 | BG12: 0 | BH12: -1 | BI12: 42448068 | BJ12: 0.00055648303 | BK12: -1 | BL12: 36417058 | BM12: 0 | BN12: -1 | BO12: 20765006 | BP12: 0.0062620424 | BQ12: -1 | BR12: ФОП, Добрянський Олесь Степанович | BS12: 0 | BT12: -1 | BU12: 01996674 | BV12: 0.00079491256 | BW12: -1 | BX12: 01996674 | BY12: 0.028688525 | BZ12: -1 | CA12: ФОП, БУНЬКО ВАСИЛЬ МИХАЙЛОВИЧ | CB12: 0.0022026432 | CC12: -1 | CD12: ФОП, ОЩИПКО ІРИНА ГЕОРГІЇВНА | CE12: 0.66666667 | CF12: -1 | CG12: 22398210 | CH12: 7.7543424e-05 | CI12: -1 | CJ12: 42021164 | CK12: 0.00076026356 | CL12: -1 | CM12: 41136480 | CN12: 0.0099778271 | CO12: -1
V13: 01997297 | W13: 0 | X13: -1 | Y13: ФОП, ЛОМАЄВА ОЛЕКСАНДРА ВАЛЕРІЇВНА | Z13: 0.075 | AA13: -1 | AB13: 45094345 | AC13: 0.20840513 | AD13: -1 | AE13: ФОП, КРАВЧУК ГАЛИНА ВАСИЛІВНА | AF13: 0.58156028 | AG13: -1 | AH13: ФОП, СУХОВЕРСЬКИЙ МИРОСЛАВ МИРОНОВИЧ | AI13: 1.5416667 | AJ13: -1 | AK13: 41066560 | AL13: 0 | AM13: -1 | AN13: ФОП, БЕРЕЗНЮК ТЕТЯНА ПАВЛІВНА | AO13: 0.11111111 | AP13: -1 | AQ13: ФОП, Лялька Наталія Петрівна | AR13: 0.055555556 | AS13: -1 | AT13: 22398210 | AU13: 0.0018301401 | AV13: -1 | AW13: 01998226 | AX13: 0.0038650738 | AY13: -1 | AZ13: 42769586 | BA13: 0.0057471264 | BB13: -1 | BC13: 41894875 | BD13: 0.0018484288 | BE13: -1 | BF13: ФОП, КАРАКЕВИЧ ЮРІЙ МИХАЙЛОВИЧ | BG13: 0 | BH13: -1 | BI13: 45094345 | BJ13: 0.0006021678 | BK13: -1 | BL13: 44028360 | BM13: 0 | BN13: -1 | BO13: ФОП, КАРАКЕВИЧ ЮРІЙ МИХАЙЛОВИЧ | BP13: 0.0076335878 | BQ13: -1 | BR13: 44848931 | BS13: 0 | BT13: -1 | BU13: 23970286 | BV13: 0.00090103619 | BW13: -1 | BX13: 42448068 | BY13: 0.030769231 | BZ13: -1 | CA13: ФОП, РОНДЯК БОГДАН ЯРОСЛАВОВИЧ | CB13: 0.0022779043 | CC13: -1 | CD13: ФОП, Турянська Ольга Тарасівна | CE13: 0.66666667 | CF13: -1 | CG13: 41136480 | CH13: 8.4381065e-05 | CI13: -1 | CJ13: 37639909 | CK13: 0.001242236 | CL13: -1 | CM13: 40626575 | CN13: 0.010214168 | CO13: -1
V14: ФОП, ГОРАЛЬЧУК ОКСАНА МИКОЛАЇВНА | W14: 0 | X14: -1 | Y14: ФОП, Турянська Ольга Тарасівна | Z14: 0.080833333 | AA14: -1 | AB14: 40236036 | AC14: 0.21042002 | AD14: -1 | AE14: ФОП, Жданова Оксана Степанівна | AF14: 0.58333333 | AG14: -1 | AH14: 44871599 | AI14: 1.7076923 | AJ14: -1 | AK14: ФОП, ГРИЦАК РУСЛАН ГЕННАДІЙОВИЧ | AL14: 0 | AM14: -1 | AN14: 44925460 | AO14: 0.1328125 | AP14: -1 | AQ14: ФОП, КОТОВИЧ НАТАЛІЯ СТЕПАНІВНА | AR14: 0.063348416 | AS14: -1 | AT14: ФОП, Мазур Руслана Ярославівна | AU14: 0.0019367334 | AV14: -1 | AW14: 01998101 | AX14: 0.0039615167 | AY14: -1 | AZ14: ФОП, КРАВЧУК ГАЛИНА ВАСИЛІВНА | BA14: 0.0064102564 | BB14: -1 | BC14: 01997248 | BD14: 0.0018663047 | BE14: -1 | BF14: 44848931 | BG14: 0 | BH14: -1 | BI14: 44216151 | BJ14: 0.00070646415 | BK14: -1 | BL14: ФОП, ЗАСТАВНИЙ ІГОР ІГОРОВИЧ | BM14: 0 | BN14: -1 | BO14: 36194399 | BP14: 0.0079051383 | BQ14: -1 | BR14: ФОП, Карпяк Марта Ігорівна | BS14: 0 | BT14: -1 | BU14: 20851349 | BV14: 0.0012180268 | BW14: -1 | BX14: 01984228 | BY14: 0.032258065 | BZ14: -1 | CA14: ФОП, АПАРІНА ЛІДІЯ ВОЛОДИМИРІВНА | CB14: 0.0025773196 | CC14: -1 | CD14: 01996869 | CE14: 0.66666667 | CF14: -1 | CG14: 36761597 | CH14: 9.6181591e-05 | CI14: -1 | CJ14: ФОП, РОНДЯК ОЛЕКСАНДРА ЗІНОВІЇВНА | CK14: 0.0014771049 | CL14: -1 | CM14: 01996409 | CN14: 0.014912281 | CO14: -1
V15: ФОП, ПОКІНСЬКА МАРІЯ МИХАЙЛІВНА | W15: 0 | X15: -1 | Y15: 44871599 | Z15: 0.081034483 | AA15: -1 | AB15: 41845440 | AC15: 0.21978165 | AD15: -1 | AE15: ФОП, КАРАКЕВИЧ ЮРІЙ МИХАЙЛОВИЧ | AF15: 0.60493827 | AG15: -1 | AH15: 44114246 | AI15: 1.75 | AJ15: -1 | AK15: ФОП, БЕРЕЗНЮК ТЕТЯНА ПАВЛІВНА | AL15: 0 | AM15: -1 | AN15: ФОП, ГРИЦАК РУСЛАН ГЕННАДІЙОВИЧ | AO15: 0.16666667 | AP15: -1 | AQ15: ФОП, ШКУЛЬСЬКИЙ ВОЛОДИМИР ВОЛОДИМИРОВИЧ | AR15: 0.066666667 | AS15: -1 | AT15: ФОП, КАБАН ВОЛОДИМИР БОГДАНОВИЧ | AU15: 0.0030410542 | AV15: -1 | AW15: ФОП, ДІДИК ЛЕСЯ ІВАНІВНА | AX15: 0.0041152263 | AY15: -1 | AZ15: ФОП, СКОБИЛКО ІРИНА ВОЛОДИМИРІВНА | BA15: 0.0069444444 | BB15: -1 | BC15: 44397639 | BD15: 0.0019480519 | BE15: -1 | BF15: 44646459 | BG15: 0 | BH15: -1 | BI15: 41851009 | BJ15: 0.00084530854 | BK15: -1 | BL15: 44114246 | BM15: 0 | BN15: -1 | BO15: 42750109 | BP15: 0.0091033227 | BQ15: -1 | BR15: 01998035 | BS15: 0 | BT15: -1 | BU15: 41845440 | BV15: 0.0017035775 | BW15: -1 | BX15: 23957835 | BY15: 0.046218487 | BZ15: -1 | CA15: ФОП, СУХОВЕРСЬКИЙ МИРОСЛАВ МИРОНОВИЧ | CB15: 0.0027497709 | CC15: -1 | CD15: 43260585 | CE15: 0.70588235 | CF15: -1 | CG15: 01997633 | CH15: 0.00011644607 | CI15: -1 | CJ15: 43914746 | CK15: 0.0015860428 | CL15: -1 | CM15: 44093644 | CN15: 0.018726592 | CO15: -1
V16: 44976028 | W16: 0 | X16: -1 | Y16: ФОП, КОЗЕНКО ПАВЛО ВОЛОДИМИРОВИЧ | Z16: 0.083 | AA16: -1 | AB16: 45214923 | AC16: 0.22281523 | AD16: -1 | AE16: ФОП, ВОРОБЕЦЬ ІРИНА ЙОСИФІВНА | AF16: 0.60655738 | AG16: -1 | AH16: 39792683 | AI16: 1.7619048 | AJ16: -1 | AK16: ФОП, ДУДА НАДІЯ БОГДАНІВНА | AL16: 0 | AM16: -1 | AN16: ФОП, КОТОВИЧ НАТАЛІЯ СТЕПАНІВНА | AO16: 0.18181818 | AP16: -1 | AQ16: ФОП, КОШЛАТА ЛЕСЯ ВАСИЛІВНА | AR16: 0.06870229 | AS16: -1 | AT16: ФОП, КРАВЧУК ГАЛИНА ВАСИЛІВНА | AU16: 0.0037664783 | AV16: -1 | AW16: 20764716 | AX16: 0.0045146727 | AY16: -1 | AZ16: 41180990 | BA16: 0.01214128 | BB16: -1 | BC16: 22398210 | BD16: 0.0019502682 | BE16: -1 | BF16: 32613493 | BG16: 0 | BH16: -1 | BI16: 42310851 | BJ16: 0.00092229652 | BK16: -1 | BL16: 20763272 | BM16: 0 | BN16: -1 | BO16: 01996869 | BP16: 0.010204082 | BQ16: -1 | BR16: ФОП, ЛОМАЄВА ОЛЕКСАНДРА ВАЛЕРІЇВНА | BS16: 0 | BT16: -1 | BU16: 20761149 | BV16: 0.0017694641 | BW16: -1 | BX16: ФОП, ФЕДЕНКО НАТАЛІЯ РОМАНІВНА | BY16: 0.055555556 | BZ16: -1 | CA16: 41195567 | CB16: 0.0031446541 | CC16: -1 | CD16: ФОП, ЯКИМІВ СВІТЛАНА ЯРОСЛАВІВНА | CE16: 0.73684211 | CF16: -1 | CG16: 44646459 | CH16: 0.00012033694 | CI16: -1 | CJ16: 37325796 | CK16: 0.0017006803 | CL16: -1 | CM16: ФОП, Люта Оксана Павлівна | CN16: 0.02283105 | CO16: -1
V17: ФОП, ІВЧЕНКО АНДРІЙ АНАТОЛІЙОВИЧ | W17: 0 | X17: -1 | Y17: 44114246 | Z17: 0.087368421 | AA17: -1 | AB17: 42310851 | AC17: 0.22350159 | AD17: -1 | AE17: ФОП, Кащук Марія Анатоліївна | AF17: 0.60655738 | AG17: -1 | AH17: 35472249 | AI17: 1.7692308 | AJ17: -1 | AK17: 01998035 | AL17: 0 | AM17: -1 | AN17: ФОП, ПЕТРИК КАТЕРИНА ЮРІЇВНА | AO17: 0.2 | AP17: -1 | AQ17: ФОП, СИВАК ЛЮДМИЛА ЮРІЇВНА | AR17: 0.071428571 | AS17: -1 | AT17: ФОП, Столяр Маряна Миколаївна | AU17: 0.0042918455 | AV17: -1 | AW17: ФОП, РИСЕЙ ОЛЬГА ІГОРІВНА | AX17: 0.004950495 | AY17: -1 | AZ17: 42108962 | BA17: 0.017618041 | BB17: -1 | BC17: 42224043 | BD17: 0.0020780051 | BE17: -1 | BF17: ФОП, КРАВЧУК ГАЛИНА ВАСИЛІВНА | BG17: 0 | BH17: -1 | BI17: ФОП, НІКОНОРОВ ВАЛЕРІЙ МИКОЛАЙОВИЧ | BJ17: 0.00095602294 | BK17: -1 | BL17: ФОП, ПОКІНСЬКА МАРІЯ МИХАЙЛІВНА | BM17: 0 | BN17: -1 | BO17: ФОП, НІКОНОРОВ ВАЛЕРІЙ МИКОЛАЙОВИЧ | BP17: 0.011583012 | BQ17: -1 | BR17: ФОП, КОЗИЧ РОКСОЛАНА АНДРІЇВНА | BS17: 0 | BT17: -1 | BU17: ФОП, РОНДЯК ОЛЕКСАНДРА ЗІНОВІЇВНА | BV17: 0.0022675737 | BW17: -1 | CA17: ФОП, Жук Олег Євгенович | CB17: 0.003197442 | CC17: -1 | CD17: ФОП, ГРИЦАК РУСЛАН ГЕННАДІЙОВИЧ | CE17: 0.74193548 | CF17: -1 | CG17: 41839788 | CH17: 0.00012106538 | CI17: -1 | CJ17: 41136480 | CK17: 0.0017286085 | CL17: -1 | CM17: 43919770 | CN17: 0.025280899 | CO17: -1
V18: ФОП, ЯКИМІВ СВІТЛАНА ЯРОСЛАВІВНА | W18: 0 | X18: -1 | Y18: 39792683 | Z18: 0.09675 | AA18: -1 | AB18: 44056885 | AC18: 0.25635525 | AD18: -1 | AE18: ФОП, ЛАЗАРЕВИЧ ПЕТРО ЯРОСЛАВОВИЧ | AF18: 0.61111111 | AG18: -1 | AH18: ФОП, ЗАСТАВНИЙ ІГОР ІГОРОВИЧ | AI18: 1.8333333 | AJ18: -1 | AK18: 43260585 | AL18: 0 | AM18: -1 | AN18: ФОП, ПОКІНСЬКА МАРІЯ МИХАЙЛІВНА | AO18: 0.21621622 | AP18: -1 | AQ18: ФОП, ПОКІНСЬКА МАРІЯ МИХАЙЛІВНА | AR18: 0.08 | AS18: -1 | AT18: 44070522 | AU18: 0.0043782837 | AV18: -1 | AW18: 44119976 | AX18: 0.0057471264 | AY18: -1 | AZ18: 22348948 | BA18: 0.021442495 | BB18: -1 | BC18: 41900490 | BD18: 0.0022591101 | BE18: -1 | BF18: 20764478 | BG18: 0 | BH18: -1 | BI18: 32418147 | BJ18: 0.00097943193 | BK18: -1 | BL18: ФОП, ШКУЛЬСЬКИЙ ВОЛОДИМИР ВОЛОДИМИРОВИЧ | BM18: 0 | BN18: -1 | BO18: ФОП, СЕРЕДЮК ОЛЬГА ІВАНІВНА | BP18: 0.012244898 | BQ18: -1 | BR18: ФОП, КОТОВИЧ НАТАЛІЯ СТЕПАНІВНА | BS18: 0 | BT18: -1 | BU18: 41160010 | BV18: 0.0026191723 | BW18: -1 | CA18: ФОП, ПІКУЛИЦЬКА ЯРИНА ВАСИЛІВНА | CB18: 0.003703018 | CC18: -1 | CD18: ФОП, БАЛЛА РОКСОЛАНА АНДРІЇВНА | CE18: 0.75 | CF18: -1 | CG18: 41850775 | CH18: 0.00015470297 | CI18: -1 | CJ18: 42750109 | CK18: 0.0017565872 | CL18: -1 | CM18: 20763941 | CN18: 0.026388125 | CO18: -1
V19: ФОП, КАРАКЕВИЧ ЮРІЙ МИХАЙЛОВИЧ | W19: 0 | X19: -1 | Y19: 20850964 | Z19: 0.10148148 | AA19: -1 | AB19: ФОП, РОНДЯК БОГДАН ЯРОСЛАВОВИЧ | AC19: 0.26728111 | AD19: -1 | AE19: ФОП, БЕРЕЗНЮК ТЕТЯНА ПАВЛІВНА | AF19: 0.61111111 | AG19: -1 | AH19: ФОП, ОЩИПКО ІРИНА ГЕОРГІЇВНА | AI19: 1.8571429 | AJ19: -1 | AK19: 02010793 | AL19: 0 | AM19: -1 | AN19: ФОП, Кольченко Леся Михайлівна | AO19: 0.21862348 | AP19: -1 | AQ19: 44925460 | AR19: 0.082287308 | AS19: -1 | AT19: 42448068 | AU19: 0.0045561546 | AV19: -1 | AW19: 20763160 | AX19: 0.0057803468 | AY19: -1 | AZ19: 41505308 | BA19: 0.022222222 | BB19: -1 | BC19: 01998101 | BD19: 0.0026441036 | BE19: -1 | BF19: ФОП, САВЕНКО НАТАЛІЯ ЯРОСЛАВІВНА | BG19: 0 | BH19: -1 | BI19: 38763426 | BJ19: 0.0010060362 | BK19: -1 | BL19: 44216151 | BM19: 0 | BN19: -1 | BO19: ФОП, ПЕТРИК КАТЕРИНА ЮРІЇВНА | BP19: 0.012345679 | BQ19: -1 | BR19: 42310851 | BS19: 0.001002004 | BT19: -1 | BU19: 41902533 | BV19: 0.0028818444 | BW19: -1 | CA19: ФОП, БЕРЕЗНЮК ТЕТЯНА ПАВЛІВНА | CB19: 0.003931848 | CC19: -1 | CD19: 34327104 | CE19: 0.75 | CF19: -1 | CG19: 20763591 | CH19: 0.00017222079 | CI19: -1 | CJ19: 02010793 | CK19: 0.0024154589 | CL19: -1 | CM19: 42274953 | CN19: 0.027375201 | CO19: -1
V20: 43288396 | W20: 0 | X20: -1 | Y20: ФОП, МЕЛЬНИК ЗОРЯНА СТЕПАНІВНА | Z20: 0.10327586 | AA20: -1 | AB20: 44246746 | AC20: 0.30572801 | AD20: -1 | AE20: 38763426 | AF20: 0.61320755 | AG20: -1 | AH20: ФОП, Рудько Ольга Олександрівна | AI20: 1.9090909 | AJ20: -1 | AK20: 42138054 | AL20: 0 | AM20: -1 | AN20: ФОП, Лялька Наталія Петрівна | AO20: 0.25 | AP20: -1 | AQ20: ФОП, ГРИЦАК РУСЛАН ГЕННАДІЙОВИЧ | AR20: 0.086956522 | AS20: -1 | AT20: 01998226 | AU20: 0.004609246 | AV20: -1 | AW20: 20763941 | AX20: 0.0058102001 | AY20: -1 | AZ20: ФОП, ЗАСТАВНИЙ ІГОР ІГОРОВИЧ | BA20: 0.023809524 | BB20: -1 | BC20: ФОП, Лялька Наталія Петрівна | BD20: 0.0028490028 | BE20: -1 | BF20: ФОП, ВОРОБЕЦЬ ІРИНА ЙОСИФІВНА | BG20: 0 | BH20: -1 | BI20: ФОП, РОНДЯК ОЛЕКСАНДРА ЗІНОВІЇВНА | BJ20: 0.0010454783 | BK20: -1 | BL20: 44976028 | BM20: 0 | BN20: -1 | BO20: ФОП, ПІКУЛИЦЬКА ЯРИНА ВАСИЛІВНА | BP20: 0.012779553 | BQ20: -1 | BR20: 40221119 | BS20: 0.0014684288 | BT20: -1 | BU20: 01984276 | BV20: 0.0029481132 | BW20: -1 | CA20: ФОП, СЕРЕДИЧ ЛІЛІЯ ПЕТРІВНА | CB20: 0.0045948204 | CC20: -1 | CD20: ФОП, Кащук Марія Анатоліївна | CE20: 0.75 | CF20: -1 | CG20: 42750109 | CH20: 0.00020255216 | CI20: -1 | CJ20: 36194399 | CK20: 0.0025773196 | CL20: -1 | CM20: 41064034 | CN20: 0.028906956 | CO20: -1
V21: ФОП, ЛАЗАРЕВИЧ ПЕТРО ЯРОСЛАВОВИЧ | W21: 0 | X21: -1 | Y21: 43288396 | Z21: 0.11026316 | AA21: -1 | AB21: ФОП, ОЩИПКО ІРИНА ГЕОРГІЇВНА | AC21: 0.31804281 | AD21: -1 | AE21: 01998035 | AF21: 0.62142857 | AG21: -1 | AH21: ФОП, ВОЗІВ ХРИСТИНА ІВАНІВНА | AI21: 1.9285714 | AJ21: -1 | AK21: 01996606 | AL21: 0 | AM21: -1 | AN21: 44976028 | AO21: 0.25 | AP21: -1 | AQ21: ФОП, Кащук Марія Анатоліївна | AR21: 0.08815427 | AS21: -1 | AT21: ФОП, ЗАСТАВНИЙ ІГОР ІГОРОВИЧ | AU21: 0.004784689 | AV21: -1 | AW21: 38763426 | AX21: 0.0063897764 | AY21: -1 | AZ21: ФОП, НІКОНОРОВ ВАЛЕРІЙ МИКОЛАЙОВИЧ | BA21: 0.025278059 | BB21: -1 | BC21: 36194399 | BD21: 0.0037735849 | BE21: -1 | BF21: ФОП, РОМАНІВ ЛЕСЯ АНАТОЛІЇВНА | BG21: 0 | BH21: -1 | BI21: 01998101 | BJ21: 0.0011149653 | BK21: -1 | BL21: 41160010 | BM21: 0 | BN21: -1 | BO21: 43260585 | BP21: 0.014285714 | BQ21: -1 | BR21: 43871190 | BS21: 0.0023116043 | BT21: -1 | BU21: 41900490 | BV21: 0.0031926215 | BW21: -1 | CA21: ФОП, Кащук Марія Анатоліївна | CB21: 0.0047732697 | CC21: -1 | CD21: 20850964 | CE21: 0.75862069 | CF21: -1 | CG21: 20764716 | CH21: 0.00021112636 | CI21: -1 | CJ21: 32418147 | CK21: 0.002690583 | CL21: -1 | CM21: 44056885 | CN21: 0.030973451 | CO21: -1
V22: ФОП, РОМАНІВ ЛЕСЯ АНАТОЛІЇВНА | W22: 0 | X22: -1 | Y22: 34327104 | Z22: 0.11536232 | AA22: -1 | AB22: ФОП, ПОЛУПАНЕЦЬ ВІРА ВОЛОДИМИРІВНА | AC22: 0.32211101 | AD22: -1 | AE22: ФОП, ПІКУЛИЦЬКА ЯРИНА ВАСИЛІВНА | AF22: 0.6360424 | AG22: -1 | AH22: ФОП, ПОЛУПАНЕЦЬ ВІРА ВОЛОДИМИРІВНА | AI22: 1.9411765 | AJ22: -1 | AK22: ФОП, КОШЛАТА ЛЕСЯ ВАСИЛІВНА | AL22: 0 | AM22: -1 | AN22: 45094345 | AO22: 0.25528583 | AP22: -1 | AQ22: ФОП, ПЕТРИК КАТЕРИНА ЮРІЇВНА | AR22: 0.095238095 | AS22: -1 | AT22: ФОП, Кащук Марія Анатоліївна | AU22: 0.0054794521 | AV22: -1 | AW22: 01997633 | AX22: 0.0073688773 | AY22: -1 | AZ22: ФОП, Добрянський Олесь Степанович | BA22: 0.027777778 | BB22: -1 | BC22: ФОП, НІКОНОРОВ ВАЛЕРІЙ МИКОЛАЙОВИЧ | BD22: 0.0043196544 | BE22: -1 | BF22: ФОП, ГРИЦАК РУСЛАН ГЕННАДІЙОВИЧ | BG22: 0 | BH22: -1 | BI22: 01984228 | BJ22: 0.0011534025 | BK22: -1 | BL22: ФОП, ІВЧЕНКО АНДРІЙ АНАТОЛІЙОВИЧ | BM22: 0 | BN22: -1 | BO22: 43914746 | BP22: 0.015370284 | BQ22: -1 | BR22: ФОП, ДІДИК ЛЕСЯ ІВАНІВНА | BS22: 0.0024213075 | BT22: -1 | BU22: ФОП, КОСТИРКО МИКОЛА МИХАЙЛОВИЧ | BV22: 0.0044444444 | BW22: -1 | CA22: ФОП, Турянська Ольга Тарасівна | CB22: 0.0050761421 | CC22: -1 | CD22: 22348948 | CE22: 0.76190476 | CF22: -1 | CG22: 42877452 | CH22: 0.00025117739 | CI22: -1 | CJ22: 20763160 | CK22: 0.0031512605 | CL22: -1 | CM22: 44712882 | CN22: 0.03942896 | CO22: -1
V23: ФОП, МИСНИК ЛЮДМИЛА ІЛЛІВНА | W23: 0 | X23: -1 | Y23: 44976028 | Z23: 0.11833333 | AA23: -1 | AB23: 42108962 | AC23: 0.32542373 | AD23: -1 | AE23: ФОП, МИСЛОВИЧ ОЛЕГ ЮРІЙОВИЧ | AF23: 0.64516129 | AG23: -1 | AH23: ФОП, Добрянський Олесь Степанович | AI23: 1.95 | AJ23: -1 | AK23: ФОП, МИСЛОВИЧ ОЛЕГ ЮРІЙОВИЧ | AL23: 0 | AM23: -1 | AN23: 20763591 | AO23: 0.26637555 | AP23: -1 | AQ23: 01998035 | AR23: 0.10055866 | AS23: -1 | AT23: 37325796 | AU23: 0.0059304703 | AV23: -1 | AW23: 44397639 | AX23: 0.007518797 | AY23: -1 | AZ23: ФОП, ПОШИВАК ТЕТЯНА ПЕТРІВНА | BA23: 0.029339853 | BB23: -1 | BC23: ФОП, Столяр Галина Ігорівна | BD23: 0.0045454545 | BE23: -1 | BF23: 44018588 | BG23: 0 | BH23: -1 | BI23: ФОП, Лялька Наталія Петрівна | BJ23: 0.0013175231 | BK23: -1 | BL23: ФОП, ЯКИМІВ СВІТЛАНА ЯРОСЛАВІВНА | BM23: 0 | BN23: -1 | BO23: 01998035 | BP23: 0.015625 | BQ23: -1 | BR23: 40393866 | BS23: 0.002739726 | BT23: -1 | BU23: 44646459 | BV23: 0.0061601643 | BW23: -1 | CA23: ФОП, КОШЛАТА ЛЕСЯ ВАСИЛІВНА | CB23: 0.0054347826 | CC23: -1 | CD23: ФОП, ЗУБРИЦЬКА НАДІЯ СТЕПАНІВНА | CE23: 0.76923077 | CF23: -1 | CG23: 41209595 | CH23: 0.00028473804 | CI23: -1 | CJ23: 01996272 | CK23: 0.0033603479 | CL23: 0.0033603479 | CM23: 44496574 | CN23: 0.048861601 | CO23: -1
